Workbook
Name BO: #REF!
Name BO點數: [1]期貨!$A$1:$AH$1
Name DATE: #REF!
Name 日期: 日期!$A$1:$AG$3
Name 月供應率: 月供應率!$A$1:$P$22
Name 月供應率ALL: 月供應率ALL!$A$1:$O$23
Name 月庫存金額: 月庫存金額!$A$1:$AB$26
Name 月點數BO: 月點數BO!$A$1:$O$20
Name 供應率: 供應率!$A$1:$AI$22
Name 供應率ALL: 供應率ALL!$A$1:$AH$23
Name 庫存金額: 庫存金額!$A$1:$AI$25
Name 庫存金額A類: 庫存金額A類!$A$1:$AH$4
Name 期貨: [1]當年月推移!$A$1:$AI$1
Name 期貨金額: 期貨金額!$A$1:$AI$21
Name 點數BO: 點數BO!$A$1:$AH$20

Sheet 當月份
A2: ㄧ、庫存金額日推移123
A3: 商品別 | D3: =YEAR(日期!C2)-1&"/"&MONTH(日期!C2) -> 2024/5 | E3: =YEAR(日期!C2)&"/"&MONTH(日期!C2) -> 2025/5 | F3: =YEAR(日期!C2) -> 2025 | G3: =YEAR(日期!C2) -> 2025 | H3: =YEAR(日期!C2) -> 2025 | I3: =日期!C2 -> 2025/05/01 | J3: =日期!D2 -> 2025/05/02 | K3: =日期!E2 -> 2025/05/03 | L3: =日期!F2 -> 2025/05/04 | M3: =日期!G2 -> 2025/05/05 | N3: =日期!H2 -> 2025/05/06 | O3: =日期!I2 -> 2025/05/07 | P3: =日期!J2 -> 2025/05/08 | ... AM3: =日期!AG2 -> 2025/05/31 | AN3: 日推移增減 | AO3: 本月庫存平均
D4: 實績 | E4: 目標 | F4: 至前月目標平均 | G4: 至前月實績(平均) | H4: 至前月實績(月底) | I4: =日期!C3 -> Thu | J4: =日期!D3 -> Fri | K4: =日期!E3 -> Sat | L4: =日期!F3 -> Sun | M4: =日期!G3 -> Mon | N4: =日期!H3 -> Tue | O4: =日期!I3 -> Wed | P4: =日期!J3 -> Thu | ... AM4: =日期!AG3 -> Sat
A5: 管理全商品 | D5: =D6+D13+D18+D26 -> 5.5484451e+08 | E5: =E6+E13+E18+E26 -> 6.2406008e+08 | F5: =F6+F13+F18+F26 -> 6.419635e+08 | G5: =G6+G13+G18+G26 -> 609877385 | H5: =H6+H13+H18+H26 -> 636071307 | I5: =I6+I13+I18+I26 -> 684014258 | J5: =J6+J13+J18+J26 -> 676952599 | K5: =K6+K13+K18+K26 -> 661941396 | ... AO5: =AO6+AO13+AO18+AO26 -> 6.4398309e+08 | AP5: =AJ5/10000 -> 61978.482 | AQ5: =AO5/10000 -> 64398.309
B6: 主商品 | D6: =SUM(D7:D12) -> 3.3071575e+08 | E6: =SUM(E7:E12) -> 3.4355299e+08 | F6: =SUM(F7:F12) -> 3.4793065e+08 | G6: =SUM(G7:G12) -> 346020235 | H6: =SUM(H7:H12) -> 363133490 | I6: =SUM(I7:I12) -> 369084774 | J6: =SUM(J7:J12) -> 359856476 | K6: =SUM(K7:K12) -> 350053666 | ... AO6: =SUM(AO7:AO12) -> 3.4129516e+08 | AP6: =AJ6/10000 -> 32571.811 | AQ6: =AO6/10000 -> 34129.516
C7: A 豐 田 | D7: =HLOOKUP(MONTH(日期!$C$2),去年月推移!$D$1:$O$33,5,TRUE) -> 2.9049416e+08 | E7: =HLOOKUP(MONTH(日期!$C$2),當年目標設定!$D$1:$O$33,5,TRUE) -> 2.9986129e+08 | F7: =HLOOKUP(MONTH(日期!$C$2),當年目標設定!$R$1:$AC$33,5,TRUE) -> 3.0119345e+08 | G7: =當年月推移!P5 -> 298934055 | H7: =當年月推移!P39 -> 308322760 | I7: =VALUE(庫存金額!C2) -> 311974084 | J7: =VALUE(庫存金額!D2) -> 307339949 | K7: =VALUE(庫存金額!E2) -> 304349072 | L7: =VALUE(庫存金額!F2) -> 304335526 | M7: =VALUE(庫存金額!G2) -> 305949450 | N7: =VALUE(庫存金額!H2) -> 304814994 | O7: =VALUE(庫存金額!I2) -> 313159147 | P7: =VALUE(庫存金額!J2) -> 315264198 | ... AO7: =VALUE(庫存金額!AI2) -> 2.9821125e+08 | AP7: =AJ7/10000 -> 27825.346 | AQ7: =AO7/10000 -> 29821.125
C8: J 油 料 | D8: =HLOOKUP(MONTH(日期!$C$2),去年月推移!$D$1:$O$33,6,TRUE) -> 5803713.5 | E8: =HLOOKUP(MONTH(日期!$C$2),當年目標設定!$D$1:$O$33,6,TRUE) -> 5817287.8 | F8: =HLOOKUP(MONTH(日期!$C$2),當年目標設定!$R$1:$AC$33,6,TRUE) -> 6699898.7 | G8: =當年月推移!$P6 -> 6609067 | H8: =當年月推移!P40 -> 8190649 | I8: =VALUE(庫存金額!C4) -> 6400194 | J8: =VALUE(庫存金額!D4) -> 5793832 | K8: =VALUE(庫存金額!E4) -> 4172804 | L8: =VALUE(庫存金額!F4) -> 4172804 | M8: =VALUE(庫存金額!G4) -> 4090908 | N8: =VALUE(庫存金額!H4) -> 5178997 | O8: =VALUE(庫存金額!I4) -> 4948274 | P8: =VALUE(庫存金額!J4) -> 5571175 | ... AO8: =VALUE(庫存金額!AI4) -> 5731138 | AP8: =AJ8/10000 -> 567.0066 | AQ8: =AO8/10000 -> 573.1138
C9: O 工具對策 | D9: =HLOOKUP(MONTH(日期!$C$2),去年月推移!$D$1:$O$33,7,TRUE) -> 3746962.9 | E9: =HLOOKUP(MONTH(日期!$C$2),當年目標設定!$D$1:$O$33,7,TRUE) -> 7794994.3 | F9: =HLOOKUP(MONTH(日期!$C$2),當年目標設定!$R$1:$AC$33,7,TRUE) -> 9312238.8 | G9: =當年月推移!$P7 -> 9291496 | H9: =當年月推移!P41 -> 8866156 | I9: =VALUE(庫存金額!C5) -> 6800876 | J9: =VALUE(庫存金額!D5) -> 7018299 | K9: =VALUE(庫存金額!E5) -> 6929576 | L9: =VALUE(庫存金額!F5) -> 6929576 | M9: =VALUE(庫存金額!G5) -> 6811797 | N9: =VALUE(庫存金額!H5) -> 6680095 | O9: =VALUE(庫存金額!I5) -> 6447781 | P9: =VALUE(庫存金額!J5) -> 6289744 | ... AO9: =VALUE(庫存金額!AI5) -> 5885981.3 | AP9: =AJ9/10000 -> 524.1109 | AQ9: =AO9/10000 -> 588.59813
C10: N 用品補修件 | D10: =HLOOKUP(MONTH(日期!$C$2),去年月推移!$D$1:$O$33,8,TRUE) -> 19958825 | E10: =HLOOKUP(MONTH(日期!$C$2),當年目標設定!$D$1:$O$33,8,TRUE) -> 18097093 | F10: =HLOOKUP(MONTH(日期!$C$2),當年目標設定!$R$1:$AC$33,8,TRUE) -> 18767602 | G10: =當年月推移!$P8 -> 19818962 | H10: =當年月推移!P42 -> 21051552 | I10: =VALUE(庫存金額!C6) -> 21065273 | J10: =VALUE(庫存金額!D6) -> 21030984 | K10: =VALUE(庫存金額!E6) -> 18935940 | L10: =VALUE(庫存金額!F6) -> 18944440 | M10: =VALUE(庫存金額!G6) -> 19015629 | N10: =VALUE(庫存金額!H6) -> 19222197 | O10: =VALUE(庫存金額!I6) -> 18480250 | P10: =VALUE(庫存金額!J6) -> 19224641 | ... AO10: =VALUE(庫存金額!AI6) -> 19873426 | AP10: =AJ10/10000 -> 2326.4593 | AQ10: =AO10/10000 -> 1987.3426
C11: C 日 野 | D11: =HLOOKUP(MONTH(日期!$C$2),去年月推移!$D$1:$O$33,9,TRUE) -> 0 | E11: =HLOOKUP(MONTH(日期!$C$2),當年目標設定!$D$1:$O$33,9,TRUE) -> 0 | F11: =HLOOKUP(MONTH(日期!$C$2),當年目標設定!$R$1:$AC$33,9,TRUE) -> 0 | G11: =當年月推移!$P9 -> 0 | H11: =當年月推移!P43 -> 0 | I11: =VALUE(庫存金額!C7) -> 0 | J11: =VALUE(庫存金額!D7) -> 0 | K11: =VALUE(庫存金額!E7) -> 0 | L11: =VALUE(庫存金額!F7) -> 0 | M11: =VALUE(庫存金額!G7) -> 0 | N11: =VALUE(庫存金額!H7) -> 0 | O11: =VALUE(庫存金額!I7) -> 0 | P11: =VALUE(庫存金額!J7) -> 0 | ... AO11: =VALUE(庫存金額!AI7) -> 0 | AP11: =AJ11/10000 -> 0 | AQ11: =AO11/10000 -> 0
C12: H 輪 胎 | D12: =HLOOKUP(MONTH(日期!$C$2),去年月推移!$D$1:$O$33,10,TRUE) -> 10712095 | E12: =HLOOKUP(MONTH(日期!$C$2),當年目標設定!$D$1:$O$33,10,TRUE) -> 11982324 | F12: =HLOOKUP(MONTH(日期!$C$2),當年目標設定!$R$1:$AC$33,10,TRUE) -> 11957463 | G12: =當年月推移!$P10 -> 11366655 | H12: =當年月推移!P44 -> 16702373 | I12: =VALUE(庫存金額!C8) -> 22844347 | J12: =VALUE(庫存金額!D8) -> 18673412 | K12: =VALUE(庫存金額!E8) -> 15666274 | L12: =VALUE(庫存金額!F8) -> 15666274 | M12: =VALUE(庫存金額!G8) -> 12022271 | N12: =VALUE(庫存金額!H8) -> 12367191 | O12: =VALUE(庫存金額!I8) -> 12485632 | P12: =VALUE(庫存金額!J8) -> 11439101 | ... AO12: =VALUE(庫存金額!AI8) -> 11593368 | AP12: =AJ12/10000 -> 1328.8885 | AQ12: =AO12/10000 -> 1159.3368
B13: 其他 | D13: =SUM(D14:D17) -> 13122132 | E13: =SUM(E14:E17) -> 12222079 | F13: =SUM(F14:F17) -> 11024745 | G13: =SUM(G14:G17) -> 1986660 | H13: =SUM(H14:H17) -> 2177264 | I13: =SUM(I14:I17) -> 13956053 | J13: =SUM(J14:J17) -> 14246366 | K13: =SUM(K14:K17) -> 12743986 | ... AO13: =SUM(AO14:AO17) -> 11788373 | AP13: =AJ13/10000 -> 1520.0992 | AQ13: =AO13/10000 -> 1178.8373
C14: E 噴射泵 | D14: =HLOOKUP(MONTH(日期!$C$2),去年月推移!$D$1:$O$33,12,TRUE) -> 0 | E14: =HLOOKUP(MONTH(日期!$C$2),當年目標設定!$D$1:$O$33,12,TRUE) -> 0 | F14: =HLOOKUP(MONTH(日期!$C$2),當年目標設定!$R$1:$AC$33,12,TRUE) -> 0 | G14: =當年月推移!P12 -> 0 | H14: =當年月推移!P46 -> 0 | I14: =VALUE(庫存金額!C9) -> 0 | J14: =VALUE(庫存金額!D9) -> 0 | K14: =VALUE(庫存金額!E9) -> 0 | L14: =VALUE(庫存金額!F9) -> 0 | M14: =VALUE(庫存金額!G9) -> 0 | N14: =VALUE(庫存金額!H9) -> 0 | O14: =VALUE(庫存金額!I9) -> 0 | P14: =VALUE(庫存金額!J9) -> 0 | ... AO14: =VALUE(庫存金額!AI9) -> 0
C15: F 電 裝 | D15: =HLOOKUP(MONTH(日期!$C$2),去年月推移!$D$1:$O$33,13,TRUE) -> 3735778.2 | E15: =HLOOKUP(MONTH(日期!$C$2),當年目標設定!$D$1:$O$33,13,TRUE) -> 3075747.8 | F15: =HLOOKUP(MONTH(日期!$C$2),當年目標設定!$R$1:$AC$33,13,TRUE) -> 1648865.1 | G15: =當年月推移!P13 -> 1695067 | H15: =當年月推移!P47 -> 1886353 | I15: =VALUE(庫存金額!C10) -> 2642042 | J15: =VALUE(庫存金額!D10) -> 2489817 | K15: =VALUE(庫存金額!E10) -> 2382952 | L15: =VALUE(庫存金額!F10) -> 2382952 | M15: =VALUE(庫存金額!G10) -> 2203662 | N15: =VALUE(庫存金額!H10) -> 2083032 | O15: =VALUE(庫存金額!I10) -> 2616642 | P15: =VALUE(庫存金額!J10) -> 2461137 | ... AO15: =VALUE(庫存金額!AI10) -> 2055329.9
C16: U 咖啡 | D16: =HLOOKUP(MONTH(日期!$C$2),去年月推移!$D$1:$O$33,14,TRUE) -> 173471.55 | E16: =HLOOKUP(MONTH(日期!$C$2),當年目標設定!$D$1:$O$33,14,TRUE) -> 303775.24 | F16: =HLOOKUP(MONTH(日期!$C$2),當年目標設定!$R$1:$AC$33,14,TRUE) -> 344969.48 | G16: =當年月推移!P15 -> 291593 | H16: =當年月推移!P49 -> 290911 | I16: =VALUE(庫存金額!C14) -> 243488 | J16: =VALUE(庫存金額!D14) -> 240788 | K16: =VALUE(庫存金額!E14) -> 238238 | L16: =VALUE(庫存金額!F14) -> 238238 | M16: =VALUE(庫存金額!G14) -> 234458 | N16: =VALUE(庫存金額!H14) -> 233378 | O16: =VALUE(庫存金額!I14) -> 245258 | P16: =VALUE(庫存金額!J14) -> 244718 | ... AO16: =VALUE(庫存金額!AI14) -> 226225.1
C17: 6 國採用品零件 | D17: =HLOOKUP(MONTH(日期!$C$2),去年月推移!$D$1:$O$33,15,TRUE) -> 9212882.6 | E17: =HLOOKUP(MONTH(日期!$C$2),當年目標設定!$D$1:$O$33,15,TRUE) -> 8842556.1 | F17: =HLOOKUP(MONTH(日期!$C$2),當年目標設定!$R$1:$AC$33,15,TRUE) -> 9030910.3 | G17: =當年月推移!P33 -> 0 | H17: =當年月推移!P67 -> 0 | I17: =VALUE(庫存金額!C24) -> 11070523 | J17: =VALUE(庫存金額!D24) -> 11515761 | K17: =VALUE(庫存金額!E24) -> 10122796 | L17: =VALUE(庫存金額!F24) -> 10122796 | M17: =VALUE(庫存金額!G24) -> 8860220 | N17: =VALUE(庫存金額!H24) -> 8522101 | O17: =VALUE(庫存金額!I24) -> 7658952 | P17: =VALUE(庫存金額!J24) -> 10206107 | ... AO17: =VALUE(庫存金額!AI24) -> 9506818.2
B18: LEXUS零件 | D18: =SUM(D19:D25) -> 2.0928344e+08 | E18: =SUM(E19:E25) -> 2.6828502e+08 | F18: =SUM(F19:F25) -> 2.830081e+08 | G18: =SUM(G19:G25) -> 246876181 | H18: =SUM(H19:H25) -> 255041305 | I18: =SUM(I19:I25) -> 292848960 | J18: =SUM(J19:J25) -> 294587385 | K18: =SUM(K19:K25) -> 291035772 | ... AO18: =SUM(AO19:AO25) -> 2.8299989e+08 | AP18: =AJ18/10000 -> 26820.987 | AQ18: =AO18/10000 -> 28299.989
C19: D LEXUS | D19: =HLOOKUP(MONTH(日期!$C$2),去年月推移!$D$1:$O$33,17,TRUE) -> 1.8175839e+08 | E19: =HLOOKUP(MONTH(日期!$C$2),當年目標設定!$D$1:$O$33,17,TRUE) -> 2.4372645e+08 | F19: =HLOOKUP(MONTH(日期!$C$2),當年目標設定!$R$1:$AC$33,17,TRUE) -> 2.5749941e+08 | G19: =當年月推移!P17 -> 225770603 | H19: =當年月推移!P51 -> 232645519 | I19: =VALUE(庫存金額!C3) -> 249410081 | J19: =VALUE(庫存金額!D3) -> 251063268 | K19: =VALUE(庫存金額!E3) -> 249183991 | L19: =VALUE(庫存金額!F3) -> 249183991 | M19: =VALUE(庫存金額!G3) -> 250375060 | N19: =VALUE(庫存金額!H3) -> 250382011 | O19: =VALUE(庫存金額!I3) -> 250622297 | P19: =VALUE(庫存金額!J3) -> 249929837 | ... AO19: =VALUE(庫存金額!AI3) -> 2.4436522e+08
C20: M 油 料 | D20: =HLOOKUP(MONTH(日期!$C$2),去年月推移!$D$1:$O$33,18,TRUE) -> 2373800.7 | E20: =HLOOKUP(MONTH(日期!$C$2),當年目標設定!$D$1:$O$33,18,TRUE) -> 2079356.2 | F20: =HLOOKUP(MONTH(日期!$C$2),當年目標設定!$R$1:$AC$33,18,TRUE) -> 2031522.1 | G20: =當年月推移!P18 -> 2247630 | H20: =當年月推移!P52 -> 2644689 | I20: =VALUE(庫存金額!C13) -> 1381676 | J20: =VALUE(庫存金額!D13) -> 1660145 | K20: =VALUE(庫存金額!E13) -> 1497869 | L20: =VALUE(庫存金額!F13) -> 1497869 | M20: =VALUE(庫存金額!G13) -> 953630 | N20: =VALUE(庫存金額!H13) -> 1067226 | O20: =VALUE(庫存金額!I13) -> 841090 | P20: =VALUE(庫存金額!J13) -> 1124538 | ... AO20: =VALUE(庫存金額!AI13) -> 1542560.2
C21: S 工具對策 | D21: =HLOOKUP(MONTH(日期!$C$2),去年月推移!$D$1:$O$33,19,TRUE) -> 7812749.6 | E21: =HLOOKUP(MONTH(日期!$C$2),當年目標設定!$D$1:$O$33,19,TRUE) -> 5673644.6 | F21: =HLOOKUP(MONTH(日期!$C$2),當年目標設定!$R$1:$AC$33,19,TRUE) -> 6722407.6 | G21: =當年月推移!P19 -> 161176 | H21: =當年月推移!P53 -> 161176 | I21: =VALUE(庫存金額!C18) -> 22038535 | J21: =VALUE(庫存金額!D18) -> 21937400 | K21: =VALUE(庫存金額!E18) -> 21770553 | L21: =VALUE(庫存金額!F18) -> 21770553 | M21: =VALUE(庫存金額!G18) -> 21704746 | N21: =VALUE(庫存金額!H18) -> 21524694 | O21: =VALUE(庫存金額!I18) -> 21405046 | P21: =VALUE(庫存金額!J18) -> 21254419 | ... AO21: =VALUE(庫存金額!AI18) -> 20431668
C22: V 用品補修件 | D22: =HLOOKUP(MONTH(日期!$C$2),去年月推移!$D$1:$O$33,20,TRUE) -> 12864030 | E22: =HLOOKUP(MONTH(日期!$C$2),當年目標設定!$D$1:$O$33,20,TRUE) -> 10373819 | F22: =HLOOKUP(MONTH(日期!$C$2),當年目標設定!$R$1:$AC$33,20,TRUE) -> 10394302 | G22: =當年月推移!P20 -> 162800 | H22: =當年月推移!P54 -> 162800 | I22: =VALUE(庫存金額!C17) -> 10247940 | J22: =VALUE(庫存金額!D17) -> 10807041 | K22: =VALUE(庫存金額!E17) -> 10073622 | L22: =VALUE(庫存金額!F17) -> 10073622 | M22: =VALUE(庫存金額!G17) -> 9994226 | N22: =VALUE(庫存金額!H17) -> 9123488 | O22: =VALUE(庫存金額!I17) -> 9112326 | P22: =VALUE(庫存金額!J17) -> 10120532 | ... AO22: =VALUE(庫存金額!AI17) -> 9849791.7
C23: T 輪 胎 | D23: =HLOOKUP(MONTH(日期!$C$2),去年月推移!$D$1:$O$33,21,TRUE) -> 4186738.3 | E23: =HLOOKUP(MONTH(日期!$C$2),當年目標設定!$D$1:$O$33,21,TRUE) -> 6248420.6 | F23: =HLOOKUP(MONTH(日期!$C$2),當年目標設定!$R$1:$AC$33,21,TRUE) -> 6179311.5 | G23: =當年月推移!P21 -> 18267350 | H23: =當年月推移!P55 -> 19145149 | I23: =VALUE(庫存金額!C16) -> 9516089 | J23: =VALUE(庫存金額!D16) -> 8864892 | K23: =VALUE(庫存金額!E16) -> 8255098 | L23: =VALUE(庫存金額!F16) -> 8255098 | M23: =VALUE(庫存金額!G16) -> 7645206 | N23: =VALUE(庫存金額!H16) -> 7757589 | O23: =VALUE(庫存金額!I16) -> 7621441 | P23: =VALUE(庫存金額!J16) -> 7309649 | ... AO23: =VALUE(庫存金額!AI16) -> 6556006.6
C24: P 電 裝 | D24: =HLOOKUP(MONTH(日期!$C$2),去年月推移!$D$1:$O$33,22,TRUE) -> 124926.1 | E24: =HLOOKUP(MONTH(日期!$C$2),當年目標設定!$D$1:$O$33,22,TRUE) -> 183323.22 | F24: =HLOOKUP(MONTH(日期!$C$2),當年目標設定!$R$1:$AC$33,22,TRUE) -> 181150.27 | G24: =當年月推移!P22 -> 101611 | H24: =當年月推移!P56 -> 99652 | I24: =VALUE(庫存金額!C11) -> 91839 | J24: =VALUE(庫存金額!D11) -> 91839 | K24: =VALUE(庫存金額!E11) -> 91839 | L24: =VALUE(庫存金額!F11) -> 91839 | M24: =VALUE(庫存金額!G11) -> 91839 | N24: =VALUE(庫存金額!H11) -> 91839 | O24: =VALUE(庫存金額!I11) -> 91839 | P24: =VALUE(庫存金額!J11) -> 91839 | ... AO24: =VALUE(庫存金額!AI11) -> 91839
C25: Q 咖 啡 | D25: =HLOOKUP(MONTH(日期!$C$2),去年月推移!$D$1:$O$33,23,TRUE) -> 162800 | E25: =HLOOKUP(MONTH(日期!$C$2),當年目標設定!$D$1:$O$33,23,TRUE) -> 0 | F25: =HLOOKUP(MONTH(日期!$C$2),當年目標設定!$R$1:$AC$33,23,TRUE) -> 0 | G25: =當年月推移!P23 -> 165011 | H25: =當年月推移!P57 -> 182320 | I25: =VALUE(庫存金額!C19) -> 162800 | J25: =VALUE(庫存金額!D19) -> 162800 | K25: =VALUE(庫存金額!E19) -> 162800 | L25: =VALUE(庫存金額!F19) -> 162800 | M25: =VALUE(庫存金額!G19) -> 162800 | N25: =VALUE(庫存金額!H19) -> 162800 | O25: =VALUE(庫存金額!I19) -> 162800 | P25: =VALUE(庫存金額!J19) -> 162800 | ... AO25: =VALUE(庫存金額!AI19) -> 162800
C26: 二通路零件 | D26: =SUM(D27:D31) -> 1723192 | E26: =SUM(E27:E31) -> 0 | F26: =SUM(F27:F31) -> 0 | G26: =SUM(G27:G31) -> 14994309 | H26: =SUM(H27:H31) -> 15719248 | I26: =SUM(I27:I31) -> 8124471 | J26: =SUM(J27:J31) -> 8262372 | K26: =SUM(K27:K31) -> 8107972 | ... AO26: =SUM(AO27:AO31) -> 7899670.9
C27: 2 二品牌零件(HOT專用) | D27: =HLOOKUP(MONTH(日期!$C$2),去年月推移!$D$1:$O$33,25,TRUE) -> 161176 | E27: =HLOOKUP(MONTH(日期!$C$2),當年目標設定!$D$1:$O$33,25,TRUE) -> 0 | F27: =HLOOKUP(MONTH(日期!$C$2),當年目標設定!$R$1:$AC$33,25,TRUE) -> 0 | G27: =當年月推移!P25 -> 0 | H27: =當年月推移!P59 -> 0 | I27: =VALUE(庫存金額!C20) -> 161176 | J27: =VALUE(庫存金額!D20) -> 161176 | K27: =VALUE(庫存金額!E20) -> 161176 | L27: =VALUE(庫存金額!F20) -> 161176 | M27: =VALUE(庫存金額!G20) -> 161176 | N27: =VALUE(庫存金額!H20) -> 161176 | O27: =VALUE(庫存金額!I20) -> 161176 | P27: =VALUE(庫存金額!J20) -> 161176 | ... AO27: =VALUE(庫存金額!AI20) -> 161176
C28: 3 二品牌油料(HOT專用) | D28: =HLOOKUP(MONTH(日期!$C$2),去年月推移!$D$1:$O$33,26,TRUE) -> 173744.45 | E28: =HLOOKUP(MONTH(日期!$C$2),當年目標設定!$D$1:$O$33,26,TRUE) -> 0 | F28: =HLOOKUP(MONTH(日期!$C$2),當年目標設定!$R$1:$AC$33,26,TRUE) -> 0 | G28: =當年月推移!P26 -> 0 | H28: =當年月推移!P60 -> 0 | I28: =VALUE(庫存金額!C21) -> 209338 | J28: =VALUE(庫存金額!D21) -> 209338 | K28: =VALUE(庫存金額!E21) -> 209338 | L28: =VALUE(庫存金額!F21) -> 209338 | M28: =VALUE(庫存金額!G21) -> 209338 | N28: =VALUE(庫存金額!H21) -> 209338 | O28: =VALUE(庫存金額!I21) -> 115978 | P28: =VALUE(庫存金額!J21) -> 132178 | ... AO28: =VALUE(庫存金額!AI21) -> 136660.58
C29: 4 二品牌零件(CPO專用) | D29: =HLOOKUP(MONTH(日期!$C$2),去年月推移!$D$1:$O$33,27,TRUE) -> 0 | E29: =HLOOKUP(MONTH(日期!$C$2),當年目標設定!$D$1:$O$33,27,TRUE) -> 0 | F29: =HLOOKUP(MONTH(日期!$C$2),當年目標設定!$R$1:$AC$33,27,TRUE) -> 0 | G29: =當年月推移!P27 -> 9192419 | H29: =當年月推移!P61 -> 9592211 | I29: =VALUE(庫存金額!C22) -> 0 | J29: =VALUE(庫存金額!D22) -> 0 | K29: =VALUE(庫存金額!E22) -> 0 | L29: =VALUE(庫存金額!F22) -> 0 | M29: =VALUE(庫存金額!G22) -> 0 | N29: =VALUE(庫存金額!H22) -> 0 | O29: =VALUE(庫存金額!I22) -> 0 | P29: =VALUE(庫存金額!J22) -> 0 | ... AO29: =VALUE(庫存金額!AI22) -> 0
C30: 5 二品牌油料(CPO專用) | D30: =HLOOKUP(MONTH(日期!$C$2),去年月推移!$D$1:$O$33,28,TRUE) -> 0 | E30: =HLOOKUP(MONTH(日期!$C$2),當年目標設定!$D$1:$O$33,28,TRUE) -> 0 | F30: =HLOOKUP(MONTH(日期!$C$2),當年目標設定!$R$1:$AC$33,28,TRUE) -> 0 | G30: =當年月推移!P28 -> 5801890 | H30: =當年月推移!P62 -> 6127037 | I30: =VALUE(庫存金額!C23) -> 0 | J30: =VALUE(庫存金額!D23) -> 0 | K30: =VALUE(庫存金額!E23) -> 0 | L30: =VALUE(庫存金額!F23) -> 0 | M30: =VALUE(庫存金額!G23) -> 0 | N30: =VALUE(庫存金額!H23) -> 0 | O30: =VALUE(庫存金額!I23) -> 0 | P30: =VALUE(庫存金額!J23) -> 0 | ... AO30: =VALUE(庫存金額!AI23) -> 0
C31: 7 二品牌零件(車美仕專用) | D31: =HLOOKUP(MONTH(日期!$C$2),去年月推移!$D$1:$O$33,29,TRUE) -> 1388271.5 | E31: =HLOOKUP(MONTH(日期!$C$2),當年目標設定!$D$1:$O$33,29,TRUE) -> 0 | F31: =HLOOKUP(MONTH(日期!$C$2),當年目標設定!$R$1:$AC$33,29,TRUE) -> 0 | G31: =當年月推移!P34 -> 0 | H31: =當年月推移!P68 -> 0 | I31: =VALUE(庫存金額!C25) -> 7753957 | J31: =VALUE(庫存金額!D25) -> 7891858 | K31: =VALUE(庫存金額!E25) -> 7737458 | L31: =VALUE(庫存金額!F25) -> 7737458 | M31: =VALUE(庫存金額!G25) -> 7638137 | N31: =VALUE(庫存金額!H25) -> 6627115 | O31: =VALUE(庫存金額!I25) -> 6594735 | P31: =VALUE(庫存金額!J25) -> 6538735 | ... AO31: =VALUE(庫存金額!AI25) -> 7601834.4
A32: 非管理 | C32: L 小車用品 | D32: =HLOOKUP(MONTH(日期!$C$2),去年月推移!$D$1:$O$33,30,TRUE) -> 2763037.1 | E32: =HLOOKUP(MONTH(日期!$C$2),當年目標設定!$D$1:$O$33,30,TRUE) -> 0 | F32: =HLOOKUP(MONTH(日期!$C$2),當年目標設定!$R$1:$AC$33,30,TRUE) -> 0 | G32: =當年月推移!P29 -> 1616553 | H32: =當年月推移!P63 -> 1606723 | I32: =VALUE(庫存金額!C15) -> 1605674 | J32: =VALUE(庫存金額!D15) -> 1605674 | K32: =VALUE(庫存金額!E15) -> 1605674 | L32: =VALUE(庫存金額!F15) -> 1605674 | M32: =VALUE(庫存金額!G15) -> 1605674 | N32: =VALUE(庫存金額!H15) -> 1624429 | O32: =VALUE(庫存金額!I15) -> 1605674 | P32: =VALUE(庫存金額!J15) -> 1605674 | ... AO32: =VALUE(庫存金額!AI15) -> 1617368.2
C33: W 服務商品 | D33: =HLOOKUP(MONTH(日期!$C$2),去年月推移!$D$1:$O$33,31,TRUE) -> 0 | E33: =HLOOKUP(MONTH(日期!$C$2),當年目標設定!$D$1:$O$33,31,TRUE) -> 0 | F33: =HLOOKUP(MONTH(日期!$C$2),當年目標設定!$R$1:$AC$33,31,TRUE) -> 0 | G33: =當年月推移!P30 -> 0 | H33: =當年月推移!P64 -> 0 | I33: =VALUE(庫存金額!C26) -> 0 | J33: =VALUE(庫存金額!D26) -> 0 | K33: =VALUE(庫存金額!E26) -> 0 | L33: =VALUE(庫存金額!F26) -> 0 | M33: =VALUE(庫存金額!G26) -> 0 | N33: =VALUE(庫存金額!H26) -> 0 | O33: =VALUE(庫存金額!I26) -> 0 | P33: =VALUE(庫存金額!J26) -> 0 | ... AO33: =VALUE(庫存金額!AI26) -> 0
C34: X Lexus精品 | D34: =HLOOKUP(MONTH(日期!$C$2),去年月推移!$D$1:$O$33,32,TRUE) -> 0 | E34: =HLOOKUP(MONTH(日期!$C$2),當年目標設定!$D$1:$O$33,32,TRUE) -> 0 | F34: =HLOOKUP(MONTH(日期!$C$2),當年目標設定!$R$1:$AC$33,32,TRUE) -> 0 | G34: =當年月推移!P31 -> 6048482 | H34: =當年月推移!P65 -> 8136926 | I34: =VALUE(庫存金額!C26) -> 0 | J34: =VALUE(庫存金額!D26) -> 0 | K34: =VALUE(庫存金額!E26) -> 0 | L34: =VALUE(庫存金額!F26) -> 0 | M34: =VALUE(庫存金額!G26) -> 0 | N34: =VALUE(庫存金額!H26) -> 0 | O34: =VALUE(庫存金額!I26) -> 0 | P34: =VALUE(庫存金額!J26) -> 0 | ... AO34: =VALUE(庫存金額!AI26) -> 0
C35: 8 活動贈品 | D35: =HLOOKUP(MONTH(日期!$C$2),去年月推移!$D$1:$O$33,33,TRUE) -> 0 | E35: =HLOOKUP(MONTH(日期!$C$2),當年目標設定!$D$1:$O$33,33,TRUE) -> 0 | F35: =HLOOKUP(MONTH(日期!$C$2),當年目標設定!$R$1:$AC$33,33,TRUE) -> 0 | G35: =當年月推移!P32 -> 11362159 | H35: =當年月推移!P66 -> 11154318 | I35: =VALUE(庫存金額!C26) -> 0 | J35: =VALUE(庫存金額!D26) -> 0 | K35: =VALUE(庫存金額!E26) -> 0 | L35: =VALUE(庫存金額!F26) -> 0 | M35: =VALUE(庫存金額!G26) -> 0 | N35: =VALUE(庫存金額!H26) -> 0 | O35: =VALUE(庫存金額!I26) -> 0 | P35: =VALUE(庫存金額!J26) -> 0 | ... AO35: =VALUE(庫存金額!AI26) -> 0
A37: 二、全省供應率日推移(異動等級='全部')
A38: 商品別 | D38: =D3 -> 2024/5 | E38: =E3 -> 2025/5 | G38: =YEAR(日期!C2) -> 2025 | I38: =日期!C2 -> 2025/05/01 | J38: =日期!D2 -> 2025/05/02 | K38: =日期!E2 -> 2025/05/03 | L38: =日期!F2 -> 2025/05/04 | M38: =日期!G2 -> 2025/05/05 | N38: =日期!H2 -> 2025/05/06 | O38: =日期!I2 -> 2025/05/07 | P38: =日期!J2 -> 2025/05/08 | ... AM38: =日期!AG2 -> 2025/05/31 | AN38: 合計
G39: 1~12月實績 | I39: =日期!C3 -> Thu | J39: =日期!D3 -> Fri | K39: =日期!E3 -> Sat | L39: =日期!F3 -> Sun | M39: =日期!G3 -> Mon | N39: =日期!H3 -> Tue | O39: =日期!I3 -> Wed | P39: =日期!J3 -> Thu | ... AM39: =日期!AG3 -> Sat
A40: A 豐田 | D40: =HLOOKUP(MONTH(日期!$C$2),去年月推移!$D$1:$O$200,98,TRUE) -> 98.731241 | E40: 97.8 | F40: - | G40: =ROUND(當年月推移!P99,1) -> 98.3 | I40: =ROUND(供應率ALL!C2,1) -> 0 | J40: =ROUND(供應率ALL!D2,1) -> 98.1 | K40: =ROUND(供應率ALL!E2,1) -> 98.6 | L40: =ROUND(供應率ALL!F2,1) -> 0 | M40: =ROUND(供應率ALL!G2,1) -> 98.6 | N40: =ROUND(供應率ALL!H2,1) -> 98.4 | O40: =ROUND(供應率ALL!I2,1) -> 98.4 | P40: =ROUND(供應率ALL!J2,1) -> 98.4 | ... AN40: =ROUND(供應率ALL!AH2,1) -> 98.2
A41: J 油料 | D41: =HLOOKUP(MONTH(日期!$C$2),去年月推移!$D$1:$O$200,99,TRUE) -> 99.989088 | E41: 99 | F41: - | G41: =ROUND(當年月推移!P100,1) -> 99.7 | I41: =ROUND(供應率ALL!C4,1) -> 0 | J41: =ROUND(供應率ALL!D4,1) -> 100 | K41: =ROUND(供應率ALL!E4,1) -> 100 | L41: =ROUND(供應率ALL!F4,1) -> 0 | M41: =ROUND(供應率ALL!G4,1) -> 100 | N41: =ROUND(供應率ALL!H4,1) -> 100 | O41: =ROUND(供應率ALL!I4,1) -> 100 | P41: =ROUND(供應率ALL!J4,1) -> 100 | ... AN41: =ROUND(供應率ALL!AH4,1) -> 100
A42: O 工具對策 | D42: =HLOOKUP(MONTH(日期!$C$2),去年月推移!$D$1:$O$200,100,TRUE) -> 86.044273 | E42: 75 | F42: - | G42: =ROUND(當年月推移!P101,1) -> 92.4 | I42: =ROUND(供應率ALL!C5,1) -> 0 | J42: =ROUND(供應率ALL!D5,1) -> 100 | K42: =ROUND(供應率ALL!E5,1) -> 100 | L42: =ROUND(供應率ALL!F5,1) -> 0 | M42: =ROUND(供應率ALL!G5,1) -> 95.6 | N42: =ROUND(供應率ALL!H5,1) -> 87.1 | O42: =ROUND(供應率ALL!I5,1) -> 84.4 | P42: =ROUND(供應率ALL!J5,1) -> 82.8 | ... AN42: =ROUND(供應率ALL!AH5,1) -> 89
...

Sheet 附件一(A庫存金額)
A1: ㄧ、豐田件庫存金額日推移
A4: 商品別 | B4: 進口別 | C4: =YEAR(日期!C2)&"年"&MONTH(日期!C2)&"月" -> 2025年5月 | D4: =日期!C2 -> 2025/05/01 | E4: =日期!D2 -> 2025/05/02 | F4: =日期!E2 -> 2025/05/03 | G4: =日期!F2 -> 2025/05/04 | H4: =日期!G2 -> 2025/05/05 | I4: =日期!H2 -> 2025/05/06 | J4: =日期!I2 -> 2025/05/07 | K4: =日期!J2 -> 2025/05/08 | ... AH4: =日期!AG2 -> 2025/05/31 | AI4: Average | AJ4: 比例 | AK4: =YEAR(日期!C2)&"年"&MONTH(日期!C2)+1&"月" -> 2025年6月
C5: 目標 | D5: =日期!C3 -> Thu | E5: =日期!D3 -> Fri | F5: =日期!E3 -> Sat | G5: =日期!F3 -> Sun | H5: =日期!G3 -> Mon | I5: =日期!H3 -> Tue | J5: =日期!I3 -> Wed | K5: =日期!J3 -> Thu | ... AH5: =日期!AG3 -> Sat | AK5: 目標
A6: A | B6: 1 | C6: =HLOOKUP(MONTH(日期!$C$2),A類各進口別庫存金額目標!$B$2:$M$7,4,TRUE) -> 1.4264222e+08 | D6: =VALUE(庫存金額A類!C2) -> 139794654 | E6: =VALUE(庫存金額A類!D2) -> 137959501 | F6: =VALUE(庫存金額A類!E2) -> 135574128 | G6: =VALUE(庫存金額A類!F2) -> 135573833 | H6: =VALUE(庫存金額A類!G2) -> 136404498 | I6: =VALUE(庫存金額A類!H2) -> 136226803 | J6: =VALUE(庫存金額A類!I2) -> 136074028 | K6: =VALUE(庫存金額A類!J2) -> 137485748 | ... AI6: =VALUE(庫存金額A類!AH2) -> 1.3747785e+08 | AJ6: =AI6/AI9 -> 0.46100828 | AK6: =HLOOKUP(MONTH(日期!$C$2)+1,A類各進口別庫存金額目標!$B$2:$M$7,4,TRUE) -> 1.3712794e+08
A7: A | B7: 3 | C7: =HLOOKUP(MONTH(日期!$C$2),A類各進口別庫存金額目標!$B$2:$M$7,5,TRUE) -> 1.2342562e+08 | D7: =VALUE(庫存金額A類!C3) -> 130463017 | E7: =VALUE(庫存金額A類!D3) -> 129811627 | F7: =VALUE(庫存金額A類!E3) -> 130330030 | G7: =VALUE(庫存金額A類!F3) -> 130316779 | H7: =VALUE(庫存金額A類!G3) -> 132467376 | I7: =VALUE(庫存金額A類!H3) -> 132435736 | J7: =VALUE(庫存金額A類!I3) -> 140265325 | K7: =VALUE(庫存金額A類!J3) -> 139812651 | ... AI7: =VALUE(庫存金額A類!AH3) -> 1.2534392e+08 | AJ7: =AI7/AI9 -> 0.42031923 | AK7: =HLOOKUP(MONTH(日期!$C$2)+1,A類各進口別庫存金額目標!$B$2:$M$7,5,TRUE) -> 1.139012e+08
A8: A | B8: 4 | C8: =HLOOKUP(MONTH(日期!$C$2),A類各進口別庫存金額目標!$B$2:$M$7,6,TRUE) -> 33793445 | D8: =VALUE(庫存金額A類!C4) -> 41716413 | E8: =VALUE(庫存金額A類!D4) -> 39568821 | F8: =VALUE(庫存金額A類!E4) -> 38444914 | G8: =VALUE(庫存金額A類!F4) -> 38444914 | H8: =VALUE(庫存金額A類!G4) -> 37077576 | I8: =VALUE(庫存金額A類!H4) -> 36152455 | J8: =VALUE(庫存金額A類!I4) -> 36819794 | K8: =VALUE(庫存金額A類!J4) -> 37965799 | ... AI8: =VALUE(庫存金額A類!AH4) -> 35389474 | AJ8: =AI8/AI9 -> 0.1186725 | AK8: =HLOOKUP(MONTH(日期!$C$2)+1,A類各進口別庫存金額目標!$B$2:$M$7,6,TRUE) -> 32470239
A9: 總計 | C9: =SUM(C6:C8) -> 2.9986129e+08 | D9: =SUM(D6:D8) -> 311974084 | E9: =SUM(E6:E8) -> 307339949 | F9: =SUM(F6:F8) -> 304349072 | G9: =SUM(G6:G8) -> 304335526 | H9: =SUM(H6:H8) -> 305949450 | I9: =SUM(I6:I8) -> 304814994 | J9: =SUM(J6:J8) -> 313159147 | ... AI9: =SUM(AI6:AI8) -> 2.9821125e+08 | AJ9: =AI9/AI$9 -> 1 | AK9: =SUM(AK6:AK8) -> 2.8349938e+08
AI10: =AI9-C9 -> -1650036.1
A14: 商品別 | B14: 進口別 | C14: 10年6月目標 | D14: 2010/8/1 | E14: 2010/8/2 | F14: 2010/8/3 | G14: 2010/8/4 | H14: 2010/8/5 | I14: 2010/8/6 | J14: 2010/8/7 | K14: 2010/8/8 | L14: 2010/8/9 | M14: 2010/8/10 | N14: 2010/8/11 | O14: 2010/8/12 | P14: 2010/8/13 | Q14: 2010/8/14 | R14: 2010/8/15 | S14: 2010/8/16 | T14: 2010/8/17 | U14: 2010/8/18 | V14: 2010/8/19 | W14: 2010/8/20 | X14: 2010/8/21 | Y14: 2010/8/22 | Z14: 2010/8/23 | AA14: 2010/8/24 | AB14: 2010/8/25 | AC14: 2010/8/26 | AD14: 2010/8/27 | AE14: 2010/8/28 | AF14: 2010/8/29 | AG14: 2010/8/30 | AH14: 2010/8/31 | AI14: Average | AJ14: 比例
D15: Sun | E15: Mon | F15: Tue | G15: Wed | H15: Thu | I15: Fri | J15: Sat | K15: Sun | L15: Mon | M15: Tue | N15: Wed | O15: Thu | P15: Fri | Q15: Sat | R15: Sun | S15: Mon | T15: Tue | U15: Wed | V15: Thu | W15: Fri | X15: Sat | Y15: Sun | Z15: Mon | AA15: Tue | AB15: Wed | AC15: Thu | AD15: Fri | AE15: Sat | AF15: Sun | AG15: Mon | AH15: Tue
A16: A | B16: 1 | AI16: =AVERAGE(D16:AH16) -> #DIV/0! | AJ16: =AI16/AI$19 -> #DIV/0!
A17: A | B17: 3 | AI17: =AVERAGE(D17:AH17) -> #DIV/0! | AJ17: =AI17/AI$19 -> #DIV/0!
A18: A | B18: 4 | AI18: =AVERAGE(D18:AH18) -> #DIV/0! | AJ18: =AI18/AI$19 -> #DIV/0!
A19: 總計 | C19: =SUM(C16:C18) -> 0 | D19: =SUM(D16:D18) -> 0 | E19: =SUM(E16:E18) -> 0 | F19: =SUM(F16:F18) -> 0 | G19: =SUM(G16:G18) -> 0 | H19: =SUM(H16:H18) -> 0 | I19: =SUM(I16:I18) -> 0 | J19: =SUM(J16:J18) -> 0 | ... AI19: =SUM(AI16:AI18) -> #DIV/0! | AJ19: =AI19/AI$19 -> #DIV/0!
A24: 商品別 | B24: 進口別 | C24: 10年6月目標 | D24: 2010/9/1 | E24: 2010/9/2 | F24: 2010/9/3 | G24: 2010/9/4 | H24: 2010/9/5 | I24: 2010/9/6 | J24: 2010/9/7 | K24: 2010/9/8 | L24: 2010/9/9 | M24: 2010/9/10 | N24: 2010/9/11 | O24: 2010/9/12 | P24: 2010/9/13 | Q24: 2010/9/14 | R24: 2010/9/15 | S24: 2010/9/16 | T24: 2010/9/17 | U24: 2010/9/18 | V24: 2010/9/19 | W24: 2010/9/20 | X24: 2010/9/21 | Y24: 2010/9/22 | Z24: 2010/9/23 | AA24: 2010/9/24 | AB24: 2010/9/25 | AC24: 2010/9/26 | AD24: 2010/9/27 | AE24: 2010/9/28 | AF24: 2010/9/29 | AG24: 2010/9/30 | AI24: Average | AJ24: 比例
D25: Wed | E25: Thu | F25: Fri | G25: Sat | H25: Sun | I25: Mon | J25: Tue | K25: Wed | L25: Thu | M25: Fri | N25: Sat | O25: Sun | P25: Mon | Q25: Tue | R25: Wed | S25: Thu | T25: Fri | U25: Sat | V25: Sun | W25: Mon | X25: Tue | Y25: Wed | Z25: Thu | AA25: Fri | AB25: Sat | AC25: Sun | AD25: Mon | AE25: Tue | AF25: Wed | AG25: Thu
A26: A | B26: 1 | AI26: =AVERAGE(D26:AH26) -> #DIV/0! | AJ26: =AI26/AI$29 -> #DIV/0!
A27: A | B27: 3 | AI27: =AVERAGE(D27:AH27) -> #DIV/0! | AJ27: =AI27/AI$29 -> #DIV/0!
A28: A | B28: 4 | AI28: =AVERAGE(D28:AH28) -> #DIV/0! | AJ28: =AI28/AI$29 -> #DIV/0!
A29: 總計 | C29: =SUM(C26:C28) -> 0 | D29: =SUM(D26:D28) -> 0 | E29: =SUM(E26:E28) -> 0 | F29: =SUM(F26:F28) -> 0 | G29: =SUM(G26:G28) -> 0 | H29: =SUM(H26:H28) -> 0 | I29: =SUM(I26:I28) -> 0 | J29: =SUM(J26:J28) -> 0 | ... AI29: =SUM(AI26:AI28) -> #DIV/0! | AJ29: =AI29/AI$29 -> #DIV/0!
A34: 商品別 | B34: 進口別 | C34: 10年6月目標 | D34: 2010/10/1 | E34: 2010/10/2 | F34: 2010/10/3 | G34: 2010/10/4 | H34: 2010/10/5 | I34: 2010/10/6 | J34: 2010/10/7 | K34: 2010/10/8 | L34: 2010/10/9 | M34: 2010/10/10 | N34: 2010/10/11 | O34: 2010/10/12 | P34: 2010/10/13 | Q34: 2010/10/14 | R34: 2010/10/15 | S34: 2010/10/16 | T34: 2010/10/17 | U34: 2010/10/18 | V34: 2010/10/19 | W34: 2010/10/20 | X34: 2010/10/21 | Y34: 2010/10/22 | Z34: 2010/10/23 | AA34: 2010/10/24 | AB34: 2010/10/25 | AC34: 2010/10/26 | AD34: 2010/10/27 | AE34: 2010/10/28 | AF34: 2010/10/29 | AG34: 2010/10/30 | AH34: 2010/10/31 | AI34: Average | AJ34: 比例
D35: Fri | E35: Sat | F35: Sun | G35: Mon | H35: Tue | I35: Wed | J35: Thu | K35: Fri | L35: Sat | M35: Sun | N35: Mon | O35: Tue | P35: Wed | Q35: Thu | R35: Fri | S35: Sat | T35: Sun | U35: Mon | V35: Tue | W35: Wed | X35: Thu | Y35: Fri | Z35: Sat | AA35: Sun | AB35: Mon | AC35: Tue | AD35: Wed | AE35: Thu | AF35: Fri | AG35: Sat | AH35: Sun
A36: A | B36: 1 | AI36: =AVERAGE(D36:AH36) -> #DIV/0! | AJ36: =AI36/AI$39 -> #DIV/0!
A37: A | B37: 3 | AI37: =AVERAGE(D37:AH37) -> #DIV/0! | AJ37: =AI37/AI$39 -> #DIV/0!
A38: A | B38: 4 | AI38: =AVERAGE(D38:AH38) -> #DIV/0! | AJ38: =AI38/AI$39 -> #DIV/0!
A39: 總計 | D39: =SUM(D36:D38) -> 0 | E39: =SUM(E36:E38) -> 0 | F39: =SUM(F36:F38) -> 0 | G39: =SUM(G36:G38) -> 0 | H39: =SUM(H36:H38) -> 0 | I39: =SUM(I36:I38) -> 0 | J39: =SUM(J36:J38) -> 0 | K39: =SUM(K36:K38) -> 0 | ... AI39: =SUM(AI36:AI38) -> #DIV/0! | AJ39: =AI39/AI$39 -> #DIV/0!
A44: 商品別 | B44: 進口別 | C44: 10年6月目標 | D44: 2010/11/1 | E44: 2010/11/2 | F44: 2010/11/3 | G44: 2010/11/4 | H44: 2010/11/5 | I44: 2010/11/6 | J44: 2010/11/7 | K44: 2010/11/8 | L44: 2010/11/9 | M44: 2010/11/10 | N44: 2010/11/11 | O44: 2010/11/12 | P44: 2010/11/13 | Q44: 2010/11/14 | R44: 2010/11/15 | S44: 2010/11/16 | T44: 2010/11/17 | U44: 2010/11/18 | V44: 2010/11/19 | W44: 2010/11/20 | X44: 2010/11/21 | Y44: 2010/11/22 | Z44: 2010/11/23 | AA44: 2010/11/24 | AB44: 2010/11/25 | AC44: 2010/11/26 | AD44: 2010/11/27 | AE44: 2010/11/28 | AF44: 2010/11/29 | AG44: 2010/11/30 | AI44: Average | AJ44: 比例
D45: Mon | E45: Tue | F45: Wed | G45: Thu | H45: Fri | I45: Sat | J45: Sun | K45: Mon | L45: Tue | M45: Wed | N45: Thu | O45: Fri | P45: Sat | Q45: Sun | R45: Mon | S45: Tue | T45: Wed | U45: Thu | V45: Fri | W45: Sat | X45: Sun | Y45: Mon | Z45: Tue | AA45: Wed | AB45: Thu | AC45: Fri | AD45: Sat | AE45: Sun | AF45: Mon | AG45: Tue
A46: A | B46: 1 | AI46: =AVERAGE(D46:AH46) -> #DIV/0! | AJ46: =AI46/AI$150 -> #DIV/0!
A47: A | B47: 3 | AI47: =AVERAGE(D47:AH47) -> #DIV/0! | AJ47: =AI47/AI$150 -> #DIV/0!
A48: A | B48: 4 | AI48: =AVERAGE(D48:AH48) -> #DIV/0! | AJ48: =AI48/AI$150 -> #DIV/0!
A49: 總計 | C49: =SUM(C46:C48) -> 0 | D49: =SUM(D46:D48) -> 0 | E49: =SUM(E46:E48) -> 0 | F49: =SUM(F46:F48) -> 0 | G49: =SUM(G46:G48) -> 0 | H49: =SUM(H46:H48) -> 0 | I49: =SUM(I46:I48) -> 0 | J49: =SUM(J46:J48) -> 0 | ... AI49: =SUM(AI46:AI48) -> #DIV/0! | AJ49: =AI49/AI$150 -> #DIV/0!
A54: 商品別 | B54: 進口別 | C54: 10年6月目標 | D54: 2010/12/1 | E54: 2010/12/2 | F54: 2010/12/3 | G54: 2010/12/4 | H54: 2010/12/5 | I54: 2010/12/6 | J54: 2010/12/7 | K54: 2010/12/8 | L54: 2010/12/9 | M54: 2010/12/10 | N54: 2010/12/11 | O54: 2010/12/12 | P54: 2010/12/13 | Q54: 2010/12/14 | R54: 2010/12/15 | S54: 2010/12/16 | T54: 2010/12/17 | U54: 2010/12/18 | V54: 2010/12/19 | W54: 2010/12/20 | X54: 2010/12/21 | Y54: 2010/12/22 | Z54: 2010/12/23 | AA54: 2010/12/24 | AB54: 2010/12/25 | AC54: 2010/12/26 | AD54: 2010/12/27 | AE54: 2010/12/28 | AF54: 2010/12/29 | AG54: 2010/12/30 | AH54: 2010/12/31 | AI54: Average | AJ54: 比例
D55: Wed | E55: Thu | F55: Fri | G55: Sat | H55: Sun | I55: Mon | J55: Tue | K55: Wed | L55: Thu | M55: Fri | N55: Sat | O55: Sun | P55: Mon | Q55: Tue | R55: Wed | S55: Thu | T55: Fri | U55: Sat | V55: Sun | W55: Mon | X55: Tue | Y55: Wed | Z55: Thu | AA55: Fri | AB55: Sat | AC55: Sun | AD55: Mon | AE55: Tue | AF55: Wed | AG55: Thu | AH55: Fri
A56: A | B56: 1 | AI56: =AVERAGE(D56:AH56) -> #DIV/0! | AJ56: =AI56/AI$1150 -> #DIV/0!
A57: A | B57: 3 | AI57: =AVERAGE(D57:AH57) -> #DIV/0! | AJ57: =AI57/AI$1150 -> #DIV/0!
A58: A | B58: 4 | AI58: =AVERAGE(D58:AH58) -> #DIV/0! | AJ58: =AI58/AI$1150 -> #DIV/0!
A59: 總計 | C59: =SUM(C56:C58) -> 0 | D59: =SUM(D56:D58) -> 0 | E59: =SUM(E56:E58) -> 0 | F59: =SUM(F56:F58) -> 0 | G59: =SUM(G56:G58) -> 0 | H59: =SUM(H56:H58) -> 0 | I59: =SUM(I56:I58) -> 0 | J59: =SUM(J56:J58) -> 0 | ... AI59: =SUM(AI56:AI58) -> #DIV/0! | AJ59: =AI59/AI$1150 -> #DIV/0!

Sheet 附件二(期貨)
A1: 二、期貨庫存金額日推移
A4: 商品別 | B4: 進口別 | C4: =日期!C2 -> 2025/05/01 | D4: =日期!D2 -> 2025/05/02 | E4: =日期!E2 -> 2025/05/03 | F4: =日期!F2 -> 2025/05/04 | G4: =日期!G2 -> 2025/05/05 | H4: =日期!H2 -> 2025/05/06 | I4: =日期!I2 -> 2025/05/07 | J4: =日期!J2 -> 2025/05/08 | ... AG4: =日期!AG2 -> 2025/05/31 | AH4: Average | AI4: 比例
C5: =日期!C3 -> Thu | D5: =日期!D3 -> Fri | E5: =日期!E3 -> Sat | F5: =日期!F3 -> Sun | G5: =日期!G3 -> Mon | H5: =日期!H3 -> Tue | I5: =日期!I3 -> Wed | J5: =日期!J3 -> Thu | ... AG5: =日期!AG3 -> Sat
A6: A | B6: 1 | C6: =VALUE(期貨金額!D2) -> 11269974 | D6: =VALUE(期貨金額!E2) -> 11199118 | E6: =VALUE(期貨金額!F2) -> 10215716 | F6: =VALUE(期貨金額!G2) -> 10215716 | G6: =VALUE(期貨金額!H2) -> 9664888 | H6: =VALUE(期貨金額!I2) -> 7647046 | I6: =VALUE(期貨金額!J2) -> 7061967 | J6: =VALUE(期貨金額!K2) -> 7016879 | ... AH6: =VALUE(期貨金額!AI2) -> 7886063.1 | AI6: =AH6/$AH$19 -> 0.47371007
A7: A | B7: 3 | C7: =VALUE(期貨金額!D3) -> 6346190 | D7: =VALUE(期貨金額!E3) -> 6359939 | E7: =VALUE(期貨金額!F3) -> 6381708 | F7: =VALUE(期貨金額!G3) -> 6381708 | G7: =VALUE(期貨金額!H3) -> 6696677 | H7: =VALUE(期貨金額!I3) -> 8008940 | I7: =VALUE(期貨金額!J3) -> 5417301 | J7: =VALUE(期貨金額!K3) -> 5363136 | ... AH7: =VALUE(期貨金額!AI3) -> 5630663.5 | AI7: =AH7/$AH$19 -> 0.33822985
A8: A | B8: 4 | C8: =VALUE(期貨金額!D4) -> 3592653 | D8: =VALUE(期貨金額!E4) -> 3603441 | E8: =VALUE(期貨金額!F4) -> 3603441 | F8: =VALUE(期貨金額!G4) -> 3603441 | G8: =VALUE(期貨金額!H4) -> 3438490 | H8: =VALUE(期貨金額!I4) -> 3611995 | I8: =VALUE(期貨金額!J4) -> 3573832 | J8: =VALUE(期貨金額!K4) -> 3660313 | ... AH8: =VALUE(期貨金額!AI4) -> 3085112.5 | AI8: =AH8/$AH$19 -> 0.18532046
A9: C | B9: 1 | C9: =VALUE(期貨金額!D5) -> 0 | D9: =VALUE(期貨金額!E5) -> 0 | E9: =VALUE(期貨金額!F5) -> 0 | F9: =VALUE(期貨金額!G5) -> 0 | G9: =VALUE(期貨金額!H5) -> 0 | H9: =VALUE(期貨金額!I5) -> 0 | I9: =VALUE(期貨金額!J5) -> 0 | J9: =VALUE(期貨金額!K5) -> 0 | ... AH9: =VALUE(期貨金額!AI5) -> 0 | AI9: =AH9/$AH$19 -> 0
A10: C | B10: 3 | C10: =VALUE(期貨金額!D6) -> 0 | D10: =VALUE(期貨金額!E6) -> 0 | E10: =VALUE(期貨金額!F6) -> 0 | F10: =VALUE(期貨金額!G6) -> 0 | G10: =VALUE(期貨金額!H6) -> 0 | H10: =VALUE(期貨金額!I6) -> 0 | I10: =VALUE(期貨金額!J6) -> 0 | J10: =VALUE(期貨金額!K6) -> 0 | ... AH10: =VALUE(期貨金額!AI6) -> 0 | AI10: =AH10/$AH$19 -> 0
A11: E | B11: 1 | C11: =VALUE(期貨金額!D8) -> 0 | D11: =VALUE(期貨金額!E8) -> 0 | E11: =VALUE(期貨金額!F8) -> 0 | F11: =VALUE(期貨金額!G8) -> 0 | G11: =VALUE(期貨金額!H8) -> 0 | H11: =VALUE(期貨金額!I8) -> 0 | I11: =VALUE(期貨金額!J8) -> 0 | J11: =VALUE(期貨金額!K8) -> 0 | ... AH11: =VALUE(期貨金額!AI8) -> 0 | AI11: =AH11/$AH$19 -> 0
A12: E | B12: 3 | C12: =VALUE(期貨金額!D9) -> 0 | D12: =VALUE(期貨金額!E9) -> 0 | E12: =VALUE(期貨金額!F9) -> 0 | F12: =VALUE(期貨金額!G9) -> 0 | G12: =VALUE(期貨金額!H9) -> 0 | H12: =VALUE(期貨金額!I9) -> 0 | I12: =VALUE(期貨金額!J9) -> 0 | J12: =VALUE(期貨金額!K9) -> 0 | ... AH12: =VALUE(期貨金額!AI9) -> 0 | AI12: =AH12/$AH$19 -> 0
A13: F | B13: 1 | C13: =VALUE(期貨金額!D10) -> 0 | D13: =VALUE(期貨金額!E10) -> 0 | E13: =VALUE(期貨金額!F10) -> 0 | F13: =VALUE(期貨金額!G10) -> 0 | G13: =VALUE(期貨金額!H10) -> 0 | H13: =VALUE(期貨金額!I10) -> 0 | I13: =VALUE(期貨金額!J10) -> 0 | J13: =VALUE(期貨金額!K10) -> 0 | ... AH13: =VALUE(期貨金額!AI10) -> 0 | AI13: =AH13/$AH$19 -> 0
A14: F | B14: 3 | C14: =VALUE(期貨金額!D11) -> 0 | D14: =VALUE(期貨金額!E11) -> 0 | E14: =VALUE(期貨金額!F11) -> 0 | F14: =VALUE(期貨金額!G11) -> 0 | G14: =VALUE(期貨金額!H11) -> 0 | H14: =VALUE(期貨金額!I11) -> 0 | I14: =VALUE(期貨金額!J11) -> 24192 | J14: =VALUE(期貨金額!K11) -> 24192 | ... AH14: =VALUE(期貨金額!AI11) -> 19509.68 | AI14: =AH14/$AH$19 -> 0.0011719323
A15: H | B15: 3 | C15: =VALUE(期貨金額!D12) -> 0 | D15: =VALUE(期貨金額!E12) -> 0 | E15: =VALUE(期貨金額!F12) -> 0 | F15: =VALUE(期貨金額!G12) -> 0 | G15: =VALUE(期貨金額!H12) -> 0 | H15: =VALUE(期貨金額!I12) -> 0 | I15: =VALUE(期貨金額!J12) -> 0 | J15: =VALUE(期貨金額!K12) -> 0 | ... AH15: =VALUE(期貨金額!AI12) -> 0 | AI15: =AH15/$AH$19 -> 0
A16: J | B16: 3 | C16: =VALUE(期貨金額!D13) -> 0 | D16: =VALUE(期貨金額!E13) -> 0 | E16: =VALUE(期貨金額!F13) -> 0 | F16: =VALUE(期貨金額!G13) -> 0 | G16: =VALUE(期貨金額!H13) -> 0 | H16: =VALUE(期貨金額!I13) -> 0 | I16: =VALUE(期貨金額!J13) -> 0 | J16: =VALUE(期貨金額!K13) -> 0 | ... AH16: =VALUE(期貨金額!AI13) -> 0 | AI16: =AH16/$AH$19 -> 0
A17: N | B17: 3 | C17: =VALUE(期貨金額!D15) -> 6350 | D17: =VALUE(期貨金額!E15) -> 6350 | E17: =VALUE(期貨金額!F15) -> 6350 | F17: =VALUE(期貨金額!G15) -> 6350 | G17: =VALUE(期貨金額!H15) -> 11444 | H17: =VALUE(期貨金額!I15) -> 47744 | I17: =VALUE(期貨金額!J15) -> 47744 | J17: =VALUE(期貨金額!K15) -> 47744 | ... AH17: =VALUE(期貨金額!AI15) -> 26097.97 | AI17: =AH17/$AH$19 -> 0.001567686
A18: O | B18: 3 | C18: =VALUE(期貨金額!D16) -> 0 | D18: =VALUE(期貨金額!E16) -> 0 | E18: =VALUE(期貨金額!F16) -> 0 | F18: =VALUE(期貨金額!G16) -> 0 | G18: =VALUE(期貨金額!H16) -> 0 | H18: =VALUE(期貨金額!I16) -> 0 | I18: =VALUE(期貨金額!J16) -> 0 | J18: =VALUE(期貨金額!K16) -> 0 | ... AH18: =VALUE(期貨金額!AI16) -> 0 | AI18: =AH18/$AH$19 -> 0
A19: 合計 | C19: =SUM(C6:C18) -> 21215167 | D19: =SUM(D6:D18) -> 21168848 | E19: =SUM(E6:E18) -> 20207215 | F19: =SUM(F6:F18) -> 20207215 | G19: =SUM(G6:G18) -> 19811499 | H19: =SUM(H6:H18) -> 19315725 | I19: =SUM(I6:I18) -> 16125036 | J19: =SUM(J6:J18) -> 16112264 | ... AH19: =SUM(AH6:AH18) -> 16647447 | AI19: =AH19/AH$19 -> 1
A20: D | B20: 1 | C20: =VALUE(期貨金額!D7) -> 1815285 | D20: =VALUE(期貨金額!E7) -> 1834673 | E20: =VALUE(期貨金額!F7) -> 1792821 | F20: =VALUE(期貨金額!G7) -> 1792821 | G20: =VALUE(期貨金額!H7) -> 1933945 | H20: =VALUE(期貨金額!I7) -> 1938267 | I20: =VALUE(期貨金額!J7) -> 1754019 | J20: =VALUE(期貨金額!K7) -> 1743335 | ... AH20: =VALUE(期貨金額!AI7) -> 4166478.4 | AI20: =AH20/$AH$26 -> 0.99998476
A21: S | B21: 3 | C21: =VALUE(期貨金額!D19) -> 0 | D21: =VALUE(期貨金額!E19) -> 0 | E21: =VALUE(期貨金額!F19) -> 0 | F21: =VALUE(期貨金額!G19) -> 0 | G21: =VALUE(期貨金額!H19) -> 0 | H21: =VALUE(期貨金額!I19) -> 0 | I21: =VALUE(期貨金額!J19) -> 0 | J21: =VALUE(期貨金額!K19) -> 0 | ... AH21: =VALUE(期貨金額!AI19) -> 0 | AI21: =AH21/$AH$26 -> 0
A22: V | B22: 3 | C22: =VALUE(期貨金額!D21) -> 1968 | D22: =VALUE(期貨金額!E21) -> 0 | E22: =VALUE(期貨金額!F21) -> 0 | F22: =VALUE(期貨金額!G21) -> 0 | G22: =VALUE(期貨金額!H21) -> 0 | H22: =VALUE(期貨金額!I21) -> 0 | I22: =VALUE(期貨金額!J21) -> 0 | J22: =VALUE(期貨金額!K21) -> 0 | ... AH22: =VALUE(期貨金額!AI21) -> 63.48 | AI22: =AH22/$AH$26 -> 1.5235656e-05
A23: T | B23: 3 | C23: =VALUE(期貨金額!D20) -> 0 | D23: =VALUE(期貨金額!E20) -> 0 | E23: =VALUE(期貨金額!F20) -> 0 | F23: =VALUE(期貨金額!G20) -> 0 | G23: =VALUE(期貨金額!H20) -> 0 | H23: =VALUE(期貨金額!I20) -> 0 | I23: =VALUE(期貨金額!J20) -> 0 | J23: =VALUE(期貨金額!K20) -> 0 | ... AH23: =VALUE(期貨金額!AI20) -> 0 | AI23: =AH23/$AH$26 -> 0
A24: P | B24: 1 | C24: =VALUE(期貨金額!D17) -> 0 | D24: =VALUE(期貨金額!E17) -> 0 | E24: =VALUE(期貨金額!F17) -> 0 | F24: =VALUE(期貨金額!G17) -> 0 | G24: =VALUE(期貨金額!H17) -> 0 | H24: =VALUE(期貨金額!I17) -> 0 | I24: =VALUE(期貨金額!J17) -> 0 | J24: =VALUE(期貨金額!K17) -> 0 | ... AH24: =VALUE(期貨金額!AI17) -> 0 | AI24: =AH24/$AH$26 -> 0
A25: Q | B25: 3 | C25: =VALUE(期貨金額!D18) -> 0 | D25: =VALUE(期貨金額!E18) -> 0 | E25: =VALUE(期貨金額!F18) -> 0 | F25: =VALUE(期貨金額!G18) -> 0 | G25: =VALUE(期貨金額!H18) -> 0 | H25: =VALUE(期貨金額!I18) -> 0 | I25: =VALUE(期貨金額!J18) -> 0 | J25: =VALUE(期貨金額!K18) -> 0 | ... AH25: =VALUE(期貨金額!AI18) -> 0 | AI25: =AH25/$AH$26 -> 0
A26: 合計 | C26: =SUM(C20:C25) -> 1817253 | D26: =SUM(D20:D25) -> 1834673 | E26: =SUM(E20:E25) -> 1792821 | F26: =SUM(F20:F25) -> 1792821 | G26: =SUM(G20:G25) -> 1933945 | H26: =SUM(H20:H25) -> 1938267 | I26: =SUM(I20:I25) -> 1754019 | J26: =SUM(J20:J25) -> 1743335 | ... AH26: =SUM(AH20:AH25) -> 4166541.8 | AI26: =AH26/AH$26 -> 1

Sheet 當年月推移
A1: 一、庫存金額(平均)
A2: 商品別 | D2: 一月 | E2: 二月 | F2: 三月 | G2: 四月 | H2: 五月 | I2: 六月 | J2: 七月 | K2: 八月 | L2: 九月 | M2: 十月 | N2: 十一月 | O2: 十二月 | P2: 平均 | Q2: 目標平均
A3: 管理全商品 | D3: =D4+D11+D16 -> 5.6949312e+08 | E3: =E4+E11+E16 -> 5.8305304e+08 | F3: =F4+F11+F16 -> 6.077964e+08 | G3: =G4+G11+G16 -> 6.1918973e+08 | H3: =H4+H11+H16 -> 0 | I3: =I4+I11+I16 -> 0 | J3: =J4+J11+J16 -> 0 | K3: =K4+K11+K16 -> 0 | ... P3: =P4+P11+P16 -> 594883076 | Q3: 4.6467758e+08
B4: 主商品 | D4: =SUM(D5:D10) -> 3.4221623e+08 | E4: =SUM(E5:E10) -> 3.4490165e+08 | F4: =SUM(F5:F10) -> 3.4852343e+08 | G4: =SUM(G5:G10) -> 3.4843962e+08 | H4: =SUM(H5:H10) -> 0 | I4: =SUM(I5:I10) -> 0 | J4: =SUM(J5:J10) -> 0 | K4: =SUM(K5:K10) -> 0 | ... P4: =SUM(P5:P10) -> 346020235 | Q4: 2.7303265e+08
C5: A 豐 田 | D5: =VALUE(月庫存金額!C2) -> 2.9289557e+08 | E5: =VALUE(月庫存金額!D2) -> 2.9427785e+08 | F5: =VALUE(月庫存金額!E2) -> 3.035471e+08 | G5: =VALUE(月庫存金額!F2) -> 3.0501569e+08 | H5: =VALUE(月庫存金額!G2) -> 0 | I5: =VALUE(月庫存金額!H2) -> 0 | J5: =VALUE(月庫存金額!I2) -> 0 | K5: =VALUE(月庫存金額!J2) -> 0 | ... P5: =VALUE(月庫存金額!O2) -> 298934055 | Q5: 2.3436966e+08
C6: J 油 料 | D6: =VALUE(月庫存金額!C4) -> 6894022.5 | E6: =VALUE(月庫存金額!D4) -> 7273219.5 | F6: =VALUE(月庫存金額!E4) -> 6022622.2 | G6: =VALUE(月庫存金額!F4) -> 6246401.7 | H6: =VALUE(月庫存金額!G4) -> 0 | I6: =VALUE(月庫存金額!H4) -> 0 | J6: =VALUE(月庫存金額!I4) -> 0 | K6: =VALUE(月庫存金額!J4) -> 0 | ... P6: =VALUE(月庫存金額!O4) -> 6609067 | Q6: 11732298
C7: O 工具對策 | D7: =VALUE(月庫存金額!C5) -> 11103888 | E7: =VALUE(月庫存金額!D5) -> 10717600 | F7: =VALUE(月庫存金額!E5) -> 7939466.9 | G7: =VALUE(月庫存金額!F5) -> 7405026.6 | H7: =VALUE(月庫存金額!G5) -> 0 | I7: =VALUE(月庫存金額!H5) -> 0 | J7: =VALUE(月庫存金額!I5) -> 0 | K7: =VALUE(月庫存金額!J5) -> 0 | ... P7: =VALUE(月庫存金額!O5) -> 9291496 | Q7: 1014645.1
C8: N 用品補修件 | D8: =VALUE(月庫存金額!C6) -> 21593173 | E8: =VALUE(月庫存金額!D6) -> 19382074 | F8: =VALUE(月庫存金額!E6) -> 19671571 | G8: =VALUE(月庫存金額!F6) -> 18629028 | H8: =VALUE(月庫存金額!G6) -> 0 | I8: =VALUE(月庫存金額!H6) -> 0 | J8: =VALUE(月庫存金額!I6) -> 0 | K8: =VALUE(月庫存金額!J6) -> 0 | ... P8: =VALUE(月庫存金額!O6) -> 19818962 | Q8: 18506619
C9: C 日 野 | D9: =VALUE(月庫存金額!C7) -> 0 | E9: =VALUE(月庫存金額!D7) -> 0 | F9: =VALUE(月庫存金額!E7) -> 0 | G9: =VALUE(月庫存金額!F7) -> 0 | H9: =VALUE(月庫存金額!G7) -> 0 | I9: =VALUE(月庫存金額!H7) -> 0 | J9: =VALUE(月庫存金額!I7) -> 0 | K9: =VALUE(月庫存金額!J7) -> 0 | ... P9: =VALUE(月庫存金額!O7) -> 0 | Q9: 0
C10: H 輪 胎 | D10: =VALUE(月庫存金額!C8) -> 9729574.1 | E10: =VALUE(月庫存金額!D8) -> 13250905 | F10: =VALUE(月庫存金額!E8) -> 11342668 | G10: =VALUE(月庫存金額!F8) -> 11143472 | H10: =VALUE(月庫存金額!G8) -> 0 | I10: =VALUE(月庫存金額!H8) -> 0 | J10: =VALUE(月庫存金額!I8) -> 0 | K10: =VALUE(月庫存金額!J8) -> 0 | ... P10: =VALUE(月庫存金額!O8) -> 11366655 | Q10: 7409428.3
B11: 其他 | D11: =SUM(D12:D15) -> 1990385.5 | E11: =SUM(E12:E15) -> 1846899.4 | F11: =SUM(F12:F15) -> 1660307 | G11: =SUM(G12:G15) -> 2449045.6 | H11: =SUM(H12:H15) -> 0 | I11: =SUM(I12:I15) -> 0 | J11: =SUM(J12:J15) -> 0 | K11: =SUM(K12:K15) -> 0 | ... P11: =SUM(P12:P15) -> 1986660 | Q11: 13138073
C12: E 噴射泵 | D12: =VALUE(月庫存金額!C9) -> 0 | E12: =VALUE(月庫存金額!D9) -> 0 | F12: =VALUE(月庫存金額!E9) -> 0 | G12: =VALUE(月庫存金額!F9) -> 0 | H12: =VALUE(月庫存金額!G9) -> 0 | I12: =VALUE(月庫存金額!H9) -> 0 | J12: =VALUE(月庫存金額!I9) -> 0 | K12: =VALUE(月庫存金額!J9) -> 0 | ... P12: =VALUE(月庫存金額!O9) -> 0 | Q12: 0
C13: F 電 裝 | D13: =VALUE(月庫存金額!C10) -> 1710555.9 | E13: =VALUE(月庫存金額!D10) -> 1534112.8 | F13: =VALUE(月庫存金額!E10) -> 1354194.5 | G13: =VALUE(月庫存金額!F10) -> 2181402.3 | H13: =VALUE(月庫存金額!G10) -> 0 | I13: =VALUE(月庫存金額!H10) -> 0 | J13: =VALUE(月庫存金額!I10) -> 0 | K13: =VALUE(月庫存金額!J10) -> 0 | ... P13: =VALUE(月庫存金額!O10) -> 1695067 | Q13: 1921849.4
C14: G 貨車冷氣 | D14: =VALUE(月庫存金額!C12) -> 0 | E14: =VALUE(月庫存金額!D12) -> 0 | F14: =VALUE(月庫存金額!E12) -> 0 | G14: =VALUE(月庫存金額!F12) -> 0 | H14: =VALUE(月庫存金額!G12) -> 0 | I14: =VALUE(月庫存金額!H12) -> 0 | J14: =VALUE(月庫存金額!I12) -> 0 | K14: =VALUE(月庫存金額!J12) -> 0 | ... P14: =VALUE(月庫存金額!O12) -> 0 | Q14: 0
C15: U 咖啡 | D15: =VALUE(月庫存金額!C14) -> 279829.61 | E15: =VALUE(月庫存金額!D14) -> 312786.57 | F15: =VALUE(月庫存金額!E14) -> 306112.52 | G15: =VALUE(月庫存金額!F14) -> 267643.33 | H15: =VALUE(月庫存金額!G14) -> 0 | I15: =VALUE(月庫存金額!H14) -> 0 | J15: =VALUE(月庫存金額!I14) -> 0 | K15: =VALUE(月庫存金額!J14) -> 0 | ... P15: =VALUE(月庫存金額!O14) -> 291593 | Q15: 410834.41
B16: LEXUS零件 | D16: =SUM(D17:D23) -> 2.252865e+08 | E16: =SUM(E17:E23) -> 2.3630449e+08 | F16: =SUM(F17:F23) -> 2.5761266e+08 | G16: =SUM(G17:G23) -> 2.6830107e+08 | H16: =SUM(H17:H23) -> 0 | I16: =SUM(I17:I23) -> 0 | J16: =SUM(J17:J23) -> 0 | K16: =SUM(K17:K23) -> 0 | ... P16: =SUM(P17:P23) -> 246876181 | Q16: 1.7850685e+08
C17: D LEXUS | D17: =VALUE(月庫存金額!C3) -> 2.1381399e+08 | E17: =VALUE(月庫存金額!D3) -> 2.1642168e+08 | F17: =VALUE(月庫存金額!E3) -> 2.3073545e+08 | G17: =VALUE(月庫存金額!F3) -> 2.421113e+08 | H17: =VALUE(月庫存金額!G3) -> 0 | I17: =VALUE(月庫存金額!H3) -> 0 | J17: =VALUE(月庫存金額!I3) -> 0 | K17: =VALUE(月庫存金額!J3) -> 0 | ... P17: =VALUE(月庫存金額!O3) -> 225770603 | Q17: 1.514092e+08
C18: M 油 料 | D18: =VALUE(月庫存金額!C13) -> 2731882.9 | E18: =VALUE(月庫存金額!D13) -> 2401477.7 | F18: =VALUE(月庫存金額!E13) -> 1864895.6 | G18: =VALUE(月庫存金額!F13) -> 1992262.9 | H18: =VALUE(月庫存金額!G13) -> 0 | I18: =VALUE(月庫存金額!H13) -> 0 | J18: =VALUE(月庫存金額!I13) -> 0 | K18: =VALUE(月庫存金額!J13) -> 0 | ... P18: =VALUE(月庫存金額!O13) -> 2247630 | Q18: 3134492.7
C19: S 工具對策 | D19: =VALUE(月庫存金額!C21) -> 161176 | E19: =VALUE(月庫存金額!D21) -> 161176 | F19: =VALUE(月庫存金額!E21) -> 161176 | G19: =VALUE(月庫存金額!F21) -> 161176 | H19: =VALUE(月庫存金額!G21) -> 0 | I19: =VALUE(月庫存金額!H21) -> 0 | J19: =VALUE(月庫存金額!I21) -> 0 | K19: =VALUE(月庫存金額!J21) -> 0 | ... P19: =VALUE(月庫存金額!O21) -> 161176 | Q19: 9206655.4
C20: V 用品補修件 | D20: =VALUE(月庫存金額!C20) -> 162800 | E20: =VALUE(月庫存金額!D20) -> 162800 | F20: =VALUE(月庫存金額!E20) -> 162800 | G20: =VALUE(月庫存金額!F20) -> 162800 | H20: =VALUE(月庫存金額!G20) -> 0 | I20: =VALUE(月庫存金額!H20) -> 0 | J20: =VALUE(月庫存金額!I20) -> 0 | K20: =VALUE(月庫存金額!J20) -> 0 | ... P20: =VALUE(月庫存金額!O20) -> 162800 | Q20: 10542089
C21: T 輪 胎 | D21: =VALUE(月庫存金額!C19) -> 8170824.8 | E21: =VALUE(月庫存金額!D19) -> 16891476 | F21: =VALUE(月庫存金額!E19) -> 24401516 | G21: =VALUE(月庫存金額!F19) -> 23605583 | H21: =VALUE(月庫存金額!G19) -> 0 | I21: =VALUE(月庫存金額!H19) -> 0 | J21: =VALUE(月庫存金額!I19) -> 0 | K21: =VALUE(月庫存金額!J19) -> 0 | ... P21: =VALUE(月庫存金額!O19) -> 18267350 | Q21: 3640844.9
C22: P 電 裝 | D22: =VALUE(月庫存金額!C11) -> 106839 | E22: =VALUE(月庫存金額!D11) -> 106839 | F22: =VALUE(月庫存金額!E11) -> 97968.03 | G22: =VALUE(月庫存金額!F11) -> 94797.33 | H22: =VALUE(月庫存金額!G11) -> 0 | I22: =VALUE(月庫存金額!H11) -> 0 | J22: =VALUE(月庫存金額!I11) -> 0 | K22: =VALUE(月庫存金額!J11) -> 0 | ... P22: =VALUE(月庫存金額!O11) -> 101611 | Q22: 127003.21
C23: Q 咖 啡 | D23: =VALUE(月庫存金額!C22) -> 138994 | E23: =VALUE(月庫存金額!D22) -> 159046 | F23: =VALUE(月庫存金額!E22) -> 188859.81 | G23: =VALUE(月庫存金額!F22) -> 173142 | H23: =VALUE(月庫存金額!G22) -> 0 | I23: =VALUE(月庫存金額!H22) -> 0 | J23: =VALUE(月庫存金額!I22) -> 0 | K23: =VALUE(月庫存金額!J22) -> 0 | ... P23: =VALUE(月庫存金額!O22) -> 165011 | Q23: 446571.5
B24: 二通路零件 | D24: =SUM(D25:D28) -> 13551161 | E24: =SUM(E25:E28) -> 14999903 | F24: =SUM(F25:F28) -> 15310386 | G24: =SUM(G25:G28) -> 16115786 | H24: =SUM(H25:H28) -> 0 | I24: =SUM(I25:I28) -> 0 | J24: =SUM(J25:J28) -> 0 | K24: =SUM(K25:K28) -> 0 | ... P24: =SUM(P25:P28) -> 14994309
C25: 2 二品牌一般 | D25: =VALUE(月庫存金額!C23) -> 0 | E25: =VALUE(月庫存金額!D23) -> 0 | F25: =VALUE(月庫存金額!E23) -> 0 | G25: =VALUE(月庫存金額!F23) -> 0 | H25: =VALUE(月庫存金額!G23) -> 0 | I25: =VALUE(月庫存金額!H23) -> 0 | J25: =VALUE(月庫存金額!I23) -> 0 | K25: =VALUE(月庫存金額!J23) -> 0 | ... P25: =VALUE(月庫存金額!O23) -> 0
C26: 3 二品牌油料 | D26: =VALUE(月庫存金額!C24) -> 0 | E26: =VALUE(月庫存金額!D24) -> 0 | F26: =VALUE(月庫存金額!E24) -> 0 | G26: =VALUE(月庫存金額!F24) -> 0 | H26: =VALUE(月庫存金額!G24) -> 0 | I26: =VALUE(月庫存金額!H24) -> 0 | J26: =VALUE(月庫存金額!I24) -> 0 | K26: =VALUE(月庫存金額!J24) -> 0 | ... P26: =VALUE(月庫存金額!O24) -> 0
C27: 4 二品牌輪胎 | D27: =VALUE(月庫存金額!C25) -> 9106516.7 | E27: =VALUE(月庫存金額!D25) -> 9492109.1 | F27: =VALUE(月庫存金額!E25) -> 9381405.6 | G27: =VALUE(月庫存金額!F25) -> 8789643.9 | H27: =VALUE(月庫存金額!G25) -> 0 | I27: =VALUE(月庫存金額!H25) -> 0 | J27: =VALUE(月庫存金額!I25) -> 0 | K27: =VALUE(月庫存金額!J25) -> 0 | ... P27: =VALUE(月庫存金額!O25) -> 9192419
C28: 5 二品牌化學品 | D28: =VALUE(月庫存金額!C26) -> 4444644.1 | E28: =VALUE(月庫存金額!D26) -> 5507793.5 | F28: =VALUE(月庫存金額!E26) -> 5928979.9 | G28: =VALUE(月庫存金額!F26) -> 7326142.5 | H28: =VALUE(月庫存金額!G26) -> 0 | I28: =VALUE(月庫存金額!H26) -> 0 | J28: =VALUE(月庫存金額!I26) -> 0 | K28: =VALUE(月庫存金額!J26) -> 0 | ... P28: =VALUE(月庫存金額!O26) -> 5801890
A29: 非管理 | C29: L 小車用品 | D29: =VALUE(月庫存金額!C15) -> 1636322.7 | E29: =VALUE(月庫存金額!D15) -> 1606880.5 | F29: =VALUE(月庫存金額!E15) -> 1608277.8 | G29: =VALUE(月庫存金額!F15) -> 1614727.6 | H29: =VALUE(月庫存金額!G15) -> 0 | I29: =VALUE(月庫存金額!H15) -> 0 | J29: =VALUE(月庫存金額!I15) -> 0 | K29: =VALUE(月庫存金額!J15) -> 0 | ... P29: =VALUE(月庫存金額!O15) -> 1616553
C30: W 服務商品 | D30: =VALUE(月庫存金額!C16) -> 0 | E30: =VALUE(月庫存金額!D16) -> 0 | F30: =VALUE(月庫存金額!E16) -> 0 | G30: =VALUE(月庫存金額!F16) -> 0 | H30: =VALUE(月庫存金額!G16) -> 0 | I30: =VALUE(月庫存金額!H16) -> 0 | J30: =VALUE(月庫存金額!I16) -> 0 | K30: =VALUE(月庫存金額!J16) -> 0 | ... P30: =VALUE(月庫存金額!O16) -> 0
C31: X Lexus精品 | D31: =VALUE(月庫存金額!C17) -> 4738534.2 | E31: =VALUE(月庫存金額!D17) -> 6616871.4 | F31: =VALUE(月庫存金額!E17) -> 6569016.9 | G31: =VALUE(月庫存金額!F17) -> 6269507.1 | H31: =VALUE(月庫存金額!G17) -> 0 | I31: =VALUE(月庫存金額!H17) -> 0 | J31: =VALUE(月庫存金額!I17) -> 0 | K31: =VALUE(月庫存金額!J17) -> 0 | ... P31: =VALUE(月庫存金額!O17) -> 6048482
C32: 8 活動贈品 | D32: =VALUE(月庫存金額!C18) -> 12592603 | E32: =VALUE(月庫存金額!D18) -> 10668231 | F32: =VALUE(月庫存金額!E18) -> 11760706 | G32: =VALUE(月庫存金額!F18) -> 10427096 | H32: =VALUE(月庫存金額!G18) -> 0 | I32: =VALUE(月庫存金額!H18) -> 0 | J32: =VALUE(月庫存金額!I18) -> 0 | K32: =VALUE(月庫存金額!J18) -> 0 | ... P32: =VALUE(月庫存金額!O18) -> 11362159
C33: 6 | P33: =VALUE(月庫存金額!O27) -> 0
C34: 7 | P34: =VALUE(月庫存金額!O28) -> 0
A35: 二、庫存金額(期末)
A36: 商品別 | D36: 一月 | E36: 二月 | F36: 三月 | G36: 四月 | H36: 五月 | I36: 六月 | J36: 七月 | K36: 八月 | L36: 九月 | M36: 十月 | N36: 十一月 | O36: 十二月 | P36: 平均
A37: 管理全商品 | D37: =D38+D45+D50 -> 587014761 | E37: =E38+E45+E50 -> 627453357 | F37: =F38+F45+F50 -> 621535544 | G37: =G38+G45+G50 -> 645404569 | H37: =H38+H45+H50 -> 0 | I37: =I38+I45+I50 -> 0 | J37: =J38+J45+J50 -> 0 | K37: =K38+K45+K50 -> 0 | ... P37: =P38+P45+P50 -> 620352059
B38: 主商品 | D38: =SUM(D39:D44) -> 354479947 | E38: =SUM(E39:E44) -> 371926023 | F38: =SUM(F39:F44) -> 357064395 | G38: =SUM(G39:G44) -> 369063594 | H38: =SUM(H39:H44) -> 0 | I38: =SUM(I39:I44) -> 0 | J38: =SUM(J39:J44) -> 0 | K38: =SUM(K39:K44) -> 0 | ... P38: =SUM(P39:P44) -> 363133490
C39: A 豐 田 | D39: =VALUE(月庫存金額!P2) -> 301522048 | E39: =VALUE(月庫存金額!Q2) -> 312011790 | F39: =VALUE(月庫存金額!R2) -> 307804297 | G39: =VALUE(月庫存金額!S2) -> 311952904 | H39: =VALUE(月庫存金額!T2) -> 0 | I39: =VALUE(月庫存金額!U2) -> 0 | J39: =VALUE(月庫存金額!V2) -> 0 | K39: =VALUE(月庫存金額!W2) -> 0 | ... P39: =VALUE(月庫存金額!AB2) -> 308322760
C40: J 油 料 | D40: =VALUE(月庫存金額!P4) -> 11731801 | E40: =VALUE(月庫存金額!Q4) -> 6677578 | F40: =VALUE(月庫存金額!R4) -> 7953023 | G40: =VALUE(月庫存金額!S4) -> 6400194 | H40: =VALUE(月庫存金額!T4) -> 0 | I40: =VALUE(月庫存金額!U4) -> 0 | J40: =VALUE(月庫存金額!V4) -> 0 | K40: =VALUE(月庫存金額!W4) -> 0 | ... P40: =VALUE(月庫存金額!AB4) -> 8190649
...

Sheet 去年月推移_old
A1: 一、庫存金額(平均) | D1: 1 | E1: 2 | F1: 3 | G1: 4 | H1: 5 | I1: 6 | J1: 7 | K1: 8 | L1: 9 | M1: 10 | N1: 11 | O1: 12
A2: 商品別 | D2: 一月 | E2: 二月 | F2: 三月 | G2: 四月 | H2: 五月 | I2: 六月 | J2: 七月 | K2: 八月 | L2: 九月 | M2: 十月 | N2: 十一月 | O2: 十二月 | P2: 平均
A3: 管理全商品 | D3: 4.1080692e+08 | E3: 4.1963624e+08 | F3: 4.1730959e+08 | G3: 411340937 | H3: =H4+H12 -> 4.0040116e+08 | I3: 3.9657174e+08 | J3: 3.9113939e+08 | K3: 3.9615566e+08 | L3: 4.046622e+08 | M3: 3.8601496e+08 | N3: 3.9065155e+08 | O3: 4.0456009e+08 | P3: =AVERAGE(D3:O3) -> 4.0243754e+08
B4: 主商品 | D4: 3.9436583e+08 | E4: 4.0300339e+08 | F4: 4.0144044e+08 | G4: 3.9633927e+08 | H4: =SUM(H5:H11) -> 3.8781613e+08 | I4: 3.8411867e+08 | J4: 3.7788598e+08 | K4: 3.8220703e+08 | L4: 3.9100219e+08 | M4: 3.7300402e+08 | N4: 3.7736307e+08 | O4: 3.910731e+08 | P4: =AVERAGE(D4:O4) -> 3.8830159e+08
C5: A 豐 田 | D5: 2.2150033e+08 | E5: 2.3385502e+08 | F5: 2.3302646e+08 | G5: 2.2334426e+08 | H5: 2.2458323e+08 | I5: 2.1846245e+08 | J5: 2.1232696e+08 | K5: 2.1699424e+08 | L5: 2.2339088e+08 | M5: 2.0861755e+08 | N5: 2.1008342e+08 | O5: 2.2050072e+08 | P5: =AVERAGE(D5:O5) -> 2.2055713e+08
C6: D LEXUS零件 | D6: 87037849 | E6: 83565652 | F6: 82671583 | G6: 86154426 | H6: 77698382 | I6: 81308792 | J6: 84169228 | K6: 83292222 | L6: 81118791 | M6: 78568871 | N6: 78107584 | O6: 80902124 | P6: =AVERAGE(D6:O6) -> 82049625
C7: J 油 料 | D7: 14373862 | E7: 13547486 | F7: 14729059 | G7: 18156706 | H7: 19095589 | I7: 16806186 | J7: 13134520 | K7: 14558409 | L7: 17843013 | M7: 15070446 | N7: 15927525 | O7: 14884075 | P7: =AVERAGE(D7:O7) -> 15677240
C8: O 工具對策 | D8: 6860827.1 | E8: 6451848.3 | F8: 5877684.6 | G8: 5925421.4 | H8: 5130155.9 | I8: 5552409.4 | J8: 5488159.4 | K8: 4993557.7 | L8: 5501341.8 | M8: 5765568.4 | N8: 5550510.4 | O8: 5618462.5 | P8: =AVERAGE(D8:O8) -> 5726328.9
C9: N 用品補修件 | D9: 17382835 | E9: 18745134 | F9: 18741414 | G9: 16314307 | H9: 16586629 | I9: 17847243 | J9: 17177111 | K9: 17163439 | L9: 16676389 | M9: 16370840 | N9: 17103863 | O9: 16177110 | P9: =AVERAGE(D9:O9) -> 17190526
C10: C 日 野 | D10: 40477353 | E10: 40164755 | F10: 40682812 | G10: 40448376 | H10: 38895426 | I10: 38373318 | J10: 39395707 | K10: 38987535 | L10: 40691431 | M10: 41694370 | N10: 44919608 | O10: 46326310 | P10: =AVERAGE(D10:O10) -> 40921417
C11: H 輪 胎 | D11: 6732775.7 | E11: 6673495.1 | F11: 5711419.3 | G11: 5995783.8 | H11: 5826722.9 | I11: 5768275.6 | J11: 6194288 | K11: 6217631.7 | L11: 5780346.7 | M11: 6916377.7 | N11: 5670564.9 | O11: 6664297.3 | P11: =AVERAGE(D11:O11) -> 6179331.5
B12: 其他 | D12: 16441092 | E12: 16632854 | F12: 15869151 | G12: 15001662 | H12: =SUM(H13:H18) -> 12585026 | I12: 12453063 | J12: 13253416 | K12: 13948629 | L12: 13660011 | M12: 13010936 | N12: 13288482 | O12: 13486986 | P12: =AVERAGE(D12:O12) -> 14135942
C13: E 噴射泵 | D13: 1738181.7 | E13: 1526474.6 | F13: 1475703.2 | G13: 1510813.5 | H13: 1470976.5 | I13: 1438765.6 | J13: 1549308.5 | K13: 1436436.1 | L13: 1573119.1 | M13: 1463383 | N13: 1464064.3 | O13: 1486034.5 | P13: =AVERAGE(D13:O13) -> 1511105
C14: F 電 裝 | D14: 11390817 | E14: 11690788 | F14: 11037235 | G14: 10281145 | H14: 9005840.5 | I14: 8950838.7 | J14: 9640436.3 | K14: 10364817 | L14: 9983224.9 | M14: 9752395.7 | N14: 10083370 | O14: 10133665 | P14: =AVERAGE(D14:O14) -> 10192881
C15: P 政 策 | D15: 3091029 | E15: 3091029 | F15: 3091029 | G15: 3083065.5 | H15: 1835942 | I15: 1829850.4 | J15: 1811129 | K15: 1825145.4 | L15: 1826112 | M15: 1551121.3 | N15: 1526333 | O15: 1526333 | P15: =AVERAGE(D15:O15) -> 2174009.9
C16: G 貨車冷氣 | D16: 0 | E16: 0 | F16: 0 | G16: 0 | H16: 0 | I16: 0 | J16: 0 | K16: 0 | L16: 0 | M16: 0 | N16: 0 | O16: 0 | P16: =AVERAGE(D16:O16) -> 0
C17: M 開勵委託 | D17: 0 | E17: 0 | F17: 0 | G17: 0 | H17: 0 | I17: 0 | J17: 0 | K17: 0 | L17: 0 | M17: 0 | N17: 0 | O17: 0 | P17: =AVERAGE(D17:O17) -> 0
C18: U 咖啡 | D18: 221064.84 | E18: 324561.57 | F18: 265183.77 | G18: 126638.4 | H18: 272267.19 | I18: 233608.67 | J18: 252542.42 | K18: 322230.32 | L18: 277554.67 | M18: 244036.29 | N18: 214714.5 | O18: 340953.55 | P18: =AVERAGE(D18:O18) -> 257946.35
A19: 非管理 | C19: L 小車用品 | D19: 3538208.4 | E19: 2882522.1 | F19: 2562157.2 | G19: 2207710 | H19: 2766354.6 | I19: 3671224.2 | J19: 3466682.7 | K19: 3131888.5 | L19: 2830403.6 | M19: 2711648.7 | N19: 2600600.1 | O19: 2567092.1 | P19: =AVERAGE(D19:O19) -> 2911374.3
C20: W 服務商品 | D20: 1271054.6 | E20: 1367506.1 | F20: 1260832.1 | G20: 1194335.2 | H20: 1554194.7 | I20: 1862773 | J20: 1903316.1 | K20: 1879103.8 | L20: 2369591.8 | M20: 2837568.8 | N20: 2227512.4 | O20: 2096725.8 | P20: =AVERAGE(D20:O20) -> 1818709.5
C21: X Lexus精品 | D21: 0 | E21: 0 | F21: 0 | G21: 0 | H21: 0 | I21: 0 | J21: 0 | K21: 0 | L21: 0 | M21: 0 | N21: 0 | O21: 0 | P21: =AVERAGE(D21:O21) -> 0
A22: PS. L小車用品改列入『非管理』商品。
A23: 二、庫存金額(期末)
A24: 商品別 | D24: 一月 | E24: 二月 | F24: 三月 | G24: 四月 | H24: 五月 | I24: 六月 | J24: 七月 | K24: 八月 | L24: 九月 | M24: 十月 | N24: 十一月 | O24: 十二月 | P24: 平均
A25: 管理全商品 | D25: 419165791 | E25: 420827447 | F25: 414719759 | G25: 417845177 | H25: 396517725 | I25: 396113919 | J25: 392983234 | K25: 401986946 | L25: 402506684 | M25: 377027372 | N25: 396496616 | O25: 418833261 | P25: =AVERAGE(D25:O25) -> 4.0458533e+08
B26: 主商品 | D26: 402418558 | E26: 404123741 | F26: 399740305 | G26: 403409048 | H26: 383840140 | I26: 383810440 | J26: 379181631 | K26: 386747331 | L26: 389160417 | M26: 363879747 | N26: 383156928 | O26: 405126246 | P26: =AVERAGE(D26:O26) -> 3.9038288e+08
C27: A 豐 田 | D27: 232229290 | E27: 234904839 | F27: 225285265 | G27: 230507712 | H27: 221346140 | I27: 212699675 | J27: 212943216 | K27: 218661583 | L27: 220584039 | M27: 205591403 | N27: 213732474 | O27: 233979428 | P27: =AVERAGE(D27:O27) -> 2.2187209e+08
C28: D LEXUS零件 | D28: 86708415 | E28: 82605553 | F28: 83885473 | G28: 85969483 | H28: 76320956 | I28: 81839810 | J28: 84824270 | K28: 81990635 | L28: 81218719 | M28: 76661389 | N28: 80442494 | O28: 82693475 | P28: =AVERAGE(D28:O28) -> 82096723
C29: J 油 料 | D29: 15313052 | E29: 14084421 | F29: 20510895 | G29: 19042321 | H29: 18256455 | I29: 17783984 | J29: 14700388 | K29: 16795363 | L29: 15646861 | M29: 14889470 | N29: 15708480 | O29: 12224149 | P29: =AVERAGE(D29:O29) -> 16246320
C30: O 工具對策 | D30: 6338132 | E30: 6016056 | F30: 5898498 | G30: 6434186 | H30: 4922461 | I30: 7341973 | J30: 5325528 | K30: 4975124 | L30: 6522705 | M30: 5390520 | N30: 5630861 | O30: 5473130 | P30: =AVERAGE(D30:O30) -> 5855764.5
C31: N 用品補修件 | D31: 16660596 | E31: 19008244 | F31: 17210623 | G31: 16117801 | H31: 18940743 | I31: 16616268 | J31: 17341387 | K31: 17156572 | L31: 16687246 | M31: 16186710 | N31: 16584357 | O31: 15560155 | P31: =AVERAGE(D31:O31) -> 17005892
C32: C 日 野 | D32: 39311147 | E32: 40748444 | F32: 39656002 | G32: 40914909 | H32: 37565607 | I32: 40591125 | J32: 38324927 | K32: 40220698 | L32: 41722720 | M32: 40607233 | N32: 44802786 | O32: 48586257 | P32: =AVERAGE(D32:O32) -> 41087655
C33: H 輪 胎 | D33: 5857926 | E33: 6756184 | F33: 7293549 | G33: 4422636 | H33: 6487778 | I33: 6937605 | J33: 5721915 | K33: 6947356 | L33: 6778127 | M33: 4553022 | N33: 6255476 | O33: 6609652 | P33: =AVERAGE(D33:O33) -> 6218435.5
B34: 其他 | D34: 16747233 | E34: 16703706 | F34: 14979454 | G34: 14436129 | H34: 12677585 | I34: 12303479 | J34: 13801603 | K34: 15239615 | L34: 13346267 | M34: 13147625 | N34: 13339688 | O34: 13707015 | P34: =AVERAGE(D34:O34) -> 14202450
C35: E 噴射泵 | D35: 1923728 | E35: 1482201 | F35: 1455853 | G35: 1447618 | H35: 1435126 | I35: 1427439 | J35: 1424106 | K35: 1432332 | L35: 1429798 | M35: 1416680 | N35: 1511224 | O35: 1402789 | P35: =AVERAGE(D35:O35) -> 1482407.8
C36: F 電 裝 | D36: 11409214 | E36: 11671956 | F36: 10303342 | G36: 9705347 | H36: 9114127 | I36: 8863656 | J36: 10198733 | K36: 11619791 | L36: 9828662 | M36: 9948737 | N36: 9995101 | O36: 10366434 | P36: =AVERAGE(D36:O36) -> 10252092
C37: P 政 策 | D37: 3091029 | E37: 3091029 | F37: 3091029 | G37: 3043248 | H37: 1835942 | I37: 1811129 | J37: 1811129 | K37: 1826112 | L37: 1826112 | M37: 1526333 | N37: 1526333 | O37: 1526333 | P37: =AVERAGE(D37:O37) -> 2167146.5
C38: G 貨車冷氣 | D38: 0 | E38: 0 | F38: 0 | G38: 0 | H38: 0 | I38: 0 | J38: 0 | K38: 0 | L38: 0 | M38: 0 | N38: 0 | O38: 0 | P38: =AVERAGE(D38:O38) -> 0
C39: M 開勵委託 | D39: 0 | E39: 0 | F39: 0 | G39: 0 | H39: 0 | I39: 0 | J39: 0 | K39: 0 | L39: 0 | M39: 0 | N39: 0 | O39: 0 | P39: =AVERAGE(D39:O39) -> 0
C40: U 咖啡 | D40: 323262 | E40: 458520 | F40: 129230 | G40: 239916 | H40: 292390 | I40: 201255 | J40: 367635 | K40: 361380 | L40: 261695 | M40: 255875 | N40: 307030 | O40: 411459 | P40: =AVERAGE(D40:O40) -> 300803.92
...

Sheet 去年月推移
A1: 一、庫存金額(平均) | D1: 1 | E1: 2 | F1: 3 | G1: 4 | H1: 5 | I1: 6 | J1: 7 | K1: 8 | L1: 9 | M1: 10 | N1: 11 | O1: 12
A2: 商品別 | D2: 一月 | E2: 二月 | F2: 三月 | G2: 四月 | H2: 五月 | I2: 六月 | J2: 七月 | K2: 八月 | L2: 九月 | M2: 十月 | N2: 十一月 | O2: 十二月 | P2: 平均
A3: 管理全商品 | D3: 5.2715308e+08 | E3: 4.9318409e+08 | F3: 5.1270763e+08 | G3: 5.324525e+08 | H3: 5.3225476e+08 | I3: 5.2868345e+08 | J3: 5.1225477e+08 | K3: 5.2995131e+08 | L3: 5.2070838e+08 | M3: 5.0143214e+08 | N3: 5.2191783e+08 | O3: 5.7892517e+08 | P3: =P4+P11+P16+P24 -> 5.4818033e+08
B4: 主商品 | D4: 3.0126798e+08 | E4: 2.8090877e+08 | F4: 2.8796648e+08 | G4: 3.0600356e+08 | H4: 3.0894245e+08 | I4: 3.068138e+08 | J4: 2.948152e+08 | K4: 3.0775911e+08 | L4: 3.0138886e+08 | M4: 2.9156116e+08 | N4: 3.0239879e+08 | O4: 3.2576537e+08 | P4: =SUM(P5:P10) -> 3.2441952e+08
C5: A 豐 田 | D5: 2.8932133e+08 | E5: 294828766 | F5: 2.8845801e+08 | G5: 2.9697959e+08 | H5: 2.9049416e+08 | I5: 2.7888011e+08 | J5: 2.6372121e+08 | K5: 2.7612977e+08 | L5: 2.6256632e+08 | M5: 2.6746503e+08 | N5: 2.9443678e+08 | O5: 277734691 | P5: =AVERAGE(D5:O5) -> 2.8175131e+08
C6: J 油 料 | D6: 7544209.5 | E6: 8684465.6 | F6: 6315696.9 | G6: 6379190 | H6: 5803713.5 | I6: 5058505.9 | J6: 5686301.4 | K6: 5374548.7 | L6: 6312221.4 | M6: 6147893.6 | N6: 6366239.7 | O6: 6811858.2 | P6: =AVERAGE(D6:O6) -> 6373737
C7: O 工具對策 | D7: 1762491.6 | E7: 1694362 | F7: 1637628.2 | G7: 1569700 | H7: 3746962.9 | I7: 4566381.8 | J7: 3929388.1 | K7: 7488577.2 | L7: 6567855 | M7: 11974556 | N7: 11121669 | O7: 10675770 | P7: =AVERAGE(D7:O7) -> 5561278.4
C8: N 用品補修件 | D8: 19939385 | E8: 18665091 | F8: 19997372 | G8: 20372883 | H8: 19958825 | I8: 18999753 | J8: 18758457 | K8: 19611807 | L8: 19531057 | M8: 19581493 | N8: 19973997 | O8: 21114101 | P8: =AVERAGE(D8:O8) -> 19708685
C9: C 日 野 | D9: 0 | E9: 0 | F9: 0 | G9: 0 | H9: 0 | I9: 0 | J9: 0 | K9: 0 | L9: 0 | M9: 0 | N9: 0 | O9: 0 | P9: =AVERAGE(D9:O9) -> 0
C10: H 輪 胎 | D10: 10052817 | E10: 11889240 | F10: 11100501 | G10: 10776949 | H10: 10712095 | I10: 10076009 | J10: 10093905 | K10: 11680012 | L10: 11678819 | M10: 12475311 | N10: 12329428 | O10: 9428954.5 | P10: =AVERAGE(D10:O10) -> 11024503
B11: 其他 | D11: 10653907 | E11: 10432864 | F11: 10082267 | G11: 11239741 | H11: 11694706 | I11: 11026164 | J11: 9465851.8 | K11: 11277474 | L11: 12077131 | M11: 9444889.9 | N11: 9774971.9 | O11: 10533517 | P11: =SUM(P12:P15) -> 10884203
C12: E 噴射泵 | D12: 0 | E12: 0 | F12: 0 | G12: 0 | H12: 0 | I12: 0 | J12: 0 | K12: 0 | L12: 0 | M12: 0 | N12: 0 | O12: 0 | P12: =AVERAGE(D12:O12) -> 0
