Workbook

Sheet 2025年
A1: 2025年零件部楊梅配銷室月報
A2: 項目 | E2: 當月目標 | F2: 當月達成率 | G2: 1月 | H2: 2月 | I2: 3月 | J2: 4月 | K2: 5月 | L2: 6月 | M2: 7月 | N2: 8月 | O2: 9月 | P2: 10月 | Q2: 11月 | R2: 12月 | S2: 平均累計 | T2: 累計達成率 | Y2: 12
A3: 材敏現場人員數 | E3: --- | F3: --- | G3: 98 | H3: 96 | I3: 96 | J3: 93 | K3: 93 | L3: 96 | M3: 105 | N3: 101 | O3: 102 | P3: 100 | Q3: 106 | R3: 110 | S3: =AVERAGE(G3:R3) -> 99.666667 | T3: --- | U3: 材敏大物25--鈞傑/鈞凱+(進貨17+出貨29)--小鳳+P9(27)
A4: 作業量 | B4: 進貨 | C4: 點數 | E4: --- | F4: --- | G4: ='進貨點數(同期比)'!B53 -> 129842 | H4: ='進貨點數(同期比)'!C53 -> 102438 | I4: ='進貨點數(同期比)'!D53 -> 99561 | J4: ='進貨點數(同期比)'!E53 -> 103426 | K4: ='進貨點數(同期比)'!F53 -> 75605 | L4: ='進貨點數(同期比)'!G53 -> 102232 | M4: ='進貨點數(同期比)'!H53 -> 98650 | N4: ='進貨點數(同期比)'!I53 -> 95964 | ... R4: ='進貨點數(同期比)'!M53 -> 100688 | S4: =AVERAGE(G4:R4) -> 100304.75 | T4: --- | U4: 參考p7
D5: 同期比 | G5: ='進貨點數(同期比)'!B55 -> 1.1711721 | H5: ='進貨點數(同期比)'!C55 -> 1.3315742 | I5: ='進貨點數(同期比)'!D55 -> 1.1038784 | J5: ='進貨點數(同期比)'!E55 -> 1.0694558 | K5: ='進貨點數(同期比)'!F55 -> 0.80586881 | L5: ='進貨點數(同期比)'!G55 -> 1.0862802 | M5: ='進貨點數(同期比)'!H55 -> 0.97809814 | N5: ='進貨點數(同期比)'!I55 -> 1.0350317 | ... R5: ='進貨點數(同期比)'!M55 -> 0.8812954 | S5: =AVERAGE(G5:R5) -> 1.0364934 | U5: 參考進貨點數(同期比)
C6: PCS數 | E6: --- | F6: --- | G6: ='進貨點數(同期比)'!B54 -> 1492848 | H6: ='進貨點數(同期比)'!C54 -> 1547363 | I6: ='進貨點數(同期比)'!D54 -> 1584863 | J6: ='進貨點數(同期比)'!E54 -> 1569348 | K6: ='進貨點數(同期比)'!F54 -> 1438634 | L6: ='進貨點數(同期比)'!G54 -> 1640073 | M6: ='進貨點數(同期比)'!H54 -> 1737019 | N6: ='進貨點數(同期比)'!I54 -> 1664088 | ... R6: ='進貨點數(同期比)'!M54 -> 1922967 | S6: =AVERAGE(G6:R6) -> 1673806.3 | T6: ---
D7: 同期比 | G7: ='進貨點數(同期比)'!B56 -> 0.88989724 | H7: ='進貨點數(同期比)'!C56 -> 1.2081345 | I7: ='進貨點數(同期比)'!D56 -> 1.0958612 | J7: ='進貨點數(同期比)'!E56 -> 1.0650132 | K7: ='進貨點數(同期比)'!F56 -> 0.97490423 | L7: ='進貨點數(同期比)'!G56 -> 1.1353821 | M7: ='進貨點數(同期比)'!H56 -> 1.0309287 | N7: ='進貨點數(同期比)'!I56 -> 1.1208191 | ... R7: ='進貨點數(同期比)'!M56 -> 1.0802014 | S7: =AVERAGE(G7:R7) -> 1.096287
C8: 加班時數 | E8: --- | F8: --- | G8: =加班時數!B7 -> 298.9 | H8: =加班時數!C7 -> 365.7 | I8: =加班時數!D7 -> 297.3 | J8: =加班時數!E7 -> 266.8 | K8: =加班時數!F7 -> 234.8 | L8: =加班時數!G7 -> 433.3 | M8: =加班時數!H7 -> 546.7 | N8: =加班時數!I7 -> 390.2 | ... R8: =加班時數!M7 -> 232.1 | S8: =AVERAGE(G8:R8) -> 380.33333 | U8: I:\3楊梅配銷室\06.共同事務\A.月報\106年\月報新版共二頁-2017年材敏加班統計，加班合計
B9: 出貨 | C9: 點數 | E9: --- | F9: --- | G9: ='出貨點數(其他附件)'!B215 -> 339138 | H9: ='出貨點數(其他附件)'!C215 -> 341523 | I9: ='出貨點數(其他附件)'!D215 -> 376721 | J9: ='出貨點數(其他附件)'!E215 -> 341179 | K9: ='出貨點數(其他附件)'!F215 -> 345170 | L9: ='出貨點數(其他附件)'!G215 -> 365956 | M9: ='出貨點數(其他附件)'!H215 -> 393712 | N9: ='出貨點數(其他附件)'!I215 -> 367245 | ... R9: ='出貨點數(其他附件)'!M215 -> 404546 | S9: =AVERAGE(G9:R9) -> 361595.25 | T9: --- | U9: 參考p1
D10: 同期比 | G10: ='出貨點數(其他附件)'!B216 -> 0.79919783 | H10: ='出貨點數(其他附件)'!C216 -> 1.1985997 | I10: ='出貨點數(其他附件)'!D216 -> 1.017964 | J10: ='出貨點數(其他附件)'!E216 -> 1.0032493 | K10: ='出貨點數(其他附件)'!F216 -> 0.95810827 | L10: ='出貨點數(其他附件)'!G216 -> 1.0851243 | M10: ='出貨點數(其他附件)'!H216 -> 1.0252383 | N10: ='出貨點數(其他附件)'!I216 -> 0.96499941 | ... R10: ='出貨點數(其他附件)'!M216 -> 0.99791067 | S10: =AVERAGE(G10:R10) -> 1.0001284
C11: HF點數 | E11: --- | F11: --- | G11: 78287 | H11: 79015 | I11: 82801 | J11: 75333 | K11: 73855 | L11: 79081 | M11: 90281 | N11: 83916 | O11: 79688 | P11: 82371 | Q11: 78230 | R11: 99363 | S11: =AVERAGE(G11:R11) -> 81851.75 | U11: 參考p8 | V11: (台中倉全日出貨量DLR/HF+湖內副倉全日出貨量DLR/HF)-I數
C12: PCS數 | E12: --- | F12: --- | G12: ='出貨點數(其他附件)'!B234 -> 2533491 | H12: ='出貨點數(其他附件)'!C234 -> 2080755 | I12: ='出貨點數(其他附件)'!D234 -> 2480308 | J12: ='出貨點數(其他附件)'!E234 -> 2305800 | K12: ='出貨點數(其他附件)'!F234 -> 2427856 | L12: ='出貨點數(其他附件)'!G234 -> 2457339 | M12: ='出貨點數(其他附件)'!H234 -> 2652432 | N12: ='出貨點數(其他附件)'!I234 -> 2365728 | ... R12: ='出貨點數(其他附件)'!M234 -> 2769707 | S12: =AVERAGE(G12:R12) -> 2445731.1 | T12: --- | U12: 參考p1
D13: 同期比 | G13: ='出貨點數(其他附件)'!B235 -> 0.92004061 | H13: ='出貨點數(其他附件)'!C235 -> 1.1098141 | I13: ='出貨點數(其他附件)'!D235 -> 1.0096931 | J13: ='出貨點數(其他附件)'!E235 -> 1.0277572 | K13: ='出貨點數(其他附件)'!F235 -> 1.0022089 | L13: ='出貨點數(其他附件)'!G235 -> 1.0465232 | M13: ='出貨點數(其他附件)'!H235 -> 1.0403399 | N13: ='出貨點數(其他附件)'!I235 -> 0.96951933 | ... R13: ='出貨點數(其他附件)'!M235 -> 0.99400127 | S13: =AVERAGE(G13:R13) -> 1.017185
C14: HF PCS數 | E14: --- | F14: --- | G14: 549800 | H14: 431019 | I14: 488867 | J14: 424842 | K14: 445094 | L14: 475098 | M14: 496386 | N14: 432852 | O14: 448755 | P14: 487495 | Q14: 488841 | R14: 598700 | S14: =AVERAGE(G14:R14) -> 480645.75 | U14: 參考p8 | V14: (台中倉全日出貨量DLR/HF+湖內副倉全日出貨量DLR/HF)-PCS數
C15: 加班時數 | E15: --- | F15: --- | G15: =加班時數!B18 -> 792.1 | H15: =加班時數!C18 -> 411.5 | I15: =加班時數!D18 -> 710.4 | J15: =加班時數!E18 -> 635.1 | K15: =加班時數!F18 -> 612.3 | L15: =加班時數!G18 -> 609.8 | M15: =加班時數!H18 -> 416.4 | N15: =加班時數!I18 -> 709 | ... R15: =加班時數!M18 -> 1233 | S15: =AVERAGE(G15:R15) -> 744.875
B16: 優先開箱點數 | C16: 中小物 | E16: --- | F16: --- | G16: 797 | H16: 807 | I16: 1588 | J16: 561 | K16: 508 | L16: 763 | M16: 1065 | N16: 808 | O16: 868 | P16: 784 | Q16: 855 | R16: 913 | S16: =AVERAGE(G16:R16) -> 859.75 | T16: --- | U16: 抓QB
C17: 大物 | E17: --- | F17: --- | G17: 2157 | H17: 1542 | I17: 1241 | J17: 1866 | K17: 1032 | L17: 3456 | M17: 2688 | N17: 2395 | O17: 2177 | P17: 2353 | Q17: 2434 | R17: 1808 | S17: =AVERAGE(G17:R17) -> 2095.75 | T17: --- | U17: 慶林兄提供
B18: 包裝 | C18: 點數 | E18: --- | F18: --- | G18: 23959 | H18: 19984 | I18: 22267 | J18: 22159 | K18: 16404 | L18: 19244 | M18: 23324 | N18: 18160 | O18: 20841 | P18: 21404 | Q18: 21192 | R18: 20690 | S18: =AVERAGE(G18:R18) -> 20802.333 | T18: --- | U18: P9到貨
D19: 同期比 | G19: 0.90541153 | H19: 1.2221135 | I19: 1.0118144 | J19: 0.97397917 | K19: 0.74536532 | L19: 0.88514788 | M19: 0.92526182 | N19: 0.89581689 | O19: 0.88100271 | P19: 0.94419692 | Q19: 0.8134188 | R19: 0.82995708 | S19: =AVERAGE(G19:R19) -> 0.91945717
C20: PCS數 | E20: --- | F20: --- | G20: 165670 | H20: 125375 | I20: 135941 | J20: 153454 | K20: 123765 | L20: 131490 | M20: 149595 | N20: 153416 | O20: 122234 | P20: 134310 | Q20: 139087 | R20: 120887 | S20: =AVERAGE(G20:R20) -> 137935.33 | T20: ---
D21: 同期比 | G21: 0.79104813 | H21: 1.0401802 | I21: 0.86696513 | J21: 0.87537935 | K21: 0.90711532 | L21: 0.94874922 | M21: 0.79230443 | N21: 1.1260468 | O21: 0.76539283 | P21: 0.83271334 | Q21: 0.89770615 | R21: 0.82892427 | S21: =AVERAGE(G21:R21) -> 0.8893771
C22: 加班時數 | E22: --- | F22: --- | G22: =加班時數!B26 -> 840 | H22: =加班時數!C26 -> 493.5 | I22: =加班時數!D26 -> 424 | J22: =加班時數!E26 -> 720 | K22: =加班時數!F26 -> 419 | L22: =加班時數!G26 -> 641 | M22: =加班時數!H26 -> 713.7 | N22: =加班時數!I26 -> 1164.3 | ... R22: =加班時數!M26 -> 320.5 | S22: =AVERAGE(G22:R22) -> 623.16667 | U22: I:\3楊梅配銷室\06.共同事務\A.月報\106年\月報新版共二頁-2017年材敏加班統計, 加班合計
A23: 生產力 | B23: 進貨(i/hr) | E23: 36 | F23: =R23/E23 -> 1.1583333 | G23: 41.9 | H23: 43 | I23: 47.2 | J23: 47.6 | K23: 39.9 | L23: 48.7 | M23: 43.3 | N23: 46.1 | O23: 44.6 | P23: 49.1 | Q23: 47.3 | R23: 41.7 | S23: =AVERAGE(G23:R23) -> 45.033333 | T23: =S23/E23 -> 1.2509259
C24: 中小物(i/hr) | G24: 64.1 | H24: 67.6 | I24: 62.6 | J24: 62.6 | K24: 52.1 | L24: 63.6 | M24: 54.5 | N24: 61.3 | O24: 59.4 | P24: 66.8 | Q24: 64 | R24: 50.9
C25: 大物(i/hr) | G25: 19.3 | H25: 19.4 | I25: 26 | J25: 27.3 | K25: 21.9 | L25: 27.4 | M25: 25.6 | N25: 25.7 | O25: 24.4 | P25: 27.3 | Q25: 26 | R25: 27.6
B26: 出貨(i/hr) | E26: 63.6 | F26: =R26/E26 -> 1.0959119 | G26: 68.1 | H26: 64.6 | I26: 65.9 | J26: 63.6 | K26: 62.3 | L26: 65.9 | M26: 65.5 | N26: 63.7 | O26: 64.2 | P26: 72.1 | Q26: 65.8 | R26: 69.7 | S26: =AVERAGE(G26:R26) -> 65.95 | T26: =S26/E26 -> 1.0369497
C27: 中小物(i/hr) | G27: 82.4 | H27: 78.7 | I27: 75.2 | J27: 73.1 | K27: 78.7 | L27: 77.5 | M27: 81.5 | N27: 81.3 | O27: 81.7 | P27: 92.3 | Q27: 81.4 | R27: 85.5
C28: 大物(i/hr) | G28: 44.1 | H28: 41.2 | I28: 47.7 | J28: 45.3 | K28: 38.1 | L28: 45 | M28: 41.1 | N28: 38.4 | O28: 39.4 | P28: 44 | Q28: 43.4 | R28: 46
B29: 包裝(i/hr) | E29: 138 | F29: =R29/E29 -> 1.0103623 | G29: 141.27 | H29: 141.78 | I29: 140.94 | J29: 141.09 | K29: 140.03 | L29: 140.35 | M29: 139.5 | N29: 140.8 | O29: 140.36 | P29: 139.63 | Q29: 140.96 | R29: 139.43 | S29: =AVERAGE(G29:R29) -> 140.51167 | T29: =S29/E29 -> 1.0182005 | U29: P9
A30: 品質 | B30: 出貨品質 | C30: 誤品(ppm) | E30: 9 | F30: =E30/R30 -> 3.6 | G30: 5.9 | H30: 8.8 | I30: 10.6 | J30: 5.9 | K30: 17.4 | L30: 2.7 | M30: 0 | N30: 2.7 | O30: 2.8 | P30: 2.8 | Q30: 8.7 | R30: 2.5 | S30: =AVERAGE(G30:R31) -> 5.9 | T30: =E30/S30 -> 1.5254237
C31: 欠品(ppm) | F31: =E31/K31 -> #DIV/0! | U31: P3
C32: 損品(ppm) | E32: 8 | F32: =IF(R32=0,"-",E32/R32) -> - | G32: 0 | H32: 0 | I32: 0 | J32: 0 | K32: 0 | L32: 0 | M32: 0 | N32: 0 | O32: 0 | P32: 0 | Q32: 0 | R32: 0 | S32: =AVERAGE(G32:R32) -> 0 | T32: 1
C33: 包裝(ppm) | E33: 103 | F33: =IF(R33=0,"-",E33/R33) -> 0.91150442 | G33: 136 | H33: 132 | I33: 244 | J33: 264 | K33: 120 | L33: 103 | M33: 179 | N33: 193 | O33: 174 | P33: 171 | Q33: 139 | R33: 113 | S33: =AVERAGE(G33:R33) -> 164 | T33: =E33/S33 -> 0.62804878 | U33: P9
B34: 配送品質-準時率 | E34: 98 | F34: =R34/E34 -> 1 | G34: 98 | H34: 98 | I34: 98 | J34: 98 | K34: 98 | L34: 98 | M34: 98 | N34: 98 | O34: 98 | P34: 98 | Q34: 98 | R34: 98 | S34: =AVERAGE(G34:R34) -> 98 | T34: =S34/E34 -> 1 | U34: P8
A35: 包材回收 | B35: 重量 (公斤) | C35: 國內 | E35: --- | F35: --- | G35: ='包材回收(同期比)'!D91 -> 3049 | H35: ='包材回收(同期比)'!E91 -> 3344 | I35: ='包材回收(同期比)'!F91 -> 3925 | J35: ='包材回收(同期比)'!G91 -> 3494 | K35: ='包材回收(同期比)'!H91 -> 3212 | L35: ='包材回收(同期比)'!I91 -> 3261 | M35: ='包材回收(同期比)'!J91 -> 3267 | N35: ='包材回收(同期比)'!K91 -> 2520 | ... R35: ='包材回收(同期比)'!O91 -> 2603 | S35: =AVERAGE(G35:R35) -> 3014.6667 | T35: --- | U35: I:\3楊梅配銷室\06.共同事務-楊配室KPI匯整
C36: 國外 | E36: --- | F36: --- | G36: ='包材回收(同期比)'!D92 -> 14198 | H36: ='包材回收(同期比)'!E92 -> 22052 | I36: ='包材回收(同期比)'!F92 -> 23449 | J36: ='包材回收(同期比)'!G92 -> 27357.5 | K36: ='包材回收(同期比)'!H92 -> 18891 | L36: ='包材回收(同期比)'!I92 -> 29006 | M36: ='包材回收(同期比)'!J92 -> 23905 | N36: ='包材回收(同期比)'!K92 -> 12130 | ... R36: ='包材回收(同期比)'!O92 -> 19024 | S36: =AVERAGE(G36:R36) -> 20764.542 | T36: ---
C37: 合計 | E37: 28810.5 | F37: =R37/E37 -> 0.75066382 | G37: =G35+G36 -> 17247 | H37: =H35+H36 -> 25396 | I37: =I35+I36 -> 27374 | J37: =J35+J36 -> 30851.5 | K37: =K35+K36 -> 22103 | L37: =L35+L36 -> 32267 | M37: =M35+M36 -> 27172 | N37: =N35+N36 -> 14650 | ... R37: =R35+R36 -> 21627 | S37: =AVERAGE(G37:R37) -> 23779.208 | T37: ---
C38: 同期比 | E38: --- | F38: --- | G38: ='包材回收(同期比)'!D94 -> 0.4862556 | H38: ='包材回收(同期比)'!E94 -> 1.4146613 | I38: ='包材回收(同期比)'!F94 -> 0.82588626 | J38: ='包材回收(同期比)'!G94 -> 1.1633734 | K38: ='包材回收(同期比)'!H94 -> 0.78835111 | L38: ='包材回收(同期比)'!I94 -> 1.0247721 | M38: ='包材回收(同期比)'!J94 -> 0.93842169 | N38: ='包材回收(同期比)'!K94 -> 0.6292685 | ... R38: ='包材回收(同期比)'!O94 -> 0.80550486 | S38: =AVERAGE(G38:R38) -> 0.88029954
B39: 金額 (萬元) | C39: 國內 | E39: --- | F39: --- | G39: ='包材回收(同期比)'!D95 -> 13.7 | H39: ='包材回收(同期比)'!E95 -> 15.6 | I39: ='包材回收(同期比)'!F95 -> 18 | J39: ='包材回收(同期比)'!G95 -> 16.1 | K39: ='包材回收(同期比)'!H95 -> 14.9 | L39: ='包材回收(同期比)'!I95 -> 15.3 | M39: ='包材回收(同期比)'!J95 -> 15.2 | N39: ='包材回收(同期比)'!K95 -> 11.7 | ... R39: ='包材回收(同期比)'!O95 -> 11.9 | S39: =AVERAGE(G39:R39) -> 13.925 | T39: ---
C40: 國外 | E40: --- | F40: --- | G40: ='包材回收(同期比)'!D96 -> 47.5 | H40: ='包材回收(同期比)'!E96 -> 89.7 | I40: ='包材回收(同期比)'!F96 -> 96 | J40: ='包材回收(同期比)'!G96 -> 143.5 | K40: ='包材回收(同期比)'!H96 -> 84.3 | L40: ='包材回收(同期比)'!I96 -> 146.8 | M40: ='包材回收(同期比)'!J96 -> 123.1 | N40: ='包材回收(同期比)'!K96 -> 53.9 | ... R40: ='包材回收(同期比)'!O96 -> 79.3 | S40: =AVERAGE(G40:R40) -> 92.508333 | T40: ---
...

Sheet 出貨點數(其他附件)
A1: 2019年 /月份 | B1: 1 | C1: 2 | D1: 3 | E1: 4 | F1: 5 | G1: 6 | H1: 7 | I1: 8 | J1: 9 | K1: 10 | L1: 11 | M1: 12
A2: 零件 i | B2: 391042 | C2: 232855 | D2: 313479 | E2: 296353 | F2: 317723 | G2: 299282 | H2: 340859 | I2: 321679 | J2: 293513 | K2: 328038 | L2: 319587 | M2: 355032
A3: 和勁 i | B3: 19165 | C3: 5370 | D3: 7040 | E3: 8088 | F3: 14307 | G3: 15998 | H3: 17087 | I3: 9871 | J3: 7884 | K3: 10591 | L3: 14011 | M3: 19338
A4: 產機 i | B4: 1541 | C4: 915 | D4: 1173 | E4: 1192 | F4: 1374 | G4: 1259 | H4: 1698 | I4: 1184 | J4: 1284 | K4: 1463 | L4: 1337 | M4: 1413
A5: 車美仕 i | B5: 9219 | C5: 5688 | D5: 6409 | E5: 7215 | F5: 6512 | G5: 7125 | H5: 6171 | I5: 3806 | J5: 4954 | K5: 6786 | L5: 6618 | M5: 7404
A6: 和運 i | B6: 767 | C6: 338 | D6: 601 | E6: 480 | F6: 523 | G6: 573 | H6: 690 | I6: 627 | J6: 544 | K6: 652 | L6: 735 | M6: 807
A7: 和運經銷商i | B7: 1979 | C7: 1127 | D7: 1706 | E7: 1466 | F7: 2276 | G7: 1829 | H7: 2225 | I7: 2422 | J7: 2030 | K7: 2523 | L7: 2213 | M7: 2459
A8: 湯淺 i | B8: 1781 | C8: 1320 | D8: 1206 | E8: 908 | F8: 1448 | G8: 1596 | H8: 1620 | I8: 1678 | J8: 2144 | K8: 1778 | L8: 2075 | M8: 1814
A9: 總合計i | B9: =SUM(B2:B8) -> 425494 | C9: =SUM(C2:C8) -> 247613 | D9: =SUM(D2:D8) -> 331614 | E9: =SUM(E2:E8) -> 315702 | F9: =SUM(F2:F8) -> 344163 | G9: =SUM(G2:G8) -> 327662 | H9: =SUM(H2:H8) -> 370350 | I9: =SUM(I2:I8) -> 341267 | ... M9: =SUM(M2:M8) -> 388267
A10: 零件pcs | B10: 2536614 | C10: 1445282 | D10: 1916054 | E10: 1898917 | F10: 2060248 | G10: 2025118 | H10: 2211194 | I10: 1962282 | J10: 1879324 | K10: 2087204 | L10: 2061187 | M10: 2312999
A11: 和勁pcs | B11: 146177 | C11: 72647 | D11: 120051 | E11: 107960 | F11: 128648 | G11: 152500 | H11: 146036 | I11: 80867 | J11: 110822 | K11: 85412 | L11: 140248 | M11: 132573
A12: 產機pcs
A13: 車美仕pcs | B13: 81135 | C13: 41945 | D13: 49580 | E13: 76305 | F13: 65954 | G13: 69793 | H13: 60954 | I13: 26574 | J13: 44215 | K13: 60060 | L13: 58843 | M13: 69373
A14: 和運pcs | B14: 8245 | C14: 4212 | D14: 9513 | E14: 5102 | F14: 7249 | G14: 6286 | H14: 7354 | I14: 7154 | J14: 5628 | K14: 7622 | L14: 7142 | M14: 7585
A15: 和運經銷商pcs | B15: 3216 | C15: 1899 | D15: 2655 | E15: 2092 | F15: 3983 | G15: 2776 | H15: 3989 | I15: 4303 | J15: 3435 | K15: 4350 | L15: 4033 | M15: 3827
A16: 湯淺pcs | B16: 10184 | C16: 7466 | D16: 6254 | E16: 4384 | F16: 6817 | G16: 7750 | H16: 7957 | I16: 8164 | J16: 10878 | K16: 9293 | L16: 11210 | M16: 9658
A17: 總合計pcs | B17: =SUM(B10:B16) -> 2785571 | C17: =SUM(C10:C16) -> 1573451 | D17: =SUM(D10:D16) -> 2104107 | E17: =SUM(E10:E16) -> 2094760 | F17: =SUM(F10:F16) -> 2272899 | G17: =SUM(G10:G16) -> 2264223 | H17: =SUM(H10:H16) -> 2437484 | I17: =SUM(I10:I16) -> 2089344 | ... M17: =SUM(M10:M16) -> 2536015
A19: 出貨點數
A20: 2020年 /月份 | B20: 1 | C20: 2 | D20: 3 | E20: 4 | F20: 5 | G20: 6 | H20: 7 | I20: 8 | J20: 9 | K20: 10 | L20: 11 | M20: 12 | N20: 平均 | O20: 合計
A21: 零件 i | B21: 295444 | C21: 319960 | D21: 334332 | E21: 290437 | F21: 301493 | G21: 309849 | H21: 362845 | I21: 343104 | J21: 350048 | K21: 322082 | L21: 333743 | M21: 372497 | N21: =AVERAGE(B21:M21) -> 327986.17 | O21: =SUM(B21:M21) -> 3935834
A22: 同期比 | B22: =B21/B2 -> 0.7555301 | C22: =C21/C2 -> 1.374074 | D22: =D21/D2 -> 1.0665212 | E22: =E21/E2 -> 0.98003732 | F22: =F21/F2 -> 0.94891777 | G22: =G21/G2 -> 1.0353078 | H22: =H21/H2 -> 1.0645017 | I22: =I21/I2 -> 1.0666037 | ... M22: =M21/M2 -> 1.0491927 | N22: =AVERAGE(B22:M22) -> 1.04662
A23: 和勁 i | B23: 7114 | C23: 7702 | D23: 9509 | E23: 7516 | F23: 10898 | G23: 16398 | H23: 18684 | I23: 11874 | J23: 10590 | K23: 8570 | L23: 15821 | M23: 18403 | N23: =AVERAGE(B23:M23) -> 11923.25 | O23: =SUM(B23:M23) -> 143079
A24: 同期比 | B24: =B23/B3 -> 0.3711975 | C24: =C23/C3 -> 1.4342644 | D24: =D23/D3 -> 1.3507102 | E24: =E23/E3 -> 0.92927794 | F24: =F23/F3 -> 0.76172503 | G24: =G23/G3 -> 1.0250031 | H24: =H23/H3 -> 1.0934629 | I24: =I23/I3 -> 1.2029176 | ... M24: =M23/M3 -> 0.9516496 | N24: =AVERAGE(B24:M24) -> 1.0334831
A25: 產機 i | B25: 1199 | C25: 1451 | D25: 1386 | E25: 1256 | F25: 1192 | G25: 1331 | H25: 1317 | I25: 1303 | J25: 1610 | K25: 1142 | L25: 1656 | M25: 1347 | N25: =AVERAGE(B25:M25) -> 1349.1667 | O25: =SUM(B25:M25) -> 16190
A26: 同期比 | B26: =B25/B4 -> 0.77806619 | C26: =C25/C4 -> 1.5857923 | D26: =D25/D4 -> 1.1815857 | E26: =E25/E4 -> 1.0536913 | F26: =F25/F4 -> 0.86754003 | G26: =G25/G4 -> 1.0571882 | H26: =H25/H4 -> 0.77561837 | I26: =I25/I4 -> 1.1005068 | ... M26: =M25/M4 -> 0.95329087 | N26: =AVERAGE(B26:M26) -> 1.0521963
A27: 車美仕 i | B27: 6171 | C27: 4671 | D27: 9604 | E27: 8302 | F27: 8656 | G27: 9635 | H27: 11710 | I27: 9005 | J27: 8641 | K27: 9010 | L27: 9324 | M27: 11470 | N27: =AVERAGE(B27:M27) -> 8849.9167 | O27: =SUM(B27:M27) -> 106199
A28: 同期比 | B28: =B27/B5 -> 0.66937846 | C28: =C27/C5 -> 0.82120253 | D28: =D27/D5 -> 1.4985177 | E28: =E27/E5 -> 1.1506584 | F28: =F27/F5 -> 1.3292383 | G28: =G27/G5 -> 1.3522807 | H28: =H27/H5 -> 1.8975855 | I28: =I27/I5 -> 2.3660011 | ... M28: =M27/M5 -> 1.5491626 | N28: =AVERAGE(B28:M28) -> 1.4262409
A29: 和運 i | B29: 670 | C29: 796 | D29: 831 | E29: 734 | F29: 877 | G29: 931 | H29: 817 | I29: 877 | J29: 975 | K29: 765 | L29: 994 | M29: 963 | N29: =AVERAGE(B29:M29) -> 852.5 | O29: =SUM(B29:M29) -> 10230
A30: 同期比 | B30: =B29/B6 -> 0.87353325 | C30: =C29/C6 -> 2.3550296 | D30: =D29/D6 -> 1.3826955 | E30: =E29/E6 -> 1.5291667 | F30: =F29/F6 -> 1.6768642 | G30: =G29/G6 -> 1.6247818 | H30: =H29/H6 -> 1.184058 | I30: =I29/I6 -> 1.3987241 | ... M30: =M29/M6 -> 1.1933086 | N30: =AVERAGE(B30:M30) -> 1.4613446
A31: 和運經銷商i | B31: 2238 | C31: 2831 | D31: 3697 | E31: 3273 | F31: 3579 | G31: 4099 | H31: 5499 | I31: 5051 | J31: 4846 | K31: 4478 | L31: 4797 | M31: 4674 | N31: =AVERAGE(B31:M31) -> 4088.5 | O31: =SUM(B31:M31) -> 49062
A32: 同期比 | B32: =B31/B8 -> 1.2565974 | C32: =C31/C8 -> 2.144697 | D32: =D31/D8 -> 3.0655058 | E32: =E31/E8 -> 3.6046256 | F32: =F31/F8 -> 2.4716851 | G32: =G31/G8 -> 2.5682957 | H32: =H31/H8 -> 3.3944444 | I32: =I31/I8 -> 3.0101311 | ... M32: =M31/M8 -> 2.5766262 | N32: =AVERAGE(B32:M32) -> 2.5986031
A33: 湯淺 i | B33: 1835 | C33: 1257 | D33: 1564 | E33: 1268 | F33: 1490 | G33: 1635 | H33: 1795 | I33: 2126 | J33: 1810 | K33: 1753 | L33: 2185 | M33: 2034 | N33: =AVERAGE(B33:M33) -> 1729.3333 | O33: =SUM(B33:M33) -> 20752
A34: 同期比 | B34: =B33/B8 -> 1.03032 | C34: =C33/C8 -> 0.95227273 | D34: =D33/D8 -> 1.2968491 | E34: =E33/E8 -> 1.3964758 | F34: =F33/F8 -> 1.0290055 | G34: =G33/G8 -> 1.0244361 | H34: =H33/H8 -> 1.1080247 | I34: =I33/I8 -> 1.2669845 | ... M34: =M33/M8 -> 1.1212789 | N34: =AVERAGE(B34:M34) -> 1.0924013
A35: 總合計i | B35: =B21+B23+B25+B27+B29+B33+B31 -> 314671 | C35: =C21+C23+C25+C27+C29+C33 -> 335837 | D35: =D21+D23+D25+D27+D29+D33 -> 357226 | E35: =E21+E23+E25+E27+E29+E33 -> 309513 | F35: =F21+F23+F25+F27+F29+F33 -> 324606 | G35: =G21+G23+G25+G27+G29+G33 -> 339779 | H35: =H21+H23+H25+H27+H29+H33 -> 397168 | I35: =I21+I23+I25+I27+I29+I33 -> 368289 | J35: =J21+J23+J25+J27+J29+J33 -> 373674 | ... M35: =M21+M23+M25+M27+M29+M33 -> 406714 | N35: =AVERAGEA(B35:M35) -> 352876.83 | O35: =SUM(B35:M35) -> 4234522
A36: 同期比 | B36: =B35/B9 -> 0.73954274 | C36: =C35/C9 -> 1.3562979 | D36: =D35/D9 -> 1.0772344 | E36: =E35/E9 -> 0.98039607 | F36: =F35/F9 -> 0.94317518 | G36: =G35/G9 -> 1.0369802 | H36: =H35/H9 -> 1.0724126 | I36: =I35/I9 -> 1.0791814 | ... M36: =M35/M9 -> 1.0475111 | N36: =AVERAGE(B36:M36) -> 1.0461951
A37: 出貨PCS
A38: 零件pcs | B38: 2064225 | C38: 1919724 | D38: 2387421 | E38: 1925057 | F38: 1938618 | G38: 1975146 | H38: 2125321 | I38: 2075304 | J38: 2188146 | K38: 2006021 | L38: 2079620 | M38: 2473506 | N38: =AVERAGE(B38:M38) -> 2096509.1 | O38: =SUM(B38:M38) -> 25158109
A39: 同期比 | B39: =B38/B10 -> 0.81377182 | C39: =C38/C10 -> 1.3282695 | D39: =D38/D10 -> 1.2460092 | E39: =E38/E10 -> 1.0137657 | F39: =F38/F10 -> 0.94096342 | G39: =G38/G10 -> 0.97532391 | H39: =H38/H10 -> 0.96116442 | I39: =I38/I10 -> 1.0575972 | ... M39: =M38/M10 -> 1.0693935 | N39: =AVERAGE(B39:M39) -> 1.0450527
A40: 和勁pcs | B40: 51983 | C40: 51792 | D40: 82775 | E40: 87977 | F40: 99436 | G40: 140113 | H40: 150989 | I40: 94844 | J40: 462884 | K40: 115534 | L40: 139413 | M40: 165648 | N40: =AVERAGE(B40:M40) -> 136949 | O40: =SUM(B40:M40) -> 1643388
A41: 同期比 | B41: =B40/B11 -> 0.35561682 | C41: =C40/C11 -> 0.71292689 | D41: =D40/D11 -> 0.68949863 | E41: =E40/E11 -> 0.81490367 | F41: =F40/F11 -> 0.77293079 | G41: =G40/G11 -> 0.91877377 | H41: =H40/H11 -> 1.0339163 | I41: =I40/I11 -> 1.1728394 | ... M41: =M40/M11 -> 1.2494852 | N41: =AVERAGE(B41:M41) -> 1.1870357
...

Sheet 進貨點數(同期比)
A1: 2014年/月份 | B1: 1 | C1: 2 | D1: 3 | E1: 4 | F1: 5 | G1: 6 | H1: 7 | I1: 8 | J1: 9 | K1: 10 | L1: 11 | M1: 12
A2: I | B2: =37193+18064 -> 55257 | C2: =39053+16010 -> 55063 | D2: =41877+17252 -> 59129 | E2: =49005+18465 -> 67470 | F2: =35381+19931 -> 55312 | G2: =43034+19334 -> 62368 | H2: =43142+21923 -> 65065 | I2: =40516+15967 -> 56483 | J2: =44979+17834 -> 62813 | K2: =47684+20511 -> 68195 | L2: =39861+20761 -> 60622 | M2: =31739+21067 -> 52806
A3: PCS | B3: =496198+198457 -> 694655 | C3: =464784+148811 -> 613595 | D3: =492728+140695 -> 633423 | E3: =600634+157025 -> 757659 | F3: =457343+162854 -> 620197 | G3: =476239+169969 -> 646208 | H3: =517338+207767 -> 725105 | I3: =508280+142743 -> 651023 | J3: =439066+152125 -> 591191 | K3: =544603+182309 -> 726912 | L3: =443648+182039 -> 625687 | M3: =400285+17790 -> 418075
A4: 2015年/月份 | B4: 1 | C4: 2 | D4: 3 | E4: 4 | F4: 5 | G4: 6 | H4: 7 | I4: 8 | J4: 9 | K4: 10 | L4: 11 | M4: 12
A5: I | B5: =52126+22640 -> 74766 | C5: =39381+14207 -> 53588 | D5: =50344+22291 -> 72635 | E5: =45585+16098 -> 61683 | F5: 63019 | G5: 65339 | H5: 66729 | I5: 63204 | J5: 71271 | K5: 73736 | L5: 77700 | M5: 85071
A6: PCS | B6: =713524+302113 -> 1015637 | C6: =488291+138526 -> 626817 | D6: =521735+201209 -> 722944 | E6: =525340+144803 -> 670143 | F6: 700918 | G6: 707373 | H6: 737207 | I6: 814051 | J6: 918387 | K6: 775117 | L6: 1011035 | M6: 1201112
A7: 2016年/月份 | B7: 1 | C7: 2 | D7: 3 | E7: 4 | F7: 5 | G7: 6 | H7: 7 | I7: 8 | J7: 9 | K7: 10 | L7: 11 | M7: 12
A8: I | B8: 76036 | C8: 68333 | D8: 77543 | E8: 76742 | F8: 73888 | G8: 86617 | H8: 78313 | I8: 71403 | J8: 74708 | K8: 75109 | L8: 85130 | M8: 71365
A9: PCS | B9: 1328744 | C9: 939329 | D9: 981633 | E9: 1697335 | F9: 1022205 | G9: 1222222 | H9: 1051536 | I9: 889176 | J9: 929383 | K9: 1010261 | L9: 1208417 | M9: 1085894
A10: 同期比I | B10: =B8/B5 -> 1.0169863 | C10: =C8/C5 -> 1.2751549 | D10: =D8/D5 -> 1.0675707 | E10: =E8/E5 -> 1.2441353 | F10: =F8/F5 -> 1.1724718 | G10: =G8/G5 -> 1.3256554 | H10: =H8/H5 -> 1.1735977 | I10: =I8/I5 -> 1.1297228 | ... M10: =M8/M5 -> 0.83888752
A11: 同期比PCS | B11: =B9/B6 -> 1.3082863 | C11: =C9/C6 -> 1.4985698 | D11: =D9/D6 -> 1.3578272 | E11: =E9/E6 -> 2.5327952 | F11: =F9/F6 -> 1.4583803 | G11: =G9/G6 -> 1.7278324 | H11: =H9/H6 -> 1.4263782 | I11: =I9/I6 -> 1.0922854 | ... M11: =M9/M6 -> 0.90407389
A12: 2017年/月份 | B12: 1 | C12: 2 | D12: 3 | E12: 4 | F12: 5 | G12: 6 | H12: 7 | I12: 8 | J12: 9 | K12: 10 | L12: 11 | M12: 12
A13: I | B13: 89260 | C13: 61216 | D13: 92239 | E13: 70746 | F13: 72166 | G13: 79384 | H13: 88473 | I13: 93010 | J13: 87130 | K13: 77013 | L13: 88355 | M13: 76531
A14: PCS | B14: 1700935 | C14: 721085 | D14: 1202153 | E14: 1060419 | F14: 1063603 | G14: 1049824 | H14: 1103519 | I14: 1293402 | J14: 1172627 | K14: 1258484 | L14: 1216748 | M14: 1305038
A15: 同期比I | B15: =B13/B8 -> 1.1739176 | C15: =C13/C8 -> 0.89584827 | D15: =D13/D8 -> 1.1895207 | E15: =E13/E8 -> 0.92186808 | F15: =F13/F8 -> 0.97669446 | G15: =G13/G8 -> 0.91649445 | H15: =H13/H8 -> 1.1297358 | I15: =I13/I8 -> 1.3026063 | ... M15: =M13/M8 -> 1.0723884
A16: 同期比PCS | B16: =B14/B9 -> 1.2801074 | C16: =C14/C9 -> 0.76765968 | D16: =D14/D9 -> 1.2246461 | E16: =E14/E9 -> 0.62475528 | F16: =F14/F9 -> 1.0404987 | G16: =G14/G9 -> 0.85894707 | H16: =H14/H9 -> 1.0494353 | I16: =I14/I9 -> 1.4546074 | ... M16: =M14/M9 -> 1.2018098
A17: 2018年/月份 | B17: 1 | C17: 2 | D17: 3 | E17: 4 | F17: 5 | G17: 6 | H17: 7 | I17: 8 | J17: 9 | K17: 10 | L17: 11 | M17: 12
A18: I | B18: 94094 | C18: 71263 | D18: 91234 | E18: 74564 | F18: 88863 | G18: 71852 | H18: 85218 | I18: 75614 | J18: 87968 | K18: 83882 | L18: 92459 | M18: 76749
A19: PCS | B19: 1624123 | C19: 1136798 | D19: 1242691 | E19: 1182218 | F19: 1238105 | G19: 1211910 | H19: 1334803 | I19: 1171190 | J19: 1227569 | K19: 1249781 | L19: 1423839 | M19: 1267604
A20: 同期比I | B20: =B18/B13 -> 1.0541564 | C20: =C18/C13 -> 1.1641238 | D20: =D18/D13 -> 0.98910439 | E20: =E18/E13 -> 1.0539677 | F20: =F18/F13 -> 1.2313693 | G20: =G18/G13 -> 0.90511942 | H20: =H18/H13 -> 0.96320911 | I20: =I18/I13 -> 0.81296635 | ... M20: =M18/M13 -> 1.0028485
A21: 同期比PCS | B21: =B19/B14 -> 0.95484131 | C21: =C19/C14 -> 1.5765104 | D21: =D19/D14 -> 1.0337212 | E21: =E19/E14 -> 1.1148593 | F21: =F19/F14 -> 1.1640669 | G21: =G19/G14 -> 1.1543935 | H21: =H19/H14 -> 1.2095877 | I21: =I19/I14 -> 0.9055112 | ... M21: =M19/M14 -> 0.97131578
A22: 2019年/月份 | B22: 1 | C22: 2 | D22: 3 | E22: 4 | F22: 5 | G22: 6 | H22: 7 | I22: 8 | J22: 9 | K22: 10 | L22: 11 | M22: 12
A23: I | B23: 94541 | C23: 64264 | D23: 72895 | E23: 76434 | F23: 78417 | G23: 76076 | H23: 91269 | I23: 83130 | J23: 68376 | K23: 100460 | L23: 91667 | M23: 101821
A24: PCS | B24: 1514697 | C24: 987327 | D24: 1129534 | E24: 1241515 | F24: 1218380 | G24: 1234140 | H24: 1438773 | I24: 1197334 | J24: 1000002 | K24: 1434620 | L24: 1314964 | M24: 1534817
A25: 同期比I | B25: =B18/B23 -> 0.99527189 | C25: =C18/C23 -> 1.1089101 | D25: =D18/D23 -> 1.251581 | E25: =E18/E23 -> 0.97553445 | F25: =F18/F23 -> 1.1332109 | G25: =G18/G23 -> 0.94447658 | H25: =H18/H23 -> 0.93370148 | I25: =I18/I23 -> 0.90958739 | J25: =J23/J18 -> 0.77728265 | K25: =K23/K18 -> 1.1976348 | L25: =L23/L18 -> 0.99143404 | M25: =M23/M18 -> 1.3266753
A26: 同期比PCS | B26: =B19/B24 -> 1.0722428 | C26: =C19/C24 -> 1.1513896 | D26: =D19/D24 -> 1.1001803 | E26: =E19/E24 -> 0.95223819 | F26: =F19/F24 -> 1.0161895 | G26: =G19/G24 -> 0.98198746 | H26: =H19/H24 -> 0.92773704 | I26: =I19/I24 -> 0.97816482 | J26: =J24/J19 -> 0.81461979 | K26: =K24/K19 -> 1.1478971 | L26: =L24/L19 -> 0.92353419 | M26: =M24/M19 -> 1.2108016
A27: 2020年/月份 | B27: 1 | C27: 2 | D27: 3 | E27: 4 | F27: 5 | G27: 6 | H27: 7 | I27: 8 | J27: 9 | K27: 10 | L27: 11 | M27: 12
A28: I | B28: 80912 | C28: 78908 | D28: 84677 | E28: 72364 | F28: 88404 | G28: 79028 | H28: 100239 | I28: 99641 | J28: 86113 | K28: 91062 | L28: 91609 | M28: 122534
A29: PCS | B29: 1284289 | C29: 1215417 | D29: 1473277 | E29: 1281620 | F29: 1564926 | G29: 1256306 | H29: 1295767 | I29: 1277472 | J29: 1300368 | K29: 1221525 | L29: 1488301 | M29: 1590219
A30: 同期比I | B30: =B23/B28 -> 1.1684423 | C30: =C23/C28 -> 0.81441679 | D30: =D23/D28 -> 0.8608595 | E30: =E23/E28 -> 1.0562434 | F30: =F23/F28 -> 0.88703 | G30: =G23/G28 -> 0.96264615 | H30: =H23/H28 -> 0.91051387 | I30: =I23/I28 -> 0.83429512 | J30: =J28/J23 -> 1.2594039 | K30: =K28/K23 -> 0.90645033 | L30: =L28/L23 -> 0.99936728 | M30: =M28/M23 -> 1.2034256
A31: 同期比PCS | B31: =B24/B29 -> 1.1794051 | C31: =C24/C29 -> 0.81233601 | D31: =D24/D29 -> 0.76668135 | E31: =E24/E29 -> 0.96870757 | F31: =F24/F29 -> 0.77855439 | G31: =G24/G29 -> 0.98235621 | H31: =H24/H29 -> 1.110364 | I31: =I24/I29 -> 0.93726829 | J31: =J29/J24 -> 1.3003654 | K31: =K29/K24 -> 0.85146241 | L31: =L29/L24 -> 1.1318188 | M31: =M29/M24 -> 1.0360968
A32: 2021年/月份 | B32: 1 | C32: 2 | D32: 3 | E32: 4 | F32: 5 | G32: 6 | H32: 7 | I32: 8 | J32: 9 | K32: 10 | L32: 11 | M32: 12
A33: I | B33: 109087 | C33: 63617 | D33: 90797 | E33: 71472 | F33: 84403 | G33: 82486 | H33: 77347 | I33: 65823 | J33: 76526 | K33: 83320 | L33: 91781 | M33: 101214
A34: PCS | B34: 1590835 | C34: 1178970 | D34: 1516056 | E34: 1147688 | F34: 1412349 | G34: 1461802 | H34: 1284185 | I34: 1218066 | J34: 1352983 | K34: 1236302 | L34: 1447962 | M34: 1553156
A35: 同期比I | B35: =B33/B28 -> 1.3482178 | C35: =C28/C33 -> 1.2403603 | D35: =D28/D33 -> 0.93259689 | E35: =E28/E33 -> 1.0124804 | F35: =F28/F33 -> 1.0474035 | G35: =G28/G33 -> 0.95807773 | H35: =H28/H33 -> 1.2959649 | I35: =I28/I33 -> 1.5137718 | J35: =J33/J28 -> 0.88866954 | K35: =K33/K28 -> 0.914981 | L35: =L33/L28 -> 1.0018775 | M35: =M33/M28 -> 0.82600748
A36: 同期比PCS | B36: =B34/B29 -> 1.2386893 | C36: =C29/C34 -> 1.0309143 | D36: =D29/D34 -> 0.9717827 | E36: =E29/E34 -> 1.1166972 | F36: =F29/F34 -> 1.1080307 | G36: =G29/G34 -> 0.85942282 | H36: =H29/H34 -> 1.0090189 | I36: =I29/I34 -> 1.0487708 | J36: =J34/J29 -> 1.0404616 | K36: =K34/K29 -> 1.0120972 | L36: =L34/L29 -> 0.97289594 | M36: =M34/M29 -> 0.97669315
A37: 2022年/月份 | B37: 1 | C37: 2 | D37: 3 | E37: 4 | F37: 5 | G37: 6 | H37: 7 | I37: 8 | J37: 9 | K37: 10 | L37: 11 | M37: 12
A38: I | B38: 103232 | C38: 63927 | D38: 112851 | E38: 83070 | F38: 88988 | G38: 91796 | H38: 88671 | I38: 95742 | J38: 97444 | K38: 96411 | L38: 101583 | M38: 110262
A39: PCS | B39: 1491074 | C39: 922904 | D39: 1789012 | E39: 1277563 | F39: 1340509 | G39: 1294899 | H39: 1332450 | I39: 1486450 | J39: 1444923 | K39: 1390571 | L39: 1445203 | M39: 2001133
A40: 同期比I | B40: =B38/B33 -> 0.94632724 | C40: =C33/C38 -> 0.99515072 | D40: =D33/D38 -> 0.80457417 | E40: =E33/E38 -> 0.86038281 | F40: =F33/F38 -> 0.9484762 | G40: =G33/G38 -> 0.89857946 | H40: =H33/H38 -> 0.87229196 | I40: =I33/I38 -> 0.68750392 | J40: =J38/J33 -> 1.273345 | K40: =K38/K33 -> 1.1571171 | L40: =L38/L33 -> 1.1067977 | M40: =M38/M33 -> 1.0893947
...

Sheet 庫位使用率
A2: 2015年10月 ~ 2015年12月 楊 梅 倉 庫 各 零 件 保 管 庫 區 使 用 狀 況
AF3: 2016/01/06 | AH3: 製表.
A4: 管 理 別 | C4: 中 小 物 庫 區 ( 材 敏 ) | P4: 大 物 庫 區 ( 和 泰 ) | Z4: 小 計 | AA4: 庫 區 保 管 狀 況 | AE4: 新 卡 | AF4: 空庫位 取 消 | AG4: 不適當 遷 移 | AH4: 合 計
A5: 區 域 別 | C5: 積 層 庫 區 | L5: 專 區 | P5: 小 計 | Q5: 高 層 架 庫 區 | W5: 專 區 | AB5: 小 計 | AC5: 合 計 | AD5: ▲ | AE5: ◎ | AF5: ▽ | AG5: 小 計 | AH5: 新 卡 | AI5: 空庫位 取消 | AJ5: 不適當 遷移
A6: 庫 區 | C6: A | D6: B | E6: C | F6: D | G6: E | H6: P | I6: T | J6: U | K6: 4 | L6: R | M6: S | N6: J | O6: W | Q6: F | R6: N | S6: G | T6: H | U6: M、Q | V6: L | W6: K | X6: V | Y6: Y | Z6: Z | AD6: 過高 >85% | AE6: 正常 75~85% | AF6: 過低 <75% | AK6: 合 計
A7: 保管類別 | C7: 高 銷 中 物 | D7: 高 銷 中小物 | E7: 低 銷 中量物 | F7: 低 銷 中小物 | G7: 暢 銷 量物區 | H7: 低、滯 銷區 | I7: 中 銷 量物區 | L7: 精品區 | M7: 高價 品區 | N7: 精品區 | Q7: 高中銷 大 物 | R7: 中低銷 大 物 | S7: 高中銷 大中物 | T7: 金屬區 | U7: 低、滯 銷區 | V7: 玻璃 庫區 | W7: 電、化 品區 | X7: 保桿區 | Y7: 輪胎區 | Z7: 油品區
B8: 使用率 | C8: =#REF!/#REF! -> #REF! | G8: =#REF!/#REF! -> #REF! | L8: =#REF!/#REF! -> #REF! | O8: =(#REF!+#REF!)/#REF! -> #REF! | P8: =(#REF!+#REF!)/#REF! -> #REF! | Q8: =#REF!/#REF! -> #REF! | T8: =(#REF!+#REF!)/#REF! -> #REF! | U8: =(#REF!+#REF!)/#REF! -> #REF! | V8: =(#REF!+#REF!)/#REF! -> #REF! | W8: =(#REF!+#REF!)/#REF! -> #REF! | X8: =(#REF!+#REF!)/#REF! -> #REF! | Y8: =(#REF!+#REF!)/#REF! -> #REF! | Z8: =(#REF!+#REF!)/#REF! -> #REF! | AB8: =(#REF!+#REF!)/#REF! -> #REF! | AC8: =(#REF!+#REF!)/#REF! -> #REF! | AD8: =#REF!/#REF! -> #REF! | AE8: =#REF!/#REF! -> #REF! | AF8: =#REF!/#REF! -> #REF! | AG8: =#REF!/#REF! -> #REF!
A9: 2022年 1月 | B9: 點數 (i) | C9: 7959 | D9: 32656 | E9: 3743 | F9: 17230 | G9: 1522 | H9: 4390 | I9: 2153 | L9: 30 | M9: 811 | N9: 681 | O9: 129 | P9: =SUM(C9:O9) -> 71304 | Q9: 1068 | R9: 2412 | S9: 1870 | T9: 2547 | U9: 2172 | V9: 730 | W9: 271 | X9: 696 | Y9: 194 | Z9: 128 | AB9: =SUM(Q9:AA9) -> 12088 | AC9: =P9+AB9 -> 83392 | AD9: 13 | AE9: 4 | AF9: 4 | AG9: =SUM(AD9:AF9) -> 21 | AH9: 2131 | AI9: 2261 | AJ9: 670 | AK9: =SUM(AH9:AJ14) -> 5062
B10: 延伸庫位 | C10: 35.8155 | D10: 146.952 | E10: 16.8435 | F10: 77.535 | G10: 0 | H10: 0 | I10: 0 | L10: 0 | M10: 4.055 | N10: 3.405 | O10: 0 | P10: =SUM(C10:O10) -> 284.606 | Q10: 10.68 | R10: 0 | S10: 0 | T10: 25.47 | U10: 0 | V10: 0 | W10: 0 | X10: 97.44 | Y10: 0 | Z10: 25.6 | AB10: =SUM(Q10:AA10) -> 159.19 | AC10: =P10+AB10 -> 443.796
B11: 配置數 | C11: 9252 | D11: 37456 | E11: 4675 | F11: 21619 | G11: 1602 | H11: 6242 | I11: 2442 | L11: 102 | M11: 876 | N11: 1147 | O11: 129 | P11: =SUM(C11:O11) -> 85542 | Q11: 1242 | R11: 2718 | S11: 2020 | T11: 3147 | U11: 4086 | V11: 851 | W11: 292 | X11: 852 | Y11: 204 | Z11: 164 | AB11: =SUM(Q11:AA11) -> 15576 | AC11: =P11+AB11 -> 101118
B12: 合計點數 | C12: =C9+D9+E9+F9+C10+D10+E10+F10 -> 61865.146 | G12: =G9+H9+I9+G10+H10+I10 -> 8065 | L12: =L9+M9+N9+L10+M10+N10 -> 1529.46 | Q12: =Q9+R9+S9+Q10+R10+S10 -> 5360.68
B13: 合計配置數 | C13: =C11+D11+E11+F11 -> 73002 | G13: =G11+H11+I11 -> 10286 | L13: =L11+M11+N11 -> 2125 | Q13: =Q11+R11+S11 -> 5980
B14: 使用率 | C14: =C12/C13 -> 0.84744454 | G14: =G12/G13 -> 0.78407544 | L14: =L12/L13 -> 0.71974588 | O14: =(O9+O10)/O11 -> 1 | P14: =(P9+P10)/P11 -> 0.83688254 | Q14: =Q12/Q13 -> 0.89643478 | T14: =(T9+T10)/T11 -> 0.81743565 | U14: =(U9+U10)/U11 -> 0.53157122 | V14: =(V9+V10)/V11 -> 0.85781434 | W14: =(W9+W10)/W11 -> 0.92808219 | X14: =(X9+X10)/X11 -> 0.93126761 | Y14: =(Y9+Y10)/Y11 -> 0.95098039 | Z14: =(Z9+Z10)/Z11 -> 0.93658537 | AB14: =(AB9+AB10)/AB11 -> 0.78628595 | AC14: =(AC9+AC10)/AC11 -> 0.82908875 | AD14: =AD9/$AG$102 -> #DIV/0! | AE14: =AE9/$AG$102 -> #DIV/0! | AF14: =AF9/$AG$102 -> #DIV/0! | AG14: =AG9/$AG$102 -> #DIV/0!
A15: 2022年 2月 | B15: 點數 (i) | C15: 7987 | D15: 32720 | E15: 3733 | F15: 17389 | G15: 1518 | H15: 4385 | I15: 2166 | L15: 31 | M15: 808 | N15: 682 | O15: 129 | P15: =SUM(C15:O15) -> 71548 | Q15: 1077 | R15: 2400 | S15: 1884 | T15: 2553 | U15: 2145 | V15: 729 | W15: 273 | X15: 706 | Y15: 196 | Z15: 129 | AB15: =SUM(Q15:AA15) -> 12092 | AC15: =P15+AB15 -> 83640 | AD15: 13 | AE15: 4 | AF15: 4 | AG15: =SUM(AD15:AF15) -> 21 | AH15: 1649 | AI15: 1805 | AJ15: 479 | AK15: =SUM(AH15:AJ20) -> 3933
B16: 延伸庫位 | C16: 35.9415 | D16: 147.24 | E16: 16.7985 | F16: 78.2505 | G16: 0 | H16: 0 | I16: 0 | L16: 0 | M16: 4.04 | N16: 3.41 | O16: 0 | P16: =SUM(C16:O16) -> 285.6805 | Q16: 10.77 | R16: 0 | S16: 0 | T16: 25.53 | U16: 0 | V16: 0 | W16: 0 | X16: 98.84 | Y16: 0 | Z16: 25.8 | AB16: =SUM(Q16:AA16) -> 160.94 | AC16: =P16+AB16 -> 446.6205
B17: 配置數 | C17: 9252 | D17: 37456 | E17: 4675 | F17: 21619 | G17: 1602 | H17: 6242 | I17: 2442 | L17: 102 | M17: 876 | N17: 1147 | O17: 129 | P17: =SUM(C17:O17) -> 85542 | Q17: 1242 | R17: 2718 | S17: 2020 | T17: 3147 | U17: 4086 | V17: 851 | W17: 292 | X17: 852 | Y17: 204 | Z17: 164 | AB17: =SUM(Q17:AA17) -> 15576 | AC17: =P17+AB17 -> 101118
B18: 合計點數 | C18: =C15+D15+E15+F15+C16+D16+E16+F16 -> 62107.23 | G18: =G15+H15+I15+G16+H16+I16 -> 8069 | L18: =L15+M15+N15+L16+M16+N16 -> 1528.45 | Q18: =Q15+R15+S15+Q16+R16+S16 -> 5371.77
B19: 合計配置數 | C19: =C17+D17+E17+F17 -> 73002 | G19: =G17+H17+I17 -> 10286 | L19: =L17+M17+N17 -> 2125 | Q19: =Q17+R17+S17 -> 5980
B20: 使用率 | C20: =C18/C19 -> 0.85076067 | G20: =G18/G19 -> 0.78446432 | L20: =L18/L19 -> 0.71927059 | O20: =(O15+O16)/O17 -> 1 | P20: =(P15+P16)/P17 -> 0.8397475 | Q20: =Q18/Q19 -> 0.8982893 | T20: =(T15+T16)/T17 -> 0.8193613 | U20: =(U15+U16)/U17 -> 0.52496329 | V20: =(V15+V16)/V17 -> 0.85663925 | W20: =(W15+W16)/W17 -> 0.93493151 | X20: =(X15+X16)/X17 -> 0.94464789 | Y20: =(Y15+Y16)/Y17 -> 0.96078431 | Z20: =(Z15+Z16)/Z17 -> 0.94390244 | AB20: =(AB15+AB16)/AB17 -> 0.78665511 | AC20: =(AC15+AC16)/AC17 -> 0.83156926 | AD20: =AD15/$AG$102 -> #DIV/0! | AE20: =AE15/$AG$102 -> #DIV/0! | AF20: =AF15/$AG$102 -> #DIV/0! | AG20: =AG15/$AG$102 -> #DIV/0!
A21: 2022年 3月 | B21: 點數 (i) | C21: 7895 | D21: 32892 | E21: 3795 | F21: 17620 | G21: 1529 | H21: 4351 | I21: 2241 | L21: 33 | M21: 810 | N21: 683 | O21: 129 | P21: =SUM(C21:O21) -> 71978 | Q21: 1078 | R21: 2395 | S21: 1902 | T21: 2602 | U21: 2135 | V21: 750 | W21: 273 | X21: 710 | Y21: 197 | Z21: 129 | AB21: =SUM(Q21:AA21) -> 12171 | AC21: =P21+AB21 -> 84149 | AD21: 13 | AE21: 4 | AF21: 4 | AG21: =SUM(AD21:AF21) -> 21 | AH21: 2509 | AI21: 3139 | AJ21: 1135 | AK21: =SUM(AH21:AJ26) -> 6783
B22: 延伸庫位 | C22: 35.5275 | D22: 148.014 | E22: 17.0775 | F22: 79.29 | G22: 0 | H22: 0 | I22: 0 | L22: 0 | M22: 4.05 | N22: 3.415 | O22: 0 | P22: =SUM(C22:O22) -> 287.374 | Q22: 10.78 | R22: 0 | S22: 0 | T22: 26.02 | U22: 0 | V22: 0 | W22: 0 | X22: 99.4 | Y22: 0 | Z22: 25.8 | AB22: =SUM(Q22:AA22) -> 162 | AC22: =P22+AB22 -> 449.374
B23: 配置數 | C23: 9252 | D23: 37456 | E23: 4675 | F23: 21619 | G23: 1602 | H23: 6242 | I23: 2442 | L23: 102 | M23: 876 | N23: 1147 | O23: 129 | P23: =SUM(C23:O23) -> 85542 | Q23: 1242 | R23: 2718 | S23: 2020 | T23: 3147 | U23: 4086 | V23: 851 | W23: 292 | X23: 852 | Y23: 204 | Z23: 164 | AB23: =SUM(Q23:AA23) -> 15576 | AC23: =P23+AB23 -> 101118
B24: 合計點數 | C24: =C21+D21+E21+F21+C22+D22+E22+F22 -> 62481.909 | G24: =G21+H21+I21+G22+H22+I22 -> 8121 | L24: =L21+M21+N21+L22+M22+N22 -> 1533.465 | Q24: =Q21+R21+S21+Q22+R22+S22 -> 5385.78
B25: 合計配置數 | C25: =C23+D23+E23+F23 -> 73002 | G25: =G23+H23+I23 -> 10286 | L25: =L23+M23+N23 -> 2125 | Q25: =Q23+R23+S23 -> 5980
B26: 使用率 | C26: =C24/C25 -> 0.85589311 | G26: =G24/G25 -> 0.78951974 | L26: =L24/L25 -> 0.72163059 | O26: =(O21+O22)/O23 -> 1 | P26: =(P21+P22)/P23 -> 0.84479407 | Q26: =Q24/Q25 -> 0.90063211 | T26: =(T21+T22)/T23 -> 0.83508738 | U26: =(U21+U22)/U23 -> 0.52251591 | V26: =(V21+V22)/V23 -> 0.8813161 | W26: =(W21+W22)/W23 -> 0.93493151 | X26: =(X21+X22)/X23 -> 0.95 | Y26: =(Y21+Y22)/Y23 -> 0.96568627 | Z26: =(Z21+Z22)/Z23 -> 0.94390244 | AB26: =(AB21+AB22)/AB23 -> 0.79179507 | AC26: =(AC21+AC22)/AC23 -> 0.83663021 | AD26: =AD21/$AG$102 -> #DIV/0! | AE26: =AE21/$AG$102 -> #DIV/0! | AF26: =AF21/$AG$102 -> #DIV/0! | AG26: =AG21/$AG$102 -> #DIV/0!
A27: 2022年 4月 | B27: 點數 (i) | C27: 7941 | D27: 32619 | E27: 3837 | F27: 18131 | G27: 1534 | H27: 4316 | I27: 2252 | L27: 35 | M27: 821 | N27: 690 | O27: 150 | P27: =SUM(C27:O27) -> 72326 | Q27: 1100 | R27: 2359 | S27: 1907 | T27: 2634 | U27: 2144 | V27: 748 | W27: 277 | X27: 717 | Y27: 198 | Z27: 129 | AB27: =SUM(Q27:AA27) -> 12213 | AC27: =P27+AB27 -> 84539 | AD27: 14 | AE27: 3 | AF27: 4 | AG27: =SUM(AD27:AF27) -> 21 | AH27: 1840 | AI27: 2521 | AJ27: 1084 | AK27: =SUM(AH27:AJ32) -> 5445
B28: 延伸庫位 | C28: 35.7345 | D28: 146.7855 | E28: 17.2665 | F28: 81.5895 | G28: 0 | H28: 0 | I28: 0 | L28: 0 | M28: 4.105 | N28: 3.45 | O28: 0 | P28: =SUM(C28:O28) -> 288.931 | Q28: 11 | R28: 0 | S28: 0 | T28: 26.34 | U28: 0 | V28: 0 | W28: 0 | X28: 100.38 | Y28: 0 | Z28: 25.8 | AB28: =SUM(Q28:AA28) -> 163.52 | AC28: =P28+AB28 -> 452.451
B29: 配置數 | C29: 9252 | D29: 37456 | E29: 4675 | F29: 21619 | G29: 1602 | H29: 6242 | I29: 2442 | L29: 102 | M29: 876 | N29: 1147 | O29: 151 | P29: =SUM(C29:O29) -> 85564 | Q29: 1242 | R29: 2718 | S29: 2020 | T29: 3147 | U29: 4086 | V29: 851 | W29: 292 | X29: 852 | Y29: 204 | Z29: 164 | AB29: =SUM(Q29:AA29) -> 15576 | AC29: =P29+AB29 -> 101140
B30: 合計點數 | C30: =C27+D27+E27+F27+C28+D28+E28+F28 -> 62809.376 | G30: =G27+H27+I27+G28+H28+I28 -> 8102 | L30: =L27+M27+N27+L28+M28+N28 -> 1553.555 | Q30: =Q27+R27+S27+Q28+R28+S28 -> 5377
B31: 合計配置數 | C31: =C29+D29+E29+F29 -> 73002 | G31: =G29+H29+I29 -> 10286 | L31: =L29+M29+N29 -> 2125 | Q31: =Q29+R29+S29 -> 5980
B32: 使用率 | C32: =C30/C31 -> 0.86037884 | G32: =G30/G31 -> 0.78767256 | L32: =L30/L31 -> 0.73108471 | O32: =(O27+O28)/O29 -> 0.99337748 | P32: =(P27+P28)/P29 -> 0.84866218 | Q32: =Q30/Q31 -> 0.89916388 | T32: =(T27+T28)/T29 -> 0.84535748 | U32: =(U27+U28)/U29 -> 0.52471855 | V32: =(V27+V28)/V29 -> 0.87896592 | W32: =(W27+W28)/W29 -> 0.94863014 | X32: =(X27+X28)/X29 -> 0.9593662 | Y32: =(Y27+Y28)/Y29 -> 0.97058824 | Z32: =(Z27+Z28)/Z29 -> 0.94390244 | AB32: =(AB27+AB28)/AB29 -> 0.79458911 | AC32: =(AC27+AC28)/AC29 -> 0.84033469 | AD32: =AD27/$AG$102 -> #DIV/0! | AE32: =AE27/$AG$102 -> #DIV/0! | AF32: =AF27/$AG$102 -> #DIV/0! | AG32: =AG27/$AG$102 -> #DIV/0!
A33: 2022年 5月 | B33: 點數 (i) | C33: 8037 | D33: 32045 | E33: 3837 | F33: 18896 | G33: 1534 | H33: 4358 | I33: 2264 | L33: 34 | M33: 816 | N33: 692 | O33: 149 | P33: =SUM(C33:O33) -> 72662 | Q33: 1124 | R33: 2371 | S33: 1892 | T33: 2637 | U33: 2181 | V33: 749 | W33: 276 | X33: 699 | Y33: 202 | Z33: 129 | AB33: =SUM(Q33:AA33) -> 12260 | AC33: =P33+AB33 -> 84922 | AD33: 14 | AE33: 3 | AF33: 4 | AG33: =SUM(AD33:AF33) -> 21 | AH33: 2123 | AI33: 3653 | AJ33: 1937 | AK33: =SUM(AH33:AJ38) -> 7713
B34: 延伸庫位 | C34: 36.1665 | D34: 144.2025 | E34: 17.2665 | F34: 85.032 | G34: 0 | H34: 0 | I34: 0 | L34: 0 | M34: 4.08 | N34: 3.46 | O34: 0 | P34: =SUM(C34:O34) -> 290.2075 | Q34: 11.24 | R34: 0 | S34: 0 | T34: 26.37 | U34: 0 | V34: 0 | W34: 0 | X34: 97.86 | Y34: 0 | Z34: 25.8 | AB34: =SUM(Q34:AA34) -> 161.27 | AC34: =P34+AB34 -> 451.4775
B35: 配置數 | C35: 9252 | D35: 37456 | E35: 4675 | F35: 21619 | G35: 1602 | H35: 6242 | I35: 2442 | L35: 102 | M35: 876 | N35: 1147 | O35: 151 | P35: =SUM(C35:O35) -> 85564 | Q35: 1242 | R35: 2718 | S35: 2020 | T35: 3147 | U35: 4086 | V35: 851 | W35: 292 | X35: 852 | Y35: 204 | Z35: 164 | AB35: =SUM(Q35:AA35) -> 15576 | AC35: =P35+AB35 -> 101140
B36: 合計點數 | C36: =C33+D33+E33+F33+C34+D34+E34+F34 -> 63097.667 | G36: =G33+H33+I33+G34+H34+I34 -> 8156 | L36: =L33+M33+N33+L34+M34+N34 -> 1549.54 | Q36: =Q33+R33+S33+Q34+R34+S34 -> 5398.24
B37: 合計配置數 | C37: =C35+D35+E35+F35 -> 73002 | G37: =G35+H35+I35 -> 10286 | L37: =L35+M35+N35 -> 2125 | Q37: =Q35+R35+S35 -> 5980
B38: 使用率 | C38: =C36/C37 -> 0.86432793 | G38: =G36/G37 -> 0.79292242 | L38: =L36/L37 -> 0.72919529 | O38: =(O33+O34)/O35 -> 0.98675497 | P38: =(P33+P34)/P35 -> 0.85260399 | Q38: =Q36/Q37 -> 0.90271572 | T38: =(T33+T34)/T35 -> 0.84632031 | U38: =(U33+U34)/U35 -> 0.53377386 | V38: =(V33+V34)/V35 -> 0.88014101 | W38: =(W33+W34)/W35 -> 0.94520548 | X38: =(X33+X34)/X35 -> 0.93528169 | Y38: =(Y33+Y34)/Y35 -> 0.99019608 | Z38: =(Z33+Z34)/Z35 -> 0.94390244 | AB38: =(AB33+AB34)/AB35 -> 0.79746212 | AC38: =(AC33+AC34)/AC35 -> 0.8441119 | AD38: =AD33/$AG$102 -> #DIV/0! | AE38: =AE33/$AG$102 -> #DIV/0! | AF38: =AF33/$AG$102 -> #DIV/0! | AG38: =AG33/$AG$102 -> #DIV/0!
A39: 2022年 6月 | B39: 點數 (i) | C39: 8074 | D39: 30954 | E39: 3744 | F39: 19545 | G39: 1527 | H39: 3991 | I39: 2283 | L39: 35 | M39: 823 | N39: 690 | O39: 151 | P39: =SUM(C39:O39) -> 71817 | Q39: 1132 | R39: 2380 | S39: 1906 | T39: 2559 | U39: 2002 | V39: 755 | W39: 277 | X39: 702 | Y39: 204 | Z39: 129 | AB39: =SUM(Q39:AA39) -> 12046 | AC39: =P39+AB39 -> 83863 | AD39: 14 | AE39: 3 | AF39: 4 | AG39: =SUM(AD39:AF39) -> 21 | AH39: 1878 | AI39: 4670 | AJ39: 1760 | AK39: =SUM(AH39:AJ44) -> 8308
B40: 延伸庫位 | C40: 36.333 | D40: 139.293 | E40: 16.848 | F40: 87.9525 | G40: 0 | H40: 0 | I40: 0 | L40: 0 | M40: 4.115 | N40: 3.45 | O40: 0 | P40: =SUM(C40:O40) -> 287.9915 | Q40: 11.32 | R40: 0 | S40: 0 | T40: 25.59 | U40: 0 | V40: 0 | W40: 0 | X40: 98.28 | Y40: 0 | Z40: 25.8 | AB40: =SUM(Q40:AA40) -> 160.99 | AC40: =P40+AB40 -> 448.9815
B41: 配置數 | C41: 9252 | D41: 37456 | E41: 4675 | F41: 21619 | G41: 1602 | H41: 6242 | I41: 2442 | L41: 102 | M41: 876 | N41: 1147 | O41: 151 | P41: =SUM(C41:O41) -> 85564 | Q41: 1242 | R41: 2718 | S41: 2020 | T41: 3147 | U41: 4086 | V41: 851 | W41: 292 | X41: 852 | Y41: 204 | Z41: 164 | AB41: =SUM(Q41:AA41) -> 15576 | AC41: =P41+AB41 -> 101140
...

Sheet 包材回收(同期比)
A2: 項目 | D2: 一月 | E2: 二月 | F2: 三月 | G2: 四月 | H2: 五月 | I2: 六月 | J2: 七月 | K2: 八月 | L2: 九月 | M2: 十月 | N2: 十一月 | O2: 十二月 | P2: 合計
A3: 2014包材回收 | B3: 重量 | C3: 國內 | D3: 5209 | E3: 3910 | F3: 3825 | G3: 5081 | H3: 4373 | I3: 4412 | J3: 4886 | K3: 3851 | L3: 3918 | M3: 3585 | N3: 4418 | O3: 2901 | P3: 50369
C4: 國外 | D4: 9072 | E4: 10025 | F4: 15303 | G4: 14948 | H4: 8755 | I4: 10066 | J4: 10998 | K4: 7788 | L4: 10408 | M4: 15447 | N4: 11424 | O4: 11286 | P4: 135520
C5: 合計 | D5: =SUM(D3:D4) -> 14281 | E5: =SUM(E3:E4) -> 13935 | F5: =SUM(F3:F4) -> 19128 | G5: =SUM(G3:G4) -> 20029 | H5: =SUM(H3:H4) -> 13128 | I5: =SUM(I3:I4) -> 14478 | J5: =SUM(J3:J4) -> 15884 | K5: =SUM(K3:K4) -> 11639 | ... P5: =SUM(P3:P4) -> 185889
B7: 金額 (萬元) | C7: 國內 | D7: 27.3 | E7: 21.5 | F7: 38.2 | G7: 44.6 | H7: 27.2 | I7: 34.8 | J7: 36.1 | K7: 22.5 | L7: 20.7 | M7: 24.5 | N7: 21 | O7: 32 | P7: 350.4
C8: 國外 | D8: 33.4 | E8: 35.4 | F8: 71.3 | G8: 70.4 | H8: 33.2 | I8: 40.4 | J8: 43.1 | K8: 26.9 | L8: 39.5 | M8: 53.4 | N8: 52 | O8: 54.6 | P8: =SUM(D8:O8) -> 553.6
C9: 合計 | D9: =SUM(D7:D8) -> 60.7 | E9: =SUM(E7:E8) -> 56.9 | F9: =SUM(F7:F8) -> 109.5 | G9: =SUM(G7:G8) -> 115 | H9: =SUM(H7:H8) -> 60.4 | I9: =SUM(I7:I8) -> 75.2 | J9: =SUM(J7:J8) -> 79.2 | K9: =SUM(K7:K8) -> 49.4 | ... O9: =SUM(O7:O8) -> 86.6 | P9: =SUM(D9:O9) -> 904
A11: 2015包材回收 | B11: 重量 | C11: 國內 | D11: 3682 | E11: 2836 | F11: 5003 | G11: 3897 | H11: 3875 | I11: 4322 | J11: 5970 | K11: 2327 | L11: 3296 | M11: 4341 | N11: 3640 | O11: 3880 | P11: =SUM(D11:O11) -> 47069
C12: 國外 | D12: 21027 | E12: 11097 | F12: 19367 | G12: 17626 | H12: 17245 | I12: 17245 | J12: 14879 | K12: 9229 | L12: 21318 | M12: 13625 | N12: 24016 | O12: 22278 | P12: =SUM(D12:O12) -> 208952
C13: 合計 | D13: =SUM(D11:D12) -> 24709 | E13: =SUM(E11:E12) -> 13933 | F13: =SUM(F11:F12) -> 24370 | G13: =SUM(G11:G12) -> 21523 | H13: =SUM(H11:H12) -> 21120 | I13: =SUM(I11:I12) -> 21567 | J13: =SUM(J11:J12) -> 20849 | K13: =SUM(K11:K12) -> 11556 | ... O13: =SUM(O11:O12) -> 26158 | P13: =SUM(D13:O13) -> 256021
C14: 同期比 | D14: =D13/D5 -> 1.730201 | E14: =E13/E5 -> 0.99985648 | F14: =F13/F5 -> 1.2740485 | G14: =G13/G5 -> 1.0745918 | H14: =H13/H5 -> 1.6087751 | I14: =I13/I5 -> 1.4896395 | J14: =J13/J5 -> 1.3125787 | K14: =K13/K5 -> 0.9928688 | ... O14: =O13/O5 -> 1.8438007 | P14: =SUM(D14:O14) -> 16.734224
B15: 金額 (萬元) | C15: 國內 | D15: 17.7 | E15: 45.5 | F15: 70 | G15: 36 | H15: 53 | I15: 46 | J15: 29.4 | K15: 11.8 | L15: 39.6 | M15: 26.6 | N15: 21.8 | O15: 35.9 | P15: =SUM(D15:O15) -> 433.3
C16: 國外 | D16: 102.9 | E16: 54 | F16: 80.9 | G16: 83.5 | H16: 75.2 | I16: 82.8 | J16: 65.6 | K16: 42 | L16: 110.6 | M16: 56 | N16: 109.7 | O16: 109.7 | P16: =SUM(D16:O16) -> 972.9
C17: 合計 | D17: =SUM(D15:D16) -> 120.6 | E17: =SUM(E15:E16) -> 99.5 | F17: =SUM(F15:F16) -> 150.9 | G17: =SUM(G15:G16) -> 119.5 | H17: =SUM(H15:H16) -> 128.2 | I17: =SUM(I15:I16) -> 128.8 | J17: =SUM(J15:J16) -> 95 | K17: =SUM(K15:K16) -> 53.8 | ... O17: =SUM(O15:O16) -> 145.6 | P17: =SUM(D17:O17) -> 1406.2
C18: 同期比 | D18: =D17/D9 -> 1.9868204 | E18: =E17/E9 -> 1.7486819 | F18: =F17/F9 -> 1.3780822 | G18: =G17/G9 -> 1.0391304 | H18: =H17/H9 -> 2.1225166 | I18: =I17/I9 -> 1.712766 | J18: =J17/J9 -> 1.1994949 | K18: =K17/K9 -> 1.0890688 | ... P18: =P17/P9 -> 1.555531 | Q18: =SUM(D18:P18) -> 20.870106 | R18: =Q18/12 -> 1.7391755
A19: 2016包材回收 | B19: 重量 | C19: 國內 | D19: 3338 | E19: 3751 | F19: 3605 | G19: 1456 | H19: 2994 | I19: 4268 | J19: 3994 | K19: 3873 | L19: 5975 | M19: 3747 | N19: 5619 | O19: 3012
C20: 國外 | D20: 19493 | E20: 15955 | F20: 25893 | G20: 13272 | H20: 23488 | I20: 20366 | J20: 18294 | K20: 15565 | L20: 17423 | M20: 17599 | N20: 19639 | O20: 22475
C21: 合計 | D21: 22831 | E21: 19706 | F21: 29498 | G21: 14728 | H21: 24648 | I21: 24634 | J21: 22288 | K21: 19438 | L21: 23398 | M21: 21346 | N21: 25258 | O21: =SUM(O19:O20) -> 25487
C22: 同期比 | D22: =D21/D13 -> 0.92399531 | E22: =E21/E13 -> 1.4143401 | F22: =F21/F13 -> 1.2104227 | G22: =G21/G13 -> 0.68429122 | H22: =H21/H13 -> 1.1670455 | I22: =I21/I13 -> 1.142208 | J22: =J21/J13 -> 1.0690201 | K22: =K21/K13 -> 1.6820699 | ... O22: =O21/O13 -> 0.97434819
B23: 金額 (萬元) | C23: 國內 | D23: 16.2 | E23: 22.1 | F23: 18.1 | G23: 6.7 | H23: 15.2 | I23: 23.9 | J23: 31.5 | K23: 19 | L23: 26.2 | M23: 29.1 | N23: 35.1 | O23: 32.3
C24: 國外 | D24: 95.5 | E24: 73.2 | F24: 116.3 | G24: 58.8 | H24: 110.5 | I24: 90.5 | J24: 85.3 | K24: 70.8 | L24: 83 | M24: 90 | N24: 96.1 | O24: 110.1
C25: 合計 | D25: 111.7 | E25: 95.3 | F25: 134.4 | G25: 65.5 | H25: 125.7 | I25: 114.4 | J25: 116.8 | K25: 89.8 | L25: 109.2 | M25: 119.1 | N25: 131.2 | O25: =SUM(O23:O24) -> 142.4
C26: 同期比 | D26: =D25/D17 -> 0.92620232 | E26: =E25/E17 -> 0.95778894 | F26: =F25/F17 -> 0.89065606 | G26: =G25/G17 -> 0.54811715 | H26: =H25/H17 -> 0.98049922 | I26: =I25/I17 -> 0.88819876 | J26: =J25/J17 -> 1.2294737 | K26: =K25/K17 -> 1.669145 | ... O26: =O25/O17 -> 0.97802198
A27: 2017包材回收 | B27: 重量 | C27: 國內 | D27: 2876 | E27: 2359 | F27: 4705 | G27: 2973 | H27: 3131 | I27: 4878 | J27: 4725 | K27: 3367 | L27: 2448 | M27: 2792 | N27: 6921 | O27: 5847
C28: 國外 | D28: 23333 | E28: 20020 | F28: 23623 | G28: 11484 | H28: 22607 | I28: 22292 | J28: 19945 | K28: 21619 | L28: 19035 | M28: 13170 | N28: 13418 | O28: 12391
C29: 合計 | D29: =SUM(D27:D28) -> 26209 | E29: 22379 | F29: 28328 | G29: 14457 | H29: 25738 | I29: 27170 | J29: 24670 | K29: 24986 | L29: 21483 | M29: 15962 | N29: 20339 | O29: 18238
C30: 同期比 | D30: =D29/D21 -> 1.1479567 | E30: =E29/E21 -> 1.135644 | F30: =F29/F21 -> 0.96033629 | G30: =G29/G21 -> 0.98159967 | H30: =H29/H21 -> 1.0442227 | I30: =I29/I21 -> 1.1029471 | J30: =J29/J21 -> 1.1068737 | K30: =K29/K21 -> 1.2854203 | ... O30: =O29/O21 -> 0.71558049
B31: 金額 (萬元) | C31: 國內 | D31: 28.9 | E31: 32.1 | F31: 36.9 | G31: 23.4 | H31: 26.8 | I31: 25.1 | J31: 29.6 | K31: 28.3 | L31: 28.6 | M31: 21.6 | N31: 40.4 | O31: 34.1
C32: 國外 | D32: 113.3 | E32: 92.9 | F32: 111.3 | G32: 49.4 | H32: 97.6 | I32: 108.2 | J32: 100.7 | K32: 103.3 | L32: 88.3 | M32: 62.8 | N32: 59 | O32: 62
C33: 合計 | D33: 142.2 | E33: 125 | F33: 148.2 | G33: 72.8 | H33: 124.4 | I33: 133.3 | J33: 130.3 | K33: 131.6 | L33: 116.9 | M33: 84.4 | N33: 99.4 | O33: 96.1
C34: 同期比 | D34: =D33/D25 -> 1.2730528 | E34: =E33/E25 -> 1.3116474 | F34: =F33/F25 -> 1.1026786 | G34: =G33/G25 -> 1.1114504 | H34: =H33/H25 -> 0.98965792 | I34: =I33/I25 -> 1.1652098 | J34: =J33/J25 -> 1.1155822 | K34: =K33/K25 -> 1.4654788 | ... O34: =O33/O25 -> 0.67485955
A35: 2018包材回收 | B35: 重量 | C35: 國內 | D35: 6404 | E35: 5279 | F35: 7157 | G35: 3367 | H35: 9871 | I35: 9953 | J35: 9618 | K35: 9544 | L35: 9712 | M35: 8041 | N35: 3313 | O35: 7407
C36: 國外 | D36: 18721 | E36: 9937 | F36: 21946 | G36: 10583 | H36: 13259 | I36: 11654 | J36: 8581 | K36: 3900 | L36: 8800 | M36: 18008 | N36: 23826 | O36: 16269
C37: 合計 | D37: =SUM(D35:D36) -> 25125 | E37: =SUM(E35:E36) -> 15216 | F37: 29103 | G37: 13950 | H37: 23130 | I37: 21607 | J37: 18199 | K37: 13444 | L37: 18512 | M37: 26049 | N37: 27139 | O37: 23676
C38: 同期比 | D38: =D37/D29 -> 0.95864016 | E38: =E37/E29 -> 0.67992314 | F38: =F37/F29 -> 1.0273581 | G38: =G37/G29 -> 0.96493048 | H38: =H37/H29 -> 0.89867123 | I38: =I37/I29 -> 0.79525212 | J38: =J37/J29 -> 0.73769761 | K38: =K37/K29 -> 0.53806131 | ... O38: =O37/O29 -> 1.2981687
B39: 金額 (萬元) | C39: 國內 | D39: 37 | E39: 33 | F39: 40.1 | G39: 21.9 | H39: 56.7 | I39: 56.9 | J39: 56.4 | K39: 55.8 | L39: 56 | M39: 48.8 | N39: 12.3 | O39: 31.9
C40: 國外 | D40: 89.3 | E40: 46.3 | F40: 96.2 | G40: 53.9 | H40: 69 | I40: 70 | J40: 50 | K40: 22 | L40: 35.4 | M40: 81 | N40: 100 | O40: 98
C41: 合計 | D41: =SUM(D39:D40) -> 126.3 | E41: =SUM(E39:E40) -> 79.3 | F41: 136.3 | G41: 75.8 | H41: 125.7 | I41: 126.9 | J41: 106.4 | K41: 77.8 | L41: 91.4 | M41: 129.8 | N41: 112.3 | O41: 98.4
C42: 同期比 | D42: =D41/D33 -> 0.88818565 | E42: =E41/E33 -> 0.6344 | F42: =F41/F33 -> 0.9197031 | G42: =G41/G33 -> 1.0412088 | H42: =H41/H33 -> 1.0104502 | I42: =I41/I33 -> 0.951988 | J42: =J41/J33 -> 0.81657713 | K42: =K41/K33 -> 0.59118541 | ... O42: =O41/O33 -> 1.0239334
A43: 2019包材回收 | B43: 重量 | C43: 國內 | D43: 4564 | E43: 5089 | F43: 5015 | G43: 3895 | H43: 3866 | I43: 6300 | J43: 4003 | K43: 3024 | L43: 3113 | M43: 3984 | N43: 3524 | O43: 4305
...

Sheet 加班時數
A1: 月份/類別 | B1: 一 | C1: 二 | D1: 三 | E1: 四 | F1: 五 | G1: 六 | H1: 七 | I1: 八 | J1: 九 | K1: 十 | L1: 十一 | M1: 十二
A2: 大物進貨 | B2: 69.2 | C2: 114 | D2: 92 | E2: 83 | F2: 82.5 | G2: 125 | H2: 345.5 | I2: 173 | J2: 44 | K2: 102 | L2: 113 | M2: 59.5
A3: 中小物進貨 | B3: 123.3 | C3: 92 | D3: 36 | E3: 4.5 | F3: 37.9 | G3: 138 | H3: 41 | I3: 34 | J3: 244 | K3: 222 | L3: 267
A4: 改善支援上架 | B4: 30 | C4: 29 | D4: 44 | E4: 41 | F4: 16.5 | G4: 33 | H4: 13.5 | I4: 33 | K4: 17.5 | L4: 24 | M4: 4.5
A5: 支援補充上架作業(中小物) | B5: 76.4 | C5: 94.1 | D5: 98.2 | E5: 100.7 | F5: 97.9 | G5: 80.1 | H5: 97.4 | I5: 120 | J5: 135.8 | K5: 99 | L5: 86.1 | M5: 119.1
A6: 中小物進貨空運檢查支援＆加班 | C6: 36.6 | D6: 27.1 | E6: 37.6 | G6: 57.2 | H6: 49.3 | I6: 30.2 | J6: 50 | K6: 49.8 | L6: 44 | M6: 49
A7: 進貨合計 | B7: =SUM(B2:B6) -> 298.9 | C7: =SUM(C2:C6) -> 365.7 | D7: =SUM(D2:D6) -> 297.3 | E7: =SUM(E2:E6) -> 266.8 | F7: =SUM(F2:F6) -> 234.8 | G7: =SUM(G2:G6) -> 433.3 | H7: =SUM(H2:H6) -> 546.7 | I7: =SUM(I2:I6) -> 390.2 | ... M7: =SUM(M2:M6) -> 232.1
A9: 大物出貨 | B9: 337 | C9: 81 | D9: 400 | E9: 322.5 | F9: 320.5 | G9: 280.5 | H9: 48 | I9: 264.5 | J9: 342 | K9: 378 | L9: 402.5 | M9: 322.5
A10: 中小物出貨 | B10: 109.5 | C10: 112.5 | E10: 23.5 | F10: 14 | G10: 50.5 | H10: 54 | I10: 122 | J10: 93.8 | K10: =230+69.2 -> 299.2 | L10: 231 | M10: 359.2
A11: 月台理貨 | B11: 124 | C11: 75 | D11: 119.5 | E11: 64 | F11: 107.5 | G11: 97 | H11: 125 | I11: 142 | J11: 154 | K11: 157 | L11: 2 | M11: 131.5
A12: 精品出貨
A13: AGV理貨段取(支援)
A14: 改善人員/週六出勤封箱補充支援周六出貨(補充) | B14: 80 | C14: 16 | D14: 84 | E14: 72 | F14: 72 | G14: 65 | H14: 72 | I14: 56 | J14: 69.5 | K14: 64 | L14: 83 | M14: 48
A15: 支援段取到月台 | B15: 65 | C15: 60.4 | D15: 59.6 | E15: 107.9 | F15: =8.5+56.9 -> 65.4 | G15: 69.3 | H15: 71.1 | I15: 75.9 | J15: 70.2 | K15: =46.2+23 -> 69.2 | L15: 227.9 | M15: 310
A16: 中小物出貨W庫支援&加班 | B16: 76.6 | C16: 66.6 | D16: 47.3 | E16: 45.2 | F16: 32.9 | G16: 47.5 | H16: 46.3 | I16: 48.6 | J16: 41.4 | K16: 59.1 | L16: 65.1 | M16: 61.8
A17: 幹線疊貨作業
A18: 出貨合計 | B18: =SUM(B9:B17) -> 792.1 | C18: =SUM(C9:C17) -> 411.5 | D18: =SUM(D9:D17) -> 710.4 | E18: =SUM(E9:E17) -> 635.1 | F18: =SUM(F9:F17) -> 612.3 | G18: =SUM(G9:G17) -> 609.8 | H18: =SUM(H9:H17) -> 416.4 | I18: =SUM(I9:I17) -> 709 | ... M18: =SUM(M9:M17) -> 1233
A20: 包裝大物進貨 | C20: 28
A21: 包裝中小物進貨 | B21: 80 | C21: 246 | D21: 20 | E21: 68 | F21: 32 | G21: 54 | H21: 36 | I21: 84 | J21: 16 | K21: 62
A22: 包裝 | B22: 574 | D22: 178 | E22: 478 | F22: 276 | G22: 430 | H22: 256.5 | I22: 816 | J22: 160 | K22: 503 | L22: 493.5 | M22: 231
A23: 保桿
A24: 輸出 | B24: 156 | C24: 132 | D24: 216 | E24: 148 | F24: 90 | G24: 138 | H24: 293 | I24: 259 | J24: 176 | K24: 116.5 | L24: 151.5 | M24: 71.5
A25: 其他:對應KZ盤點.打切零件.事務.手冊 | B25: 30 | C25: 87.5 | D25: 10 | E25: 26 | F25: 21 | G25: 19 | H25: 128.2 | I25: 5.3 | J25: 14.5 | K25: 21 | L25: 28 | M25: 18
A26: 包裝合計 | B26: =SUM(B20:B25) -> 840 | C26: =SUM(C20:C25) -> 493.5 | D26: =SUM(D20:D25) -> 424 | E26: =SUM(E20:E25) -> 720 | F26: =SUM(F20:F25) -> 419 | G26: =SUM(G20:G25) -> 641 | H26: =SUM(H20:H25) -> 713.7 | I26: =SUM(I20:I25) -> 1164.3 | ... M26: =SUM(M20:M25) -> 320.5
A28: 總計 | B28: =B26+B18+B7 -> 1931 | C28: =C26+C18+C7 -> 1270.7 | D28: =D26+D18+D7 -> 1431.7 | E28: =E26+E18+E7 -> 1621.9 | F28: =F26+F18+F7 -> 1266.1 | G28: =G26+G18+G7 -> 1684.1 | H28: =H26+H18+H7 -> 1676.8 | I28: =I26+I18+I7 -> 2263.5 | ... M28: =M26+M18+M7 -> 1785.6

Sheet 優開SQL(中小物)
A1: --優開--
A2: SELECT CAST(CRTDT AS DATE) AS CRTDT,COUNT(*) AS CNT
A3: FROM VPMTSNO
A4: WHERE REJECTCD=' ' AND SNOTYPE='C'
A5: AND CONVERT(VARCHAR,CRTDT,112) BETWEEN '20251201' AND '20251231'
A6: GROUP BY CAST(CRTDT AS DATE)
A7: ORDER BY CAST(CRTDT AS DATE)
