Workbook

Sheet 2026年
A1: 2026年零件部楊梅配銷室月報
A2: 項目 | E2: 當月目標 | F2: 當月達成率 | G2: 1月 | H2: 2月 | I2: 3月 | J2: 4月 | K2: 5月 | L2: 6月 | M2: 7月 | N2: 8月 | O2: 9月 | P2: 10月 | Q2: 11月 | R2: 12月 | S2: 平均累計 | T2: 累計達成率 | Y2: 12
A3: 材敏現場人員數 | E3: --- | F3: --- | G3: 110 | H3: 109 | I3: 110 | J3: 109 | K3: 107 | L3: 103 | M3: 107 | N3: 105 | O3: 108 | S3: =AVERAGE(G3:R3) -> 107.55556 | T3: --- | U3: 材敏大物25--鈞傑/鈞凱+(進貨17+出貨29)--小鳳+P9(27)
A4: 作業量 | B4: 進貨 | C4: 點數 | E4: --- | F4: --- | G4: ='進貨點數(同期比)'!B58 -> 93998 | H4: ='進貨點數(同期比)'!C58 -> 66193 | I4: ='進貨點數(同期比)'!D58 -> 99100 | J4: ='進貨點數(同期比)'!E58 -> 93418 | K4: ='進貨點數(同期比)'!F58 -> 85602 | L4: ='進貨點數(同期比)'!G58 -> 98449 | M4: ='進貨點數(同期比)'!H58 -> 101191 | N4: ='進貨點數(同期比)'!I58 -> 97533 | O4: ='進貨點數(同期比)'!J58 -> 83632 | S4: =AVERAGE(G4:R4) -> 91012.889 | T4: --- | U4: 參考p7
D5: 同期比 | G5: ='進貨點數(同期比)'!B60 -> 0.72394141 | H5: ='進貨點數(同期比)'!C60 -> 0.64617622 | I5: ='進貨點數(同期比)'!D60 -> 0.99536967 | J5: ='進貨點數(同期比)'!E60 -> 0.90323516 | K5: ='進貨點數(同期比)'!F60 -> 1.1322267 | L5: ='進貨點數(同期比)'!G60 -> 0.96299593 | M5: ='進貨點數(同期比)'!H60 -> 1.0257577 | N5: ='進貨點數(同期比)'!I60 -> 1.0163499 | O5: ='進貨點數(同期比)'!J60 -> 0.88608239 | S5: =AVERAGE(G5:R5) -> 0.92134834 | U5: 參考進貨點數(同期比)
C6: PCS數 | E6: --- | F6: --- | G6: ='進貨點數(同期比)'!B59 -> 1730666 | H6: ='進貨點數(同期比)'!C59 -> 1193278 | I6: ='進貨點數(同期比)'!D59 -> 1784935 | J6: ='進貨點數(同期比)'!E59 -> 1763625 | K6: ='進貨點數(同期比)'!F59 -> 1513053 | L6: ='進貨點數(同期比)'!G59 -> 1877840 | M6: ='進貨點數(同期比)'!H59 -> 2005426 | N6: ='進貨點數(同期比)'!I59 -> 1622651 | O6: ='進貨點數(同期比)'!J59 -> 1389211 | S6: =AVERAGE(G6:R6) -> 1653409.4 | T6: ---
D7: 同期比 | G7: ='進貨點數(同期比)'!B61 -> 1.1593049 | H7: ='進貨點數(同期比)'!C61 -> 0.77116876 | I7: ='進貨點數(同期比)'!D61 -> 1.1262393 | J7: ='進貨點數(同期比)'!E61 -> 1.1237947 | K7: ='進貨點數(同期比)'!F61 -> 1.0517289 | L7: ='進貨點數(同期比)'!G61 -> 1.1449734 | M7: ='進貨點數(同期比)'!H61 -> 1.1545216 | N7: ='進貨點數(同期比)'!I61 -> 0.97509927 | O7: ='進貨點數(同期比)'!J61 -> 0.79507426 | S7: =AVERAGE(G7:R7) -> 1.033545
C8: 加班時數 | E8: --- | F8: --- | G8: =加班時數!B7 -> 317.3 | H8: =加班時數!C7 -> 273.7 | I8: =加班時數!D7 -> 310.5 | J8: =加班時數!E7 -> 414.8 | K8: =加班時數!F7 -> 327 | L8: =加班時數!G7 -> 984 | M8: =加班時數!H7 -> 887.2 | N8: =加班時數!I7 -> 1091 | O8: =加班時數!J7 -> 829 | S8: =AVERAGE(G8:R8) -> 603.83333 | U8: I:\3楊梅配銷室\06.共同事務\A.月報\106年\月報新版共二頁-2017年材敏加班統計，加班合計
B9: 出貨 | C9: 點數 | E9: --- | F9: --- | G9: ='出貨點數(其他附件)'!B272 -> 463128 | H9: ='出貨點數(其他附件)'!C272 -> 282648 | I9: ='出貨點數(其他附件)'!D272 -> 448476 | J9: ='出貨點數(其他附件)'!E272 -> 377212 | K9: ='出貨點數(其他附件)'!F272 -> 387639 | L9: ='出貨點數(其他附件)'!G272 -> 404293 | M9: ='出貨點數(其他附件)'!H272 -> 430037 | N9: ='出貨點數(其他附件)'!I272 -> 397054 | O9: ='出貨點數(其他附件)'!J272 -> 383868 | S9: =AVERAGE(G9:R9) -> 397150.56 | T9: --- | U9: 參考p1
D10: 同期比 | G10: ='出貨點數(其他附件)'!B273 -> 1.2185142 | H10: ='出貨點數(其他附件)'!C273 -> 0.7465413 | I10: ='出貨點數(其他附件)'!D273 -> 1.0773111 | J10: ='出貨點數(其他附件)'!E273 -> 0.99364111 | K10: ='出貨點數(其他附件)'!F273 -> 1.0092768 | L10: ='出貨點數(其他附件)'!G273 -> 0.99063742 | M10: ='出貨點數(其他附件)'!H273 -> 0.98026866 | N10: ='出貨點數(其他附件)'!I273 -> 0.97268999 | O10: ='出貨點數(其他附件)'!J273 -> 0.97446976 | S10: =AVERAGE(G10:R10) -> 0.99592782
C11: HF點數 | E11: --- | F11: --- | G11: 107789 | H11: 62806 | I11: 99139 | J11: 81409 | K11: 78056 | L11: 85020 | M11: 92859 | N11: 80452 | O11: 79393 | S11: =AVERAGE(G11:R11) -> 85213.667 | U11: 參考p8 | V11: (台中倉全日出貨量DLR/HF+湖內副倉全日出貨量DLR/HF)-I數
C12: PCS數 | E12: --- | F12: --- | G12: ='出貨點數(其他附件)'!B291 -> 3213190 | H12: ='出貨點數(其他附件)'!C291 -> 2272546 | I12: ='出貨點數(其他附件)'!D291 -> 3096359 | J12: ='出貨點數(其他附件)'!E291 -> 2822380 | K12: ='出貨點數(其他附件)'!F291 -> 2851680 | L12: ='出貨點數(其他附件)'!G291 -> 2973362 | M12: ='出貨點數(其他附件)'!H291 -> 3213687 | N12: ='出貨點數(其他附件)'!I291 -> 2832281 | O12: ='出貨點數(其他附件)'!J291 -> 2733219 | S12: =AVERAGE(G12:R12) -> 2889856 | T12: --- | U12: 參考p1
D13: 同期比 | G13: ='出貨點數(其他附件)'!B292 -> 1.0616406 | H13: ='出貨點數(其他附件)'!C292 -> 0.90520243 | I13: ='出貨點數(其他附件)'!D292 -> 1.0540169 | J13: ='出貨點數(其他附件)'!E292 -> 1.0416328 | K13: ='出貨點數(其他附件)'!F292 -> 1.0025185 | L13: ='出貨點數(其他附件)'!G292 -> 1.0397745 | M13: ='出貨點數(其他附件)'!H292 -> 1.0476909 | N13: ='出貨點數(其他附件)'!I292 -> 1.0360602 | O13: ='出貨點數(其他附件)'!J292 -> 1.0002181 | S13: =AVERAGE(G13:R13) -> 1.0209728
C14: HF PCS數 | E14: --- | F14: --- | G14: 598775 | H14: 369467 | I14: 554768 | J14: 535762 | K14: 511402 | L14: 551867 | M14: 601703 | N14: 493923 | O14: 481872 | S14: =AVERAGE(G14:R14) -> 522171 | U14: 參考p8 | V14: (台中倉全日出貨量DLR/HF+湖內副倉全日出貨量DLR/HF)-PCS數
C15: 加班時數 | E15: --- | F15: --- | G15: =加班時數!B18 -> 1593 | H15: =加班時數!C18 -> 608.5 | I15: =加班時數!D18 -> 1508.5 | J15: =加班時數!E18 -> 1670.5 | K15: =加班時數!F18 -> 1742.5 | L15: =加班時數!G18 -> 1666.5 | M15: =加班時數!H18 -> 1752 | N15: =加班時數!I18 -> 1717.5 | O15: =加班時數!J18 -> 1663.5 | S15: =AVERAGE(G15:R15) -> 1546.9444
B16: 優先開箱點數 | C16: 中小物 | E16: --- | F16: --- | G16: 1034 | H16: 431 | I16: 1015 | J16: 772 | K16: 969 | L16: 2133 | M16: 1386 | N16: 953 | O16: 1247 | S16: =AVERAGE(G16:R16) -> 1104.4444 | T16: --- | U16: 抓QB
C17: 大物 | E17: --- | F17: --- | G17: 1820 | H17: 1322 | I17: 3102 | J17: 1687 | K17: 4776 | L17: 4549 | M17: 6157 | N17: 4911 | O17: 9425 | S17: =AVERAGE(G17:R17) -> 4194.3333 | T17: --- | U17: 慶林兄提供
B18: 包裝 | C18: 點數 | E18: --- | F18: --- | G18: 21348 | H18: 16123 | I18: 20130 | J18: 19893 | K18: 20934 | L18: 19857 | M18: 22842 | N18: 18486 | O18: 20931 | S18: =AVERAGE(G18:R18) -> 20060.444 | T18: --- | U18: P9到貨
D19: 同期比 | G19: 0.89102216 | H19: 0.80679544 | I19: 0.90402838 | J19: 0.89773907 | K19: 1.2761522 | L19: 1.0318541 | M19: 0.97933459 | N19: 1.0179515 | O19: 1.0043184 | S19: =AVERAGE(G19:R19) -> 0.97879954
C20: PCS數 | E20: --- | F20: --- | G20: 160072 | H20: 123118 | I20: 118326 | J20: 108016 | K20: 120885 | L20: 130134 | M20: 166405 | N20: 132039 | O20: 130504 | S20: =AVERAGE(G20:R20) -> 132166.56 | T20: ---
D21: 同期比 | G21: 0.96620994 | H21: 0.98199801 | I21: 0.87042173 | J21: 0.70389824 | K21: 0.97673009 | L21: 0.98968743 | M21: 1.1123701 | N21: 0.86065991 | O21: 1.0676571 | S21: =AVERAGE(G21:R21) -> 0.94773695
C22: 加班時數 | E22: --- | F22: --- | G22: =加班時數!B26 -> 213.3 | H22: =加班時數!C26 -> 238 | I22: =加班時數!D26 -> 346.8 | J22: =加班時數!E26 -> 306.8 | K22: =加班時數!F26 -> 382 | L22: =加班時數!G26 -> 790.5 | M22: =加班時數!H26 -> 979.7 | N22: =加班時數!I26 -> 837.8 | O22: =加班時數!J26 -> 952 | S22: =AVERAGE(G22:R22) -> 560.76667 | U22: I:\3楊梅配銷室\06.共同事務\A.月報\106年\月報新版共二頁-2017年材敏加班統計, 加班合計
A23: 生產力 | B23: 進貨(i/hr) | E23: 36 | F23: =M23/E23 -> 1.3111111 | G23: 43.6 | H23: 43.2 | I23: 49.5 | J23: 40.2 | K23: 42.9 | L23: 36.9 | M23: 47.2 | N23: 51.7 | O23: 45.1 | S23: =AVERAGE(G23:R23) -> 44.477778 | T23: =S23/E23 -> 1.2354938
C24: 中小物(i/hr) | G24: 55.6 | H24: 21.3 | I24: 60.4 | J24: 51.7 | K24: 53.9 | L24: 45.1 | M24: 63.2 | N24: 73.3 | O24: 61.2
C25: 大物(i/hr) | G25: 25.2 | H25: 74.8 | I25: 35.6 | J25: 24.7 | K25: 26.6 | L25: 23.7 | M25: 25.6 | N25: 26.3 | O25: 24.5
B26: 出貨(i/hr) | E26: 63.6 | F26: =M26/E26 -> 1.0141509 | G26: 70.7 | H26: 64.2 | I26: 71.2 | J26: 65.4 | K26: 62.4 | L26: 64.8 | M26: 64.5 | N26: 63.1 | O26: 61.6 | S26: =AVERAGE(G26:R26) -> 65.322222 | T26: =S26/E26 -> 1.027079
C27: 中小物(i/hr) | G27: 86.2 | H27: 79.4 | I27: 85 | J27: 79.2 | K27: 70.9 | L27: 82.8 | M27: 83.9 | N27: 79.4 | O27: 80.6
C28: 大物(i/hr) | G28: 45.8 | H28: 41.9 | I28: 49.7 | J28: 42.7 | K28: 45.5 | L28: 39 | M28: 37.8 | N28: 38.9 | O28: 36.4
B29: 包裝(i/hr) | E29: 138 | F29: =M29/E29 -> 1.0098551 | G29: 140.65 | H29: 140.29 | I29: 139.51 | J29: 139.05 | K29: 140.48 | L29: 140.82 | M29: 139.36 | N29: 141.59 | O29: 140.41 | S29: =AVERAGE(G29:R29) -> 140.24 | T29: =S29/E29 -> 1.0162319 | U29: P9
A30: 品質 | B30: 出貨品質 | C30: 誤品(ppm) | E30: 9 | F30: =IF(M30=0,"-",E30/M30) -> 1.7307692 | G30: 0 | H30: 0 | I30: 0 | J30: 2.9 | K30: 0 | L30: 2.8 | M30: 5.2 | N30: 0 | O30: 0 | S30: =AVERAGE(G30:R31) -> 1.2111111 | T30: =E30/S30 -> 7.4311927
C31: 欠品(ppm) | F31: =E31/K31 -> #DIV/0! | U31: P3
C32: 損品(ppm) | E32: 8 | F32: =IF(M32=0,"-",E32/M32) -> - | G32: 0 | H32: 0 | I32: 0 | J32: 0 | K32: 0 | L32: 0 | M32: 0 | N32: 0 | O32: 0 | S32: =AVERAGE(G32:R32) -> 0 | T32: 1
C33: 包裝(ppm) | E33: 103 | F33: =IF(M33=0,"-",E33/M33) -> 0.86554622 | G33: 178 | H33: 129 | I33: 111 | J33: 134 | K33: 279 | L33: 169 | M33: 119 | N33: 249 | O33: 27 | S33: =AVERAGE(G33:R33) -> 155 | T33: =E33/S33 -> 0.66451613 | U33: P9
B34: 配送品質-準時率 | E34: 98 | F34: =M34/E34 -> 1 | G34: 98 | H34: 98 | I34: 98 | J34: 98 | K34: 98 | L34: 98 | M34: 98 | N34: 98 | O34: 98 | S34: =AVERAGE(G34:R34) -> 98 | T34: =S34/E34 -> 1 | U34: P8
A35: 包材回收 | B35: 重量 (公斤) | C35: 國內 | E35: --- | F35: --- | G35: ='包材回收(同期比)'!D99 -> 2155 | H35: ='包材回收(同期比)'!E99 -> 1805 | I35: ='包材回收(同期比)'!F99 -> 2723 | J35: ='包材回收(同期比)'!G99 -> 2055 | K35: ='包材回收(同期比)'!H99 -> 2345 | L35: ='包材回收(同期比)'!I99 -> 2275 | M35: ='包材回收(同期比)'!J99 -> 2205 | N35: 2135 | O35: 1859 | S35: =AVERAGE(G35:R35) -> 2173 | T35: --- | U35: I:\3楊梅配銷室\06.共同事務-楊配室KPI匯整
C36: 國外 | E36: --- | F36: --- | G36: ='包材回收(同期比)'!D100 -> 15318 | H36: ='包材回收(同期比)'!E100 -> 12213 | I36: ='包材回收(同期比)'!F100 -> 21784 | J36: ='包材回收(同期比)'!G100 -> 15884 | K36: ='包材回收(同期比)'!H100 -> 16660 | L36: ='包材回收(同期比)'!I100 -> 15063 | M36: ='包材回收(同期比)'!J100 -> 18170 | N36: 16408 | O36: 20939 | S36: =AVERAGE(G36:R36) -> 16937.667 | T36: ---
C37: 合計 | E37: 28171 | F37: =M37/E37 -> 0.72326151 | G37: =G35+G36 -> 17473 | H37: =H35+H36 -> 14018 | I37: =I35+I36 -> 24507 | J37: =J35+J36 -> 17939 | K37: =K35+K36 -> 19005 | L37: =L35+L36 -> 17338 | M37: =M35+M36 -> 20375 | N37: 18543 | O37: 22798 | S37: =AVERAGE(G37:R37) -> 19110.667 | T37: ---
C38: 同期比 | E38: --- | F38: --- | G38: ='包材回收(同期比)'!D102 -> 1.0131037 | H38: ='包材回收(同期比)'!E102 -> 0.55197669 | I38: ='包材回收(同期比)'!F102 -> 0.89526558 | J38: ='包材回收(同期比)'!G102 -> 0.58146281 | K38: ='包材回收(同期比)'!H102 -> 0.85983803 | L38: ='包材回收(同期比)'!I102 -> 0.53732916 | M38: ='包材回收(同期比)'!J102 -> 0.74985279 | N38: ='包材回收(同期比)'!K102 -> 1.2657338 | O38: ='包材回收(同期比)'!L102 -> 0.91363764 | S38: =AVERAGE(G38:R38) -> 0.81868891
B39: 金額 (萬元) | C39: 國內 | E39: --- | F39: --- | G39: ='包材回收(同期比)'!D103 -> 9.8 | H39: ='包材回收(同期比)'!E103 -> 8.4 | I39: ='包材回收(同期比)'!F103 -> 12.4 | J39: ='包材回收(同期比)'!G103 -> 9.4 | K39: ='包材回收(同期比)'!H103 -> 10.8 | L39: ='包材回收(同期比)'!I103 -> 10.4 | M39: ='包材回收(同期比)'!J103 -> 10.1 | N39: 9.7 | O39: 8.3 | S39: =AVERAGE(G39:R39) -> 9.9222222 | T39: ---
C40: 國外 | E40: --- | F40: --- | G40: ='包材回收(同期比)'!D104 -> 91.1 | H40: ='包材回收(同期比)'!E104 -> 49.2 | I40: ='包材回收(同期比)'!F104 -> 82.4 | J40: ='包材回收(同期比)'!G104 -> 64.2 | K40: ='包材回收(同期比)'!H104 -> 67.3 | L40: ='包材回收(同期比)'!I104 -> 60.7 | M40: ='包材回收(同期比)'!J104 -> 71.7 | N40: 67.2 | O40: 88.3 | S40: =AVERAGE(G40:R40) -> 71.344444 | T40: ---
...

Sheet 出貨點數(其他附件)
A1: 2019年 /月份 | B1: 1 | C1: 2 | D1: 3 | E1: 4 | F1: 5 | G1: 6 | H1: 7 | I1: 8 | J1: 9 | K1: 10 | L1: 11 | M1: 12
A2: 零件 i | B2: 391042 | C2: 232855 | D2: 313479 | E2: 296353 | F2: 317723 | G2: 299282 | H2: 340859 | I2: 321679 | J2: 293513 | K2: 328038 | L2: 319587 | M2: 355032
A3: 和勁 i | B3: 19165 | C3: 5370 | D3: 7040 | E3: 8088 | F3: 14307 | G3: 15998 | H3: 17087 | I3: 9871 | J3: 7884 | K3: 10591 | L3: 14011 | M3: 19338
A4: 產機 i | B4: 1541 | C4: 915 | D4: 1173 | E4: 1192 | F4: 1374 | G4: 1259 | H4: 1698 | I4: 1184 | J4: 1284 | K4: 1463 | L4: 1337 | M4: 1413
A5: 車美仕 i | B5: 9219 | C5: 5688 | D5: 6409 | E5: 7215 | F5: 6512 | G5: 7125 | H5: 6171 | I5: 3806 | J5: 4954 | K5: 6786 | L5: 6618 | M5: 7404
A6: 和運 i | B6: 767 | C6: 338 | D6: 601 | E6: 480 | F6: 523 | G6: 573 | H6: 690 | I6: 627 | J6: 544 | K6: 652 | L6: 735 | M6: 807
A7: 和運經銷商i | B7: 1979 | C7: 1127 | D7: 1706 | E7: 1466 | F7: 2276 | G7: 1829 | H7: 2225 | I7: 2422 | J7: 2030 | K7: 2523 | L7: 2213 | M7: 2459
A8: 湯淺 i | B8: 1781 | C8: 1320 | D8: 1206 | E8: 908 | F8: 1448 | G8: 1596 | H8: 1620 | I8: 1678 | J8: 2144 | K8: 1778 | L8: 2075 | M8: 1814
A9: 總合計i | B9: =SUM(B2:B8) -> 425494 | C9: =SUM(C2:C8) -> 247613 | D9: =SUM(D2:D8) -> 331614 | E9: =SUM(E2:E8) -> 315702 | F9: =SUM(F2:F8) -> 344163 | G9: =SUM(G2:G8) -> 327662 | H9: =SUM(H2:H8) -> 370350 | I9: =SUM(I2:I8) -> 341267 | ... M9: =SUM(M2:M8) -> 388267
A10: 零件pcs | B10: 2536614 | C10: 1445282 | D10: 1916054 | E10: 1898917 | F10: 2060248 | G10: 2025118 | H10: 2211194 | I10: 1962282 | J10: 1879324 | K10: 2087204 | L10: 2061187 | M10: 2312999
A11: 和勁pcs | B11: 146177 | C11: 72647 | D11: 120051 | E11: 107960 | F11: 128648 | G11: 152500 | H11: 146036 | I11: 80867 | J11: 110822 | K11: 85412 | L11: 140248 | M11: 132573
A12: 產機pcs
A13: 車美仕pcs | B13: 81135 | C13: 41945 | D13: 49580 | E13: 76305 | F13: 65954 | G13: 69793 | H13: 60954 | I13: 26574 | J13: 44215 | K13: 60060 | L13: 58843 | M13: 69373
A14: 和運pcs | B14: 8245 | C14: 4212 | D14: 9513 | E14: 5102 | F14: 7249 | G14: 6286 | H14: 7354 | I14: 7154 | J14: 5628 | K14: 7622 | L14: 7142 | M14: 7585
A15: 和運經銷商pcs | B15: 3216 | C15: 1899 | D15: 2655 | E15: 2092 | F15: 3983 | G15: 2776 | H15: 3989 | I15: 4303 | J15: 3435 | K15: 4350 | L15: 4033 | M15: 3827
A16: 湯淺pcs | B16: 10184 | C16: 7466 | D16: 6254 | E16: 4384 | F16: 6817 | G16: 7750 | H16: 7957 | I16: 8164 | J16: 10878 | K16: 9293 | L16: 11210 | M16: 9658
A17: 總合計pcs | B17: =SUM(B10:B16) -> 2785571 | C17: =SUM(C10:C16) -> 1573451 | D17: =SUM(D10:D16) -> 2104107 | E17: =SUM(E10:E16) -> 2094760 | F17: =SUM(F10:F16) -> 2272899 | G17: =SUM(G10:G16) -> 2264223 | H17: =SUM(H10:H16) -> 2437484 | I17: =SUM(I10:I16) -> 2089344 | ... M17: =SUM(M10:M16) -> 2536015
A19: 出貨點數
A20: 2020年 /月份 | B20: 1 | C20: 2 | D20: 3 | E20: 4 | F20: 5 | G20: 6 | H20: 7 | I20: 8 | J20: 9 | K20: 10 | L20: 11 | M20: 12 | N20: 平均 | O20: 合計
A21: 零件 i | B21: 295444 | C21: 319960 | D21: 334332 | E21: 290437 | F21: 301493 | G21: 309849 | H21: 362845 | I21: 343104 | J21: 350048 | K21: 322082 | L21: 333743 | M21: 372497 | N21: =AVERAGE(B21:M21) -> 327986.17 | O21: =SUM(B21:M21) -> 3935834
A22: 同期比 | B22: =B21/B2 -> 0.7555301 | C22: =C21/C2 -> 1.374074 | D22: =D21/D2 -> 1.0665212 | E22: =E21/E2 -> 0.98003732 | F22: =F21/F2 -> 0.94891777 | G22: =G21/G2 -> 1.0353078 | H22: =H21/H2 -> 1.0645017 | I22: =I21/I2 -> 1.0666037 | ... M22: =M21/M2 -> 1.0491927 | N22: =AVERAGE(B22:M22) -> 1.04662
A23: 和勁 i | B23: 7114 | C23: 7702 | D23: 9509 | E23: 7516 | F23: 10898 | G23: 16398 | H23: 18684 | I23: 11874 | J23: 10590 | K23: 8570 | L23: 15821 | M23: 18403 | N23: =AVERAGE(B23:M23) -> 11923.25 | O23: =SUM(B23:M23) -> 143079
A24: 同期比 | B24: =B23/B3 -> 0.3711975 | C24: =C23/C3 -> 1.4342644 | D24: =D23/D3 -> 1.3507102 | E24: =E23/E3 -> 0.92927794 | F24: =F23/F3 -> 0.76172503 | G24: =G23/G3 -> 1.0250031 | H24: =H23/H3 -> 1.0934629 | I24: =I23/I3 -> 1.2029176 | ... M24: =M23/M3 -> 0.9516496 | N24: =AVERAGE(B24:M24) -> 1.0334831
A25: 產機 i | B25: 1199 | C25: 1451 | D25: 1386 | E25: 1256 | F25: 1192 | G25: 1331 | H25: 1317 | I25: 1303 | J25: 1610 | K25: 1142 | L25: 1656 | M25: 1347 | N25: =AVERAGE(B25:M25) -> 1349.1667 | O25: =SUM(B25:M25) -> 16190
A26: 同期比 | B26: =B25/B4 -> 0.77806619 | C26: =C25/C4 -> 1.5857923 | D26: =D25/D4 -> 1.1815857 | E26: =E25/E4 -> 1.0536913 | F26: =F25/F4 -> 0.86754003 | G26: =G25/G4 -> 1.0571882 | H26: =H25/H4 -> 0.77561837 | I26: =I25/I4 -> 1.1005068 | ... M26: =M25/M4 -> 0.95329087 | N26: =AVERAGE(B26:M26) -> 1.0521963
A27: 車美仕 i | B27: 6171 | C27: 4671 | D27: 9604 | E27: 8302 | F27: 8656 | G27: 9635 | H27: 11710 | I27: 9005 | J27: 8641 | K27: 9010 | L27: 9324 | M27: 11470 | N27: =AVERAGE(B27:M27) -> 8849.9167 | O27: =SUM(B27:M27) -> 106199
A28: 同期比 | B28: =B27/B5 -> 0.66937846 | C28: =C27/C5 -> 0.82120253 | D28: =D27/D5 -> 1.4985177 | E28: =E27/E5 -> 1.1506584 | F28: =F27/F5 -> 1.3292383 | G28: =G27/G5 -> 1.3522807 | H28: =H27/H5 -> 1.8975855 | I28: =I27/I5 -> 2.3660011 | ... M28: =M27/M5 -> 1.5491626 | N28: =AVERAGE(B28:M28) -> 1.4262409
A29: 和運 i | B29: 670 | C29: 796 | D29: 831 | E29: 734 | F29: 877 | G29: 931 | H29: 817 | I29: 877 | J29: 975 | K29: 765 | L29: 994 | M29: 963 | N29: =AVERAGE(B29:M29) -> 852.5 | O29: =SUM(B29:M29) -> 10230
A30: 同期比 | B30: =B29/B6 -> 0.87353325 | C30: =C29/C6 -> 2.3550296 | D30: =D29/D6 -> 1.3826955 | E30: =E29/E6 -> 1.5291667 | F30: =F29/F6 -> 1.6768642 | G30: =G29/G6 -> 1.6247818 | H30: =H29/H6 -> 1.184058 | I30: =I29/I6 -> 1.3987241 | ... M30: =M29/M6 -> 1.1933086 | N30: =AVERAGE(B30:M30) -> 1.4613446
A31: 和運經銷商i | B31: 2238 | C31: 2831 | D31: 3697 | E31: 3273 | F31: 3579 | G31: 4099 | H31: 5499 | I31: 5051 | J31: 4846 | K31: 4478 | L31: 4797 | M31: 4674 | N31: =AVERAGE(B31:M31) -> 4088.5 | O31: =SUM(B31:M31) -> 49062
A32: 同期比 | B32: =B31/B8 -> 1.2565974 | C32: =C31/C8 -> 2.144697 | D32: =D31/D8 -> 3.0655058 | E32: =E31/E8 -> 3.6046256 | F32: =F31/F8 -> 2.4716851 | G32: =G31/G8 -> 2.5682957 | H32: =H31/H8 -> 3.3944444 | I32: =I31/I8 -> 3.0101311 | ... M32: =M31/M8 -> 2.5766262 | N32: =AVERAGE(B32:M32) -> 2.5986031
A33: 湯淺 i | B33: 1835 | C33: 1257 | D33: 1564 | E33: 1268 | F33: 1490 | G33: 1635 | H33: 1795 | I33: 2126 | J33: 1810 | K33: 1753 | L33: 2185 | M33: 2034 | N33: =AVERAGE(B33:M33) -> 1729.3333 | O33: =SUM(B33:M33) -> 20752
A34: 同期比 | B34: =B33/B8 -> 1.03032 | C34: =C33/C8 -> 0.95227273 | D34: =D33/D8 -> 1.2968491 | E34: =E33/E8 -> 1.3964758 | F34: =F33/F8 -> 1.0290055 | G34: =G33/G8 -> 1.0244361 | H34: =H33/H8 -> 1.1080247 | I34: =I33/I8 -> 1.2669845 | ... M34: =M33/M8 -> 1.1212789 | N34: =AVERAGE(B34:M34) -> 1.0924013
A35: 總合計i | B35: =B21+B23+B25+B27+B29+B33+B31 -> 314671 | C35: =C21+C23+C25+C27+C29+C33 -> 335837 | D35: =D21+D23+D25+D27+D29+D33 -> 357226 | E35: =E21+E23+E25+E27+E29+E33 -> 309513 | F35: =F21+F23+F25+F27+F29+F33 -> 324606 | G35: =G21+G23+G25+G27+G29+G33 -> 339779 | H35: =H21+H23+H25+H27+H29+H33 -> 397168 | I35: =I21+I23+I25+I27+I29+I33 -> 368289 | J35: =J21+J23+J25+J27+J29+J33 -> 373674 | ... M35: =M21+M23+M25+M27+M29+M33 -> 406714 | N35: =AVERAGEA(B35:M35) -> 352876.83 | O35: =SUM(B35:M35) -> 4234522
A36: 同期比 | B36: =B35/B9 -> 0.73954274 | C36: =C35/C9 -> 1.3562979 | D36: =D35/D9 -> 1.0772344 | E36: =E35/E9 -> 0.98039607 | F36: =F35/F9 -> 0.94317518 | G36: =G35/G9 -> 1.0369802 | H36: =H35/H9 -> 1.0724126 | I36: =I35/I9 -> 1.0791814 | ... M36: =M35/M9 -> 1.0475111 | N36: =AVERAGE(B36:M36) -> 1.0461951
A37: 出貨PCS
A38: 零件pcs | B38: 2064225 | C38: 1919724 | D38: 2387421 | E38: 1925057 | F38: 1938618 | G38: 1975146 | H38: 2125321 | I38: 2075304 | J38: 2188146 | K38: 2006021 | L38: 2079620 | M38: 2473506 | N38: =AVERAGE(B38:M38) -> 2096509.1 | O38: =SUM(B38:M38) -> 25158109
A39: 同期比 | B39: =B38/B10 -> 0.81377182 | C39: =C38/C10 -> 1.3282695 | D39: =D38/D10 -> 1.2460092 | E39: =E38/E10 -> 1.0137657 | F39: =F38/F10 -> 0.94096342 | G39: =G38/G10 -> 0.97532391 | H39: =H38/H10 -> 0.96116442 | I39: =I38/I10 -> 1.0575972 | ... M39: =M38/M10 -> 1.0693935 | N39: =AVERAGE(B39:M39) -> 1.0450527
A40: 和勁pcs | B40: 51983 | C40: 51792 | D40: 82775 | E40: 87977 | F40: 99436 | G40: 140113 | H40: 150989 | I40: 94844 | J40: 462884 | K40: 115534 | L40: 139413 | M40: 165648 | N40: =AVERAGE(B40:M40) -> 136949 | O40: =SUM(B40:M40) -> 1643388
A41: 同期比 | B41: =B40/B11 -> 0.35561682 | C41: =C40/C11 -> 0.71292689 | D41: =D40/D11 -> 0.68949863 | E41: =E40/E11 -> 0.81490367 | F41: =F40/F11 -> 0.77293079 | G41: =G40/G11 -> 0.91877377 | H41: =H40/H11 -> 1.0339163 | I41: =I40/I11 -> 1.1728394 | ... M41: =M40/M11 -> 1.2494852 | N41: =AVERAGE(B41:M41) -> 1.1870357
...

Sheet 進貨點數(同期比)
A1: 2014年/月份 | B1: 1 | C1: 2 | D1: 3 | E1: 4 | F1: 5 | G1: 6 | H1: 7 | I1: 8 | J1: 9 | K1: 10 | L1: 11 | M1: 12
A2: I | B2: =37193+18064 -> 55257 | C2: =39053+16010 -> 55063 | D2: =41877+17252 -> 59129 | E2: =49005+18465 -> 67470 | F2: =35381+19931 -> 55312 | G2: =43034+19334 -> 62368 | H2: =43142+21923 -> 65065 | I2: =40516+15967 -> 56483 | J2: =44979+17834 -> 62813 | K2: =47684+20511 -> 68195 | L2: =39861+20761 -> 60622 | M2: =31739+21067 -> 52806
A3: PCS | B3: =496198+198457 -> 694655 | C3: =464784+148811 -> 613595 | D3: =492728+140695 -> 633423 | E3: =600634+157025 -> 757659 | F3: =457343+162854 -> 620197 | G3: =476239+169969 -> 646208 | H3: =517338+207767 -> 725105 | I3: =508280+142743 -> 651023 | J3: =439066+152125 -> 591191 | K3: =544603+182309 -> 726912 | L3: =443648+182039 -> 625687 | M3: =400285+17790 -> 418075
A4: 2015年/月份 | B4: 1 | C4: 2 | D4: 3 | E4: 4 | F4: 5 | G4: 6 | H4: 7 | I4: 8 | J4: 9 | K4: 10 | L4: 11 | M4: 12
A5: I | B5: =52126+22640 -> 74766 | C5: =39381+14207 -> 53588 | D5: =50344+22291 -> 72635 | E5: =45585+16098 -> 61683 | F5: 63019 | G5: 65339 | H5: 66729 | I5: 63204 | J5: 71271 | K5: 73736 | L5: 77700 | M5: 85071
A6: PCS | B6: =713524+302113 -> 1015637 | C6: =488291+138526 -> 626817 | D6: =521735+201209 -> 722944 | E6: =525340+144803 -> 670143 | F6: 700918 | G6: 707373 | H6: 737207 | I6: 814051 | J6: 918387 | K6: 775117 | L6: 1011035 | M6: 1201112
A7: 2016年/月份 | B7: 1 | C7: 2 | D7: 3 | E7: 4 | F7: 5 | G7: 6 | H7: 7 | I7: 8 | J7: 9 | K7: 10 | L7: 11 | M7: 12
A8: I | B8: 76036 | C8: 68333 | D8: 77543 | E8: 76742 | F8: 73888 | G8: 86617 | H8: 78313 | I8: 71403 | J8: 74708 | K8: 75109 | L8: 85130 | M8: 71365
A9: PCS | B9: 1328744 | C9: 939329 | D9: 981633 | E9: 1697335 | F9: 1022205 | G9: 1222222 | H9: 1051536 | I9: 889176 | J9: 929383 | K9: 1010261 | L9: 1208417 | M9: 1085894
A10: 同期比I | B10: =B8/B5 -> 1.0169863 | C10: =C8/C5 -> 1.2751549 | D10: =D8/D5 -> 1.0675707 | E10: =E8/E5 -> 1.2441353 | F10: =F8/F5 -> 1.1724718 | G10: =G8/G5 -> 1.3256554 | H10: =H8/H5 -> 1.1735977 | I10: =I8/I5 -> 1.1297228 | ... M10: =M8/M5 -> 0.83888752
A11: 同期比PCS | B11: =B9/B6 -> 1.3082863 | C11: =C9/C6 -> 1.4985698 | D11: =D9/D6 -> 1.3578272 | E11: =E9/E6 -> 2.5327952 | F11: =F9/F6 -> 1.4583803 | G11: =G9/G6 -> 1.7278324 | H11: =H9/H6 -> 1.4263782 | I11: =I9/I6 -> 1.0922854 | ... M11: =M9/M6 -> 0.90407389
A12: 2017年/月份 | B12: 1 | C12: 2 | D12: 3 | E12: 4 | F12: 5 | G12: 6 | H12: 7 | I12: 8 | J12: 9 | K12: 10 | L12: 11 | M12: 12
A13: I | B13: 89260 | C13: 61216 | D13: 92239 | E13: 70746 | F13: 72166 | G13: 79384 | H13: 88473 | I13: 93010 | J13: 87130 | K13: 77013 | L13: 88355 | M13: 76531
A14: PCS | B14: 1700935 | C14: 721085 | D14: 1202153 | E14: 1060419 | F14: 1063603 | G14: 1049824 | H14: 1103519 | I14: 1293402 | J14: 1172627 | K14: 1258484 | L14: 1216748 | M14: 1305038
A15: 同期比I | B15: =B13/B8 -> 1.1739176 | C15: =C13/C8 -> 0.89584827 | D15: =D13/D8 -> 1.1895207 | E15: =E13/E8 -> 0.92186808 | F15: =F13/F8 -> 0.97669446 | G15: =G13/G8 -> 0.91649445 | H15: =H13/H8 -> 1.1297358 | I15: =I13/I8 -> 1.3026063 | ... M15: =M13/M8 -> 1.0723884
A16: 同期比PCS | B16: =B14/B9 -> 1.2801074 | C16: =C14/C9 -> 0.76765968 | D16: =D14/D9 -> 1.2246461 | E16: =E14/E9 -> 0.62475528 | F16: =F14/F9 -> 1.0404987 | G16: =G14/G9 -> 0.85894707 | H16: =H14/H9 -> 1.0494353 | I16: =I14/I9 -> 1.4546074 | ... M16: =M14/M9 -> 1.2018098
A17: 2018年/月份 | B17: 1 | C17: 2 | D17: 3 | E17: 4 | F17: 5 | G17: 6 | H17: 7 | I17: 8 | J17: 9 | K17: 10 | L17: 11 | M17: 12
A18: I | B18: 94094 | C18: 71263 | D18: 91234 | E18: 74564 | F18: 88863 | G18: 71852 | H18: 85218 | I18: 75614 | J18: 87968 | K18: 83882 | L18: 92459 | M18: 76749
A19: PCS | B19: 1624123 | C19: 1136798 | D19: 1242691 | E19: 1182218 | F19: 1238105 | G19: 1211910 | H19: 1334803 | I19: 1171190 | J19: 1227569 | K19: 1249781 | L19: 1423839 | M19: 1267604
A20: 同期比I | B20: =B18/B13 -> 1.0541564 | C20: =C18/C13 -> 1.1641238 | D20: =D18/D13 -> 0.98910439 | E20: =E18/E13 -> 1.0539677 | F20: =F18/F13 -> 1.2313693 | G20: =G18/G13 -> 0.90511942 | H20: =H18/H13 -> 0.96320911 | I20: =I18/I13 -> 0.81296635 | ... M20: =M18/M13 -> 1.0028485
A21: 同期比PCS | B21: =B19/B14 -> 0.95484131 | C21: =C19/C14 -> 1.5765104 | D21: =D19/D14 -> 1.0337212 | E21: =E19/E14 -> 1.1148593 | F21: =F19/F14 -> 1.1640669 | G21: =G19/G14 -> 1.1543935 | H21: =H19/H14 -> 1.2095877 | I21: =I19/I14 -> 0.9055112 | ... M21: =M19/M14 -> 0.97131578
A22: 2019年/月份 | B22: 1 | C22: 2 | D22: 3 | E22: 4 | F22: 5 | G22: 6 | H22: 7 | I22: 8 | J22: 9 | K22: 10 | L22: 11 | M22: 12
A23: I | B23: 94541 | C23: 64264 | D23: 72895 | E23: 76434 | F23: 78417 | G23: 76076 | H23: 91269 | I23: 83130 | J23: 68376 | K23: 100460 | L23: 91667 | M23: 101821
A24: PCS | B24: 1514697 | C24: 987327 | D24: 1129534 | E24: 1241515 | F24: 1218380 | G24: 1234140 | H24: 1438773 | I24: 1197334 | J24: 1000002 | K24: 1434620 | L24: 1314964 | M24: 1534817
A25: 同期比I | B25: =B18/B23 -> 0.99527189 | C25: =C18/C23 -> 1.1089101 | D25: =D18/D23 -> 1.251581 | E25: =E18/E23 -> 0.97553445 | F25: =F18/F23 -> 1.1332109 | G25: =G18/G23 -> 0.94447658 | H25: =H18/H23 -> 0.93370148 | I25: =I18/I23 -> 0.90958739 | J25: =J23/J18 -> 0.77728265 | K25: =K23/K18 -> 1.1976348 | L25: =L23/L18 -> 0.99143404 | M25: =M23/M18 -> 1.3266753
A26: 同期比PCS | B26: =B19/B24 -> 1.0722428 | C26: =C19/C24 -> 1.1513896 | D26: =D19/D24 -> 1.1001803 | E26: =E19/E24 -> 0.95223819 | F26: =F19/F24 -> 1.0161895 | G26: =G19/G24 -> 0.98198746 | H26: =H19/H24 -> 0.92773704 | I26: =I19/I24 -> 0.97816482 | J26: =J24/J19 -> 0.81461979 | K26: =K24/K19 -> 1.1478971 | L26: =L24/L19 -> 0.92353419 | M26: =M24/M19 -> 1.2108016
A27: 2020年/月份 | B27: 1 | C27: 2 | D27: 3 | E27: 4 | F27: 5 | G27: 6 | H27: 7 | I27: 8 | J27: 9 | K27: 10 | L27: 11 | M27: 12
A28: I | B28: 80912 | C28: 78908 | D28: 84677 | E28: 72364 | F28: 88404 | G28: 79028 | H28: 100239 | I28: 99641 | J28: 86113 | K28: 91062 | L28: 91609 | M28: 122534
A29: PCS | B29: 1284289 | C29: 1215417 | D29: 1473277 | E29: 1281620 | F29: 1564926 | G29: 1256306 | H29: 1295767 | I29: 1277472 | J29: 1300368 | K29: 1221525 | L29: 1488301 | M29: 1590219
A30: 同期比I | B30: =B23/B28 -> 1.1684423 | C30: =C23/C28 -> 0.81441679 | D30: =D23/D28 -> 0.8608595 | E30: =E23/E28 -> 1.0562434 | F30: =F23/F28 -> 0.88703 | G30: =G23/G28 -> 0.96264615 | H30: =H23/H28 -> 0.91051387 | I30: =I23/I28 -> 0.83429512 | J30: =J28/J23 -> 1.2594039 | K30: =K28/K23 -> 0.90645033 | L30: =L28/L23 -> 0.99936728 | M30: =M28/M23 -> 1.2034256
A31: 同期比PCS | B31: =B24/B29 -> 1.1794051 | C31: =C24/C29 -> 0.81233601 | D31: =D24/D29 -> 0.76668135 | E31: =E24/E29 -> 0.96870757 | F31: =F24/F29 -> 0.77855439 | G31: =G24/G29 -> 0.98235621 | H31: =H24/H29 -> 1.110364 | I31: =I24/I29 -> 0.93726829 | J31: =J29/J24 -> 1.3003654 | K31: =K29/K24 -> 0.85146241 | L31: =L29/L24 -> 1.1318188 | M31: =M29/M24 -> 1.0360968
A32: 2021年/月份 | B32: 1 | C32: 2 | D32: 3 | E32: 4 | F32: 5 | G32: 6 | H32: 7 | I32: 8 | J32: 9 | K32: 10 | L32: 11 | M32: 12
A33: I | B33: 109087 | C33: 63617 | D33: 90797 | E33: 71472 | F33: 84403 | G33: 82486 | H33: 77347 | I33: 65823 | J33: 76526 | K33: 83320 | L33: 91781 | M33: 101214
A34: PCS | B34: 1590835 | C34: 1178970 | D34: 1516056 | E34: 1147688 | F34: 1412349 | G34: 1461802 | H34: 1284185 | I34: 1218066 | J34: 1352983 | K34: 1236302 | L34: 1447962 | M34: 1553156
A35: 同期比I | B35: =B33/B28 -> 1.3482178 | C35: =C28/C33 -> 1.2403603 | D35: =D28/D33 -> 0.93259689 | E35: =E28/E33 -> 1.0124804 | F35: =F28/F33 -> 1.0474035 | G35: =G28/G33 -> 0.95807773 | H35: =H28/H33 -> 1.2959649 | I35: =I28/I33 -> 1.5137718 | J35: =J33/J28 -> 0.88866954 | K35: =K33/K28 -> 0.914981 | L35: =L33/L28 -> 1.0018775 | M35: =M33/M28 -> 0.82600748
A36: 同期比PCS | B36: =B34/B29 -> 1.2386893 | C36: =C29/C34 -> 1.0309143 | D36: =D29/D34 -> 0.9717827 | E36: =E29/E34 -> 1.1166972 | F36: =F29/F34 -> 1.1080307 | G36: =G29/G34 -> 0.85942282 | H36: =H29/H34 -> 1.0090189 | I36: =I29/I34 -> 1.0487708 | J36: =J34/J29 -> 1.0404616 | K36: =K34/K29 -> 1.0120972 | L36: =L34/L29 -> 0.97289594 | M36: =M34/M29 -> 0.97669315
A37: 2022年/月份 | B37: 1 | C37: 2 | D37: 3 | E37: 4 | F37: 5 | G37: 6 | H37: 7 | I37: 8 | J37: 9 | K37: 10 | L37: 11 | M37: 12
A38: I | B38: 103232 | C38: 63927 | D38: 112851 | E38: 83070 | F38: 88988 | G38: 91796 | H38: 88671 | I38: 95742 | J38: 97444 | K38: 96411 | L38: 101583 | M38: 110262
A39: PCS | B39: 1491074 | C39: 922904 | D39: 1789012 | E39: 1277563 | F39: 1340509 | G39: 1294899 | H39: 1332450 | I39: 1486450 | J39: 1444923 | K39: 1390571 | L39: 1445203 | M39: 2001133
A40: 同期比I | B40: =B38/B33 -> 0.94632724 | C40: =C33/C38 -> 0.99515072 | D40: =D33/D38 -> 0.80457417 | E40: =E33/E38 -> 0.86038281 | F40: =F33/F38 -> 0.9484762 | G40: =G33/G38 -> 0.89857946 | H40: =H33/H38 -> 0.87229196 | I40: =I33/I38 -> 0.68750392 | J40: =J38/J33 -> 1.273345 | K40: =K38/K33 -> 1.1571171 | L40: =L38/L33 -> 1.1067977 | M40: =M38/M33 -> 1.0893947
...

Sheet 庫位使用率
A2: 2015年10月 ~ 2015年12月 楊 梅 倉 庫 各 零 件 保 管 庫 區 使 用 狀 況
AF3: 2016/01/06 | AH3: 製表.
A4: 管 理 別 | C4: 中 小 物 庫 區 ( 材 敏 ) | P4: 大 物 庫 區 ( 和 泰 ) | Z4: 小 計 | AA4: 庫 區 保 管 狀 況 | AG4: 合 計 | AH4: 新 卡 | AI4: 空庫位 取消 | AJ4: 不適當 遷移
A5: 區 域 別 | C5: 積 層 庫 區 | L5: 專 區 | P5: 小 計 | Q5: 高 層 架 庫 區 | W5: 專 區 | AB5: 小 計 | AC5: 合 計 | AD5: ▲ | AE5: ◎ | AF5: ▽ | AG5: 小 計 | AK5: 合 計
A6: 庫 區 | C6: A | D6: B | E6: C | F6: D | G6: E | H6: P | I6: T | J6: U | K6: 4 | L6: R | M6: S | N6: J | O6: W | Q6: F | R6: N | S6: G | T6: H | U6: M、Q | V6: L | W6: K | X6: V | Y6: Y | Z6: Z | AD6: 過高 >85% | AE6: 正常 75~85% | AF6: 過低 <75%
A7: 保管類別 | C7: 高 銷 中 物 | D7: 高 銷 中小物 | E7: 低 銷 中量物 | F7: 低 銷 中小物 | G7: 暢 銷 量物區 | H7: 低、滯 銷區 | I7: 中 銷 量物區 | J7: 低銷區 | K7: 低銷區 | L7: 精品區 | M7: 高價 品區 | N7: 精品區 | O7: CAPS 庫區 | Q7: 高中銷 大 物 | R7: 中低銷 大 物 | S7: 高中銷 大中物 | T7: 金屬區 | U7: 低、滯 銷區 | V7: 玻璃 庫區 | W7: 電、化 品區 | X7: 保桿區 | Y7: 輪胎區 | Z7: 油品區
A8: 2019年 1月 | B8: 點數(i) | C8: 8475 | D8: 33496 | E8: 4532 | F8: 15143 | G8: 1101 | H8: 1474 | I8: 1129 | L8: 671 | M8: 680 | N8: 809 | P8: =SUM(C8:N8) -> 67510 | Q8: 1131 | R8: 2287 | S8: 1586 | T8: 3417 | U8: 1505 | W8: 212 | X8: 619 | Y8: 148 | Z8: 91 | AB8: =SUM(Q8:AA8) -> 10996 | AC8: =P8+AB8 -> 78506 | AD8: 8 | AE8: 5 | AF8: 6 | AG8: =SUM(AD8:AF8) -> 19 | AH8: 2088 | AI8: 2047 | AJ8: 1694 | AK8: =SUM(AH8:AJ11) -> 5829
B9: 配置數 | C9: 9177 | D9: 37584 | E9: 4987 | F9: 21366 | G9: 1555 | H9: 1662 | I9: 1470 | L9: 1097 | M9: 876 | N9: 1147 | P9: =SUM(C9:N9) -> 80921 | Q9: 1275 | R9: 3018 | S9: 1929 | T9: 3623 | U9: 3538 | W9: 250 | X9: 661 | Y9: 160 | Z9: 164 | AB9: =SUM(Q9:AA9) -> 14618 | AC9: =P9+AB9 -> 95539
B10: 使用率 | C10: =C8/C9 -> 0.92350441 | D10: =D8/D9 -> 0.89123031 | E10: =E8/E9 -> 0.90876278 | F10: =F8/F9 -> 0.70874286 | G10: =G8/G9 -> 0.70803859 | H10: =H8/H9 -> 0.88688327 | I10: =I8/I9 -> 0.76802721 | L10: =L8/L9 -> 0.61166819 | M10: =M8/M9 -> 0.77625571 | N10: =N8/N9 -> 0.70531822 | P10: =P8/P9 -> 0.83427046 | Q10: =Q8/Q9 -> 0.88705882 | R10: =R8/R9 -> 0.75778661 | S10: =S8/S9 -> 0.82218766 | T10: =T8/T9 -> 0.94314104 | U10: =U8/U9 -> 0.42538157 | W10: =W8/W9 -> 0.848 | X10: =X8/X9 -> 0.93645991 | Y10: =Y8/Y9 -> 0.925 | Z10: =Z8/Z9 -> 0.55487805 | AB10: =AB8/AB9 -> 0.75222329 | AC10: =AC8/AC9 -> 0.82171679 | AD10: =AD8/$AG$253 -> #DIV/0! | AE10: =AE8/$AG$253 -> #DIV/0! | AF10: =AF8/$AG$253 -> #DIV/0! | AG10: =AG8/$AG$253 -> #DIV/0!
B11: 狀 況 | C11: ▲ | D11: ▲ | E11: ▲ | F11: ▽ | G11: ▽ | H11: ▲ | I11: ◎ | L11: ▽ | M11: ◎ | N11: ▽ | Q11: ▲ | R11: ◎ | S11: ◎ | T11: ▲ | U11: ▽ | W11: ◎ | X11: ▲ | Y11: ▲ | Z11: ▽
A12: 2019年 2月 | B12: 點數(i) | C12: 8351 | D12: 32966 | E12: 4473 | F12: 14972 | G12: 1147 | H12: 1455 | I12: 1142 | L12: 672 | M12: 683 | N12: 809 | P12: =SUM(C12:N12) -> 66670 | Q12: 1080 | R12: 2410 | S12: 1698 | T12: 3419 | U12: 1482 | V12: 61 | W12: 213 | X12: 629 | Y12: 148 | Z12: 91 | AB12: =SUM(Q12:AA12) -> 11231 | AC12: =P12+AB12 -> 77901 | AD12: 8 | AE12: 4 | AF12: 8 | AG12: =SUM(AD12:AF12) -> 20 | AH12: 1449 | AI12: 2169 | AJ12: 684 | AK12: =SUM(AH12:AJ16) -> 4302
B13: 配置數 | C13: 9177 | D13: 37584 | E13: 4987 | F13: 21366 | G13: 1555 | H13: 2770 | I13: 1470 | L13: 1097 | M13: 876 | N13: 1147 | P13: =SUM(C13:N13) -> 82029 | Q13: 1275 | R13: 3018 | S13: 1929 | T13: 3623 | U13: 3538 | V13: 102 | W13: 250 | X13: 661 | Y13: 160 | Z13: 164 | AB13: =SUM(Q13:AA13) -> 14720 | AC13: =P13+AB13 -> 96749
B14: 合計點數 | C14: =C12+D12+E12+F12 -> 60762 | G14: =G12+H12+I12 -> 3744 | L14: =L12+M12+N12 -> 2164 | Q14: =Q12+R12+S12 -> 5188
B15: 合計配置數 | C15: =C13+D13+E13+F13 -> 73114 | G15: =G13+H13+I13 -> 5795 | L15: =L13+M13+N13 -> 3120 | Q15: =Q13+R13+S13 -> 6222
B16: 使用率 | C16: =C14/C15 -> 0.83105835 | G16: =G14/G15 -> 0.6460742 | L16: =L14/L15 -> 0.69358974 | P16: =P12/P13 -> 0.81276134 | Q16: =Q14/Q15 -> 0.83381549 | T16: =T12/T13 -> 0.94369307 | U16: =U12/U13 -> 0.41888072 | V16: =V12/V13 -> 0.59803922 | W16: =W12/W13 -> 0.852 | X16: =X12/X13 -> 0.9515885 | Y16: =Y12/Y13 -> 0.925 | Z16: =Z12/Z13 -> 0.55487805 | AB16: =AB12/AB13 -> 0.76297554 | AC16: =AC12/AC13 -> 0.80518662 | AD16: =AD12/$AG$257 -> 0.38095238 | AE16: =AE12/$AG$257 -> 0.19047619 | AF16: =AF12/$AG$257 -> 0.38095238 | AG16: =AG12/$AG$257 -> 0.95238095
A17: 2019年 3月 | B17: 點數(i) | C17: 8330 | D17: 33302 | E17: 4494 | F17: 14975 | G17: 1307 | H17: 1438 | I17: 1197 | L17: 681 | M17: 664 | N17: 809 | P17: =SUM(C17:N17) -> 67197 | Q17: 1146 | R17: 2557 | S17: 1565 | T17: 3300 | U17: 1544 | V17: 61 | W17: 217 | X17: 615 | Y17: 148 | Z17: 92 | AB17: =SUM(Q17:AA17) -> 11245 | AC17: =P17+AB17 -> 78442 | AD17: 8 | AE17: 5 | AF17: 7 | AG17: =SUM(AD17:AF17) -> 20 | AH17: 2130 | AI17: 1564 | AJ17: 1167 | AK17: =SUM(AH17:AJ21) -> 4861
B18: 配置數 | C18: 9177 | D18: 37584 | E18: 4987 | F18: 21366 | G18: 1555 | H18: 2770 | I18: 1470 | L18: 1097 | M18: 876 | N18: 1147 | P18: =SUM(C18:N18) -> 82029 | Q18: 1275 | R18: 3018 | S18: 1929 | T18: 3623 | U18: 3538 | V18: 102 | W18: 250 | X18: 661 | Y18: 160 | Z18: 164 | AB18: =SUM(Q18:AA18) -> 14720 | AC18: =P18+AB18 -> 96749
B19: 合計點數 | C19: =C17+D17+E17+F17 -> 61101 | G19: =G17+H17+I17 -> 3942 | L19: =L17+M17+N17 -> 2154 | Q19: =Q17+R17+S17 -> 5268
B20: 合計配置數 | C20: =C18+D18+E18+F18 -> 73114 | G20: =G18+H18+I18 -> 5795 | L20: =L18+M18+N18 -> 3120 | Q20: =Q18+R18+S18 -> 6222
B21: 使用率 | C21: =C19/C20 -> 0.83569494 | G21: =G19/G20 -> 0.68024159 | L21: =L19/L20 -> 0.69038462 | P21: =P17/P18 -> 0.8191859 | Q21: =Q19/Q20 -> 0.8466731 | T21: =T17/T18 -> 0.91084736 | U21: =U17/U18 -> 0.43640475 | V21: =V17/V18 -> 0.59803922 | W21: =W17/W18 -> 0.868 | X21: =X17/X18 -> 0.93040847 | Y21: =Y17/Y18 -> 0.925 | Z21: =Z17/Z18 -> 0.56097561 | AB21: =AB17/AB18 -> 0.76392663 | AC21: =AC17/AC18 -> 0.81077841 | AD21: =AD17/$AG$259 -> #DIV/0! | AE21: =AE17/$AG$259 -> #DIV/0! | AF21: =AF17/$AG$259 -> #DIV/0! | AG21: =AG17/$AG$259 -> #DIV/0!
A22: 2019年 4月 | B22: 點數(i) | C22: 8315 | D22: 33127 | E22: 4324 | F22: 15112 | G22: 1367 | H22: 1419 | I22: 1236 | L22: 710 | M22: 661 | N22: 810 | P22: =SUM(C22:N22) -> 67081 | Q22: 1163 | R22: 2572 | S22: 1483 | T22: 3033 | U22: 1896 | V22: 56 | W22: 223 | X22: 547 | Y22: 151 | Z22: 94 | AB22: =SUM(Q22:AA22) -> 11218 | AC22: =P22+AB22 -> 78299 | AD22: 6 | AE22: 6 | AF22: 8 | AG22: =SUM(AD22:AF22) -> 20 | AH22: 2329 | AI22: 2669 | AJ22: 2427 | AK22: =SUM(AH22:AJ26) -> 7425
B23: 配置數 | C23: 9252 | D23: 37456 | E23: 4874 | F23: 21619 | G23: 1602 | H23: 2770 | I23: 1470 | L23: 1097 | M23: 876 | N23: 1147 | P23: =SUM(C23:N23) -> 82163 | Q23: 1293 | R23: 3018 | S23: 2128 | T23: 3623 | U23: 3538 | V23: 102 | W23: 250 | X23: 661 | Y23: 160 | Z23: 164 | AB23: =SUM(Q23:AA23) -> 14937 | AC23: =P23+AB23 -> 97100
B24: 合計點數 | C24: =C22+D22+E22+F22 -> 60878 | G24: =G22+H22+I22 -> 4022 | L24: =L22+M22+N22 -> 2181 | Q24: =Q22+R22+S22 -> 5218
B25: 合計配置數 | C25: =C23+D23+E23+F23 -> 73201 | G25: =G23+H23+I23 -> 5842 | L25: =L23+M23+N23 -> 3120 | Q25: =Q23+R23+S23 -> 6439
B26: 使用率 | C26: =C24/C25 -> 0.83165531 | G26: =G24/G25 -> 0.68846286 | L26: =L24/L25 -> 0.69903846 | P26: =P22/P23 -> 0.81643806 | Q26: =Q24/Q25 -> 0.81037428 | T26: =T22/T23 -> 0.83715153 | U26: =U22/U23 -> 0.53589599 | V26: =V22/V23 -> 0.54901961 | W26: =W22/W23 -> 0.892 | X26: =X22/X23 -> 0.82753404 | Y26: =Y22/Y23 -> 0.94375 | Z26: =Z22/Z23 -> 0.57317073 | AB26: =AB22/AB23 -> 0.75102095 | AC26: =AC22/AC23 -> 0.80637487 | AD26: =AD22/$AG$258 -> #DIV/0! | AE26: =AE22/$AG$258 -> #DIV/0! | AF26: =AF22/$AG$258 -> #DIV/0! | AG26: =AG22/$AG$258 -> #DIV/0!
A27: 2019年 5月 | B27: 點數(i) | C27: 8427 | D27: 32538 | E27: 4351 | F27: 16557 | G27: 1416 | H27: 1411 | I27: 1245 | L27: 709 | M27: 654 | N27: 811 | P27: =SUM(C27:N27) -> 68119 | Q27: 1097 | R27: 2894 | S27: 1618 | T27: 2722 | U27: 1877 | V27: 20 | W27: 222 | X27: 552 | Y27: 152 | Z27: 94 | AB27: =SUM(Q27:AA27) -> 11248 | AC27: =P27+AB27 -> 79367 | AD27: 7 | AE27: 5 | AF27: 8 | AG27: =SUM(AD27:AF27) -> 20 | AH27: 2210 | AI27: 1037 | AJ27: 2807 | AK27: =SUM(AH27:AJ31) -> 6054
B28: 配置數 | C28: 9252 | D28: 37456 | E28: 4874 | F28: 21619 | G28: 1602 | H28: 2770 | I28: 1470 | L28: 1097 | M28: 876 | N28: 1147 | P28: =SUM(C28:N28) -> 82163 | Q28: 1293 | R28: 3018 | S28: 2128 | T28: 3623 | U28: 3538 | V28: 102 | W28: 250 | X28: 852 | Y28: 192 | Z28: 164 | AB28: =SUM(Q28:AA28) -> 15160 | AC28: =P28+AB28 -> 97323
B29: 合計點數 | C29: =C27+D27+E27+F27 -> 61873 | G29: =G27+H27+I27 -> 4072 | L29: =L27+M27+N27 -> 2174 | Q29: =Q27+R27+S27 -> 5609
B30: 合計配置數 | C30: =C28+D28+E28+F28 -> 73201 | G30: =G28+H28+I28 -> 5842 | L30: =L28+M28+N28 -> 3120 | Q30: =Q28+R28+S28 -> 6439
B31: 使用率 | C31: =C29/C30 -> 0.84524802 | G31: =G29/G30 -> 0.69702157 | L31: =L29/L30 -> 0.69679487 | P31: =P27/P28 -> 0.82907148 | Q31: =Q29/Q30 -> 0.871098 | T31: =T27/T28 -> 0.75131107 | U31: =U27/U28 -> 0.53052572 | V31: =V27/V28 -> 0.19607843 | W31: =W27/W28 -> 0.888 | X31: =X27/X28 -> 0.64788732 | Y31: =Y27/Y28 -> 0.79166667 | Z31: =Z27/Z28 -> 0.57317073 | AB31: =AB27/AB28 -> 0.74195251 | AC31: =AC27/AC28 -> 0.81550096 | AD31: =AD27/$AG$257 -> 0.33333333 | AE31: =AE27/$AG$257 -> 0.23809524 | AF31: =AF27/$AG$257 -> 0.38095238 | AG31: =AG27/$AG$257 -> 0.95238095
A32: 2019年 6月 | B32: 點數(i) | C32: 8251 | D32: 32556 | E32: 4394 | F32: 16138 | G32: 1457 | H32: 1249 | I32: 1231 | L32: 704 | M32: 649 | N32: 811 | P32: =SUM(C32:N32) -> 67440 | Q32: 1147 | R32: 2828 | S32: 1890 | T32: 2510 | U32: 1714 | V32: 20 | W32: 215 | X32: 577 | Y32: 152 | Z32: 94 | AB32: =SUM(Q32:AA32) -> 11147 | AC32: =P32+AB32 -> 78587 | AD32: 7 | AE32: 4 | AF32: 9 | AG32: =SUM(AD32:AF32) -> 20 | AH32: 1867 | AI32: 2463 | AJ32: 1635 | AK32: =SUM(AH32:AJ36) -> 5965
B33: 配置數 | C33: 9252 | D33: 37456 | E33: 4874 | F33: 21619 | G33: 1602 | H33: 2770 | I33: 1470 | L33: 1097 | M33: 876 | N33: 1147 | P33: =SUM(C33:N33) -> 82163 | Q33: 1293 | R33: 3018 | S33: 2073 | T33: 3623 | U33: 3538 | V33: 102 | W33: 266 | X33: 852 | Y33: 192 | Z33: 164 | AB33: =SUM(Q33:AA33) -> 15121 | AC33: =P33+AB33 -> 97284
B34: 合計點數 | C34: =C32+D32+E32+F32 -> 61339 | G34: =G32+H32+I32 -> 3937 | L34: =L32+M32+N32 -> 2164 | Q34: =Q32+R32+S32 -> 5865
B35: 合計配置數 | C35: =C33+D33+E33+F33 -> 73201 | G35: =G33+H33+I33 -> 5842 | L35: =L33+M33+N33 -> 3120 | Q35: =Q33+R33+S33 -> 6384
B36: 使用率 | C36: =C34/C35 -> 0.83795303 | G36: =G34/G35 -> 0.67391304 | L36: =L34/L35 -> 0.69358974 | P36: =P32/P33 -> 0.82080742 | Q36: =Q34/Q35 -> 0.91870301 | T36: =T32/T33 -> 0.69279603 | U36: =U32/U33 -> 0.48445449 | V36: =V32/V33 -> 0.19607843 | W36: =W32/W33 -> 0.80827068 | X36: =X32/X33 -> 0.67723005 | Y36: =Y32/Y33 -> 0.79166667 | Z36: =Z32/Z33 -> 0.57317073 | AB36: =AB32/AB33 -> 0.73718669 | AC36: =AC32/AC33 -> 0.80781012 | AD36: =AD32/$AG$256 -> 7 | AE36: =AE32/$AG$256 -> 4 | AF36: =AF32/$AG$256 -> 9 | AG36: =AG32/$AG$256 -> 20
A37: 2019年 7月 | B37: 點數(i) | C37: 8310 | D37: 32795 | E37: 4413 | F37: 16362 | G37: 1472 | H37: 1263 | I37: 1272 | L37: 653 | M37: 646 | N37: 811 | P37: =SUM(C37:N37) -> 67997 | Q37: 1096 | R37: 2934 | S37: 1887 | T37: 2508 | U37: 1724 | V37: 64 | W37: 217 | X37: 578 | Y37: 146 | Z37: 98 | AB37: =SUM(Q37:AA37) -> 11252 | AC37: =P37+AB37 -> 79249 | AD37: 8 | AE37: 3 | AF37: 9 | AG37: =SUM(AD37:AF37) -> 20 | AH37: 2128 | AI37: 1747 | AJ37: 1822 | AK37: =SUM(AH37:AJ41) -> 5697
B38: 配置數 | C38: 9252 | D38: 37456 | E38: 4675 | F38: 21619 | G38: 1602 | H38: 2770 | I38: 1470 | L38: 1097 | M38: 876 | N38: 1147 | P38: =SUM(C38:N38) -> 81964 | Q38: 1233 | R38: 3018 | S38: 2081 | T38: 3623 | U38: 3538 | V38: 102 | W38: 266 | X38: 852 | Y38: 192 | Z38: 164 | AB38: =SUM(Q38:AA38) -> 15069 | AC38: =P38+AB38 -> 97033
B39: 合計點數 | C39: =C37+D37+E37+F37 -> 61880 | G39: =G37+H37+I37 -> 4007 | L39: =L37+M37+N37 -> 2110 | Q39: =Q37+R37+S37 -> 5917
B40: 合計配置數 | C40: =C38+D38+E38+F38 -> 73002 | G40: =G38+H38+I38 -> 5842 | L40: =L38+M38+N38 -> 3120 | Q40: =Q38+R38+S38 -> 6332
B41: 使用率 | C41: =C39/C40 -> 0.84764801 | G41: =G39/G40 -> 0.68589524 | L41: =L39/L40 -> 0.67628205 | P41: =P37/P38 -> 0.82959592 | Q41: =Q39/Q40 -> 0.93445989 | T41: =T37/T38 -> 0.692244 | U41: =U37/U38 -> 0.48728095 | V41: =V37/V38 -> 0.62745098 | W41: =W37/W38 -> 0.81578947 | X41: =X37/X38 -> 0.67840376 | Y41: =Y37/Y38 -> 0.76041667 | Z41: =Z37/Z38 -> 0.59756098 | AB41: =AB37/AB38 -> 0.74669852 | AC41: =AC37/AC38 -> 0.81672215 | AD41: =AD37/$AG$255 -> #DIV/0! | AE41: =AE37/$AG$255 -> #DIV/0! | AF41: =AF37/$AG$255 -> #DIV/0! | AG41: =AG37/$AG$255 -> #DIV/0!
...

Sheet 庫位使用率 (202608變更)
A2: 2015年10月 ~ 2015年12月 楊 梅 倉 庫 各 零 件 保 管 庫 區 使 用 狀 況
AG3: 2016/01/06 | AI3: 製表.
A4: 管 理 別 | C4: 中 小 物 庫 區 ( 材 敏 ) | P4: 大 物 庫 區 ( 和 泰 ) | AA4: 小 計 | AB4: 庫 區 保 管 狀 況 | AH4: 合 計 | AI4: 新 卡 | AJ4: 空庫位 取消 | AK4: 不適當 遷移
A5: 區 域 別 | C5: 積 層 庫 區 | J5: 專 區 | M5: 小 計 | N5: 高 層 架 庫 區 | U5: 專 區 | Y5: 小 計 | Z5: 三倉 | AC5: 小 計 | AD5: 合 計 | AE5: ▲ | AF5: ◎ | AG5: ▽ | AH5: 小 計 | AI5: 新卡 | AJ5: 空庫位取消 | AK5: 不適當遷移 | AL5: 合 計
A6: 庫 區 | C6: A | D6: B | E6: D | F6: E | G6: P | H6: T | I6: U | J6: R | K6: S | L6: J | N6: F | O6: N | P6: G | Q6: H | R6: I | S6: M、Q | T6: L | U6: K | V6: V | W6: Y | X6: Z | Z6: 2 | AA6: 3 | AB6: 4 | AE6: 過高 >85% | AF6: 正常 75~85% | AG6: 過低 <75%
A7: 保管類別 | C7: 高 銷 中 物 | D7: 高 銷 中小物 | E7: 低 銷 中小物 | F7: 暢 銷 量物區 | G7: 低、滯 銷區 | H7: 中 銷 量物區 | I7: 低銷區 | J7: 精品區 | K7: 高價 品區 | L7: 精品區 | N7: 高中銷 大 物 | O7: 中低銷 大 物 | P7: 高中銷 大中物 | Q7: 金屬區 | R7: 大鈑金件 | S7: 低、滯 銷區 | T7: 玻璃 庫區 | U7: 電、化 品區 | V7: 保桿區 | W7: 輪胎區 | X7: 油品區 | Z7: 2F | AA7: 3F | AB7: 4F
A8: 2026年 8月 | B8: 點數 (i) | C8: 3802 | D8: 1199 | E8: 752 | F8: 1319 | G8: 4236 | H8: 2058 | I8: 1552 | J8: 365 | K8: 337 | L8: 1496 | M8: =SUM(C8:L8) -> 17116 | N8: 1169 | O8: 2510 | P8: 1976 | Q8: 2990 | R8: 79 | S8: 2378 | T8: 792 | U8: 338 | V8: 784 | W8: 238 | X8: 130 | Y8: =SUM(N8:X8) -> 13384 | Z8: 13518 | AA8: 16923 | AB8: 33901 | AC8: =SUM(Z8:AB8) -> 64342 | AD8: =M8+Y8+AC8 -> 94842 | AE8: 12 | AF8: 7 | AG8: 5 | AH8: =SUM(AE8:AG8) -> 24 | AI8: 1949 | AJ8: 2901 | AK8: 2600 | AL8: =SUM(AI8:AK13) -> 7450
B9: 延伸庫位 | C9: 17.109 | D9: 5.3955 | E9: 3.384 | F9: 0 | G9: 0 | H9: 0 | I9: 0 | J9: 259 | K9: 1.5165 | L9: 6.732 | M9: =SUM(C9:L9) -> 293.137 | N9: 32.69 | O9: 0 | P9: 0 | Q9: 29.9 | S9: 0 | T9: 0 | U9: 0 | V9: 156.8 | W9: 0 | X9: 0 | Y9: =SUM(N9:X9) -> 219.39 | Z9: 0 | AA9: 0 | AB9: 0 | AC9: =SUM(Z9:AB9) -> 0 | AD9: =M9+Y9+AC9 -> 512.527
B10: 配置數 | C10: 4541 | D10: 1601 | E10: 913 | F10: 1710 | G10: 4268 | H10: 2553 | I10: 1576 | J10: 624 | K10: 470 | L10: 2470 | M10: =SUM(C10:L10) -> 20726 | N10: 1403 | O10: 2766 | P10: 2020 | Q10: 3192 | R10: 81 | S10: 2378 | T10: 859 | U10: 338 | V10: 990 | W10: 252 | X10: 164 | Y10: =SUM(N10:X10) -> 14443 | Z10: 44786 | AA10: 25216 | AB10: 52576 | AC10: =SUM(Z10:AB10) -> 122578 | AD10: =M10+Y10+AC10 -> 157747
B11: 合計點數 | C11: =C8+D8+E8+C9+D9+E9 -> 5778.8885 | F11: =F8+G8+H8+I8+F9+G9+H9+I9 -> 9165 | J11: =J8+K8+L8+J9+K9+L9 -> 2465.2485 | N11: =N8+O8+P8+N9+O9+P9 -> 5687.69 | Z11: =Z8+AA8+AB8+Z9+AA9+AB9 -> 64342
B12: 合計配置數 | C12: =C10+D10+E10 -> 7055 | F12: =F10+G10+H10+I10 -> 10107 | J12: =J10+K10+L10 -> 3564 | N12: =N10+O10+P10 -> 6189 | Z12: =Z10+AA10+AB10 -> 122578
B13: 使用率 | C13: =C11/C12 -> 0.81911956 | F13: =F11/F12 -> 0.90679727 | J13: =J11/J12 -> 0.69170833 | M13: =(M8+M9)/M10 -> 0.83996608 | N13: =N11/N12 -> 0.91899984 | Q13: =(Q8+Q9)/Q10 -> 0.94608396 | R13: =(R8+R9)/R10 -> 0.97530864 | S13: =(S8+S9)/S10 -> 1 | T13: =(T8+T9)/T10 -> 0.92200233 | U13: =(U8+U9)/U10 -> 1 | V13: =(V8+V9)/V10 -> 0.95030303 | W13: =(W8+W9)/W10 -> 0.94444444 | X13: =(X8+X9)/X10 -> 0.79268293 | Y13: =(Y8+Y9)/Y10 -> 0.94186734 | Z13: =Z11/Z12 -> 0.52490659 | AC13: =(AC8+AC9)/AC10 -> 0.52490659 | AD13: =(AD8+AD9)/AD10 -> 0.60447759 | AE13: =AE8/AH8 -> 0.5 | AF13: =AF8/AH8 -> 0.29166667 | AG13: =AG8/AH8 -> 0.20833333 | AH13: =SUM(AE13:AG13) -> 1
A14: 2026年 9月 | B14: 點數 (i) | C14: 3858 | D14: 1184 | E14: 749 | F14: 1356 | G14: 4234 | H14: 2058 | I14: 1544 | J14: 577 | K14: 343 | L14: 1501 | M14: =SUM(C14:L14) -> 17404 | N14: 1166 | O14: 2502 | P14: 1981 | Q14: 2910 | R14: 79 | S14: 2378 | T14: 790 | U14: 338 | V14: 785 | W14: 240 | X14: 130 | Y14: =SUM(N14:X14) -> 13299 | Z14: 16141 | AA14: 16923 | AB14: 31665 | AC14: =SUM(Z14:AB14) -> 64729 | AD14: =M14+Y14+AC14 -> 95432 | AE14: 12 | AF14: 6 | AG14: 6 | AH14: =SUM(AE14:AG14) -> 24 | AI14: 1960 | AJ14: 2045 | AK14: 3283 | AL14: =SUM(AI14:AK19) -> 7288
B15: 延伸庫位 | C15: 17.361 | D15: 5.328 | E15: 3.3705 | F15: 0 | G15: 0 | H15: 0 | I15: 0 | J15: 47 | K15: 1.5435 | L15: 6.7545 | M15: =SUM(C15:L15) -> 81.3575 | N15: 32.66 | O15: 0 | P15: 0 | Q15: 29.1 | R15: 0 | S15: 0 | T15: 0 | U15: 0 | V15: 157 | W15: 0 | X15: 0 | Y15: =SUM(N15:X15) -> 218.76 | Z15: 0 | AA15: 0 | AB15: 0 | AC15: =SUM(Z15:AB15) -> 0 | AD15: =M15+Y15+AC15 -> 300.1175
B16: 配置數 | C16: 4541 | D16: 1601 | E16: 913 | F16: 1710 | G16: 4268 | H16: 2553 | I16: 1576 | J16: 624 | K16: 470 | L16: 2470 | M16: =SUM(C16:L16) -> 20726 | N16: 1403 | O16: 2766 | P16: 2020 | Q16: 3192 | R16: 81 | S16: 2378 | T16: 859 | U16: 338 | V16: 990 | W16: 252 | X16: 164 | Y16: =SUM(N16:X16) -> 14443 | Z16: 44786 | AA16: 25216 | AB16: 52576 | AC16: =SUM(Z16:AB16) -> 122578 | AD16: =M16+Y16+AC16 -> 157747
B17: 合計點數 | C17: =C14+D14+E14+C15+D15+E15 -> 5817.0595 | F17: =F14+G14+H14+I14+F15+G15+H15+I15 -> 9192 | J17: =J14+K14+L14+J15+K15+L15 -> 2476.298 | N17: =N14+O14+P14+N15+O15+P15 -> 5681.66 | Z17: =Z14+AA14+AB14+Z15+AA15+AB15 -> 64729
B18: 合計配置數 | C18: =C16+D16+E16 -> 7055 | F18: =F16+G16+H16+I16 -> 10107 | J18: =J16+K16+L16 -> 3564 | N18: =N16+O16+P16 -> 6189 | Z18: =Z16+AA16+AB16 -> 122578
B19: 使用率 | C19: =C17/C18 -> 0.82453005 | F19: =F17/F18 -> 0.90946869 | J19: =J17/J18 -> 0.69480864 | M19: =(M14+M15)/M16 -> 0.84364361 | N19: =N17/N18 -> 0.91802553 | Q19: =(Q14+Q15)/Q16 -> 0.92077068 | R19: =(R14+R15)/R16 -> 0.97530864 | S19: =(S14+S15)/S16 -> 1 | T19: =(T14+T15)/T16 -> 0.91967404 | U19: =(U14+U15)/U16 -> 1 | V19: =(V14+V15)/V16 -> 0.95151515 | W19: =(W14+W15)/W16 -> 0.95238095 | X19: =(X14+X15)/X16 -> 0.79268293 | Y19: =(Y14+Y15)/Y16 -> 0.93593852 | Z19: =Z17/Z18 -> 0.52806376 | AC19: =(AC14+AC15)/AC16 -> 0.52806376 | AD19: =(AD14+AD15)/AD16 -> 0.60687124 | AE19: =AE14/AH14 -> 0.5 | AF19: =AF14/AH14 -> 0.25 | AG19: =AG14/AH14 -> 0.25 | AH19: =SUM(AE19:AG19) -> 1

Sheet 包材回收(同期比)
A2: 項目 | D2: 一月 | E2: 二月 | F2: 三月 | G2: 四月 | H2: 五月 | I2: 六月 | J2: 七月 | K2: 八月 | L2: 九月 | M2: 十月 | N2: 十一月 | O2: 十二月 | P2: 合計
A3: 2014包材回收 | B3: 重量 | C3: 國內 | D3: 5209 | E3: 3910 | F3: 3825 | G3: 5081 | H3: 4373 | I3: 4412 | J3: 4886 | K3: 3851 | L3: 3918 | M3: 3585 | N3: 4418 | O3: 2901 | P3: 50369
C4: 國外 | D4: 9072 | E4: 10025 | F4: 15303 | G4: 14948 | H4: 8755 | I4: 10066 | J4: 10998 | K4: 7788 | L4: 10408 | M4: 15447 | N4: 11424 | O4: 11286 | P4: 135520
C5: 合計 | D5: =SUM(D3:D4) -> 14281 | E5: =SUM(E3:E4) -> 13935 | F5: =SUM(F3:F4) -> 19128 | G5: =SUM(G3:G4) -> 20029 | H5: =SUM(H3:H4) -> 13128 | I5: =SUM(I3:I4) -> 14478 | J5: =SUM(J3:J4) -> 15884 | K5: =SUM(K3:K4) -> 11639 | ... P5: =SUM(P3:P4) -> 185889
B7: 金額 (萬元) | C7: 國內 | D7: 27.3 | E7: 21.5 | F7: 38.2 | G7: 44.6 | H7: 27.2 | I7: 34.8 | J7: 36.1 | K7: 22.5 | L7: 20.7 | M7: 24.5 | N7: 21 | O7: 32 | P7: 350.4
C8: 國外 | D8: 33.4 | E8: 35.4 | F8: 71.3 | G8: 70.4 | H8: 33.2 | I8: 40.4 | J8: 43.1 | K8: 26.9 | L8: 39.5 | M8: 53.4 | N8: 52 | O8: 54.6 | P8: =SUM(D8:O8) -> 553.6
C9: 合計 | D9: =SUM(D7:D8) -> 60.7 | E9: =SUM(E7:E8) -> 56.9 | F9: =SUM(F7:F8) -> 109.5 | G9: =SUM(G7:G8) -> 115 | H9: =SUM(H7:H8) -> 60.4 | I9: =SUM(I7:I8) -> 75.2 | J9: =SUM(J7:J8) -> 79.2 | K9: =SUM(K7:K8) -> 49.4 | ... O9: =SUM(O7:O8) -> 86.6 | P9: =SUM(D9:O9) -> 904
A11: 2015包材回收 | B11: 重量 | C11: 國內 | D11: 3682 | E11: 2836 | F11: 5003 | G11: 3897 | H11: 3875 | I11: 4322 | J11: 5970 | K11: 2327 | L11: 3296 | M11: 4341 | N11: 3640 | O11: 3880 | P11: =SUM(D11:O11) -> 47069
C12: 國外 | D12: 21027 | E12: 11097 | F12: 19367 | G12: 17626 | H12: 17245 | I12: 17245 | J12: 14879 | K12: 9229 | L12: 21318 | M12: 13625 | N12: 24016 | O12: 22278 | P12: =SUM(D12:O12) -> 208952
C13: 合計 | D13: =SUM(D11:D12) -> 24709 | E13: =SUM(E11:E12) -> 13933 | F13: =SUM(F11:F12) -> 24370 | G13: =SUM(G11:G12) -> 21523 | H13: =SUM(H11:H12) -> 21120 | I13: =SUM(I11:I12) -> 21567 | J13: =SUM(J11:J12) -> 20849 | K13: =SUM(K11:K12) -> 11556 | ... O13: =SUM(O11:O12) -> 26158 | P13: =SUM(D13:O13) -> 256021
C14: 同期比 | D14: =D13/D5 -> 1.730201 | E14: =E13/E5 -> 0.99985648 | F14: =F13/F5 -> 1.2740485 | G14: =G13/G5 -> 1.0745918 | H14: =H13/H5 -> 1.6087751 | I14: =I13/I5 -> 1.4896395 | J14: =J13/J5 -> 1.3125787 | K14: =K13/K5 -> 0.9928688 | ... O14: =O13/O5 -> 1.8438007 | P14: =SUM(D14:O14) -> 16.734224
B15: 金額 (萬元) | C15: 國內 | D15: 17.7 | E15: 45.5 | F15: 70 | G15: 36 | H15: 53 | I15: 46 | J15: 29.4 | K15: 11.8 | L15: 39.6 | M15: 26.6 | N15: 21.8 | O15: 35.9 | P15: =SUM(D15:O15) -> 433.3
C16: 國外 | D16: 102.9 | E16: 54 | F16: 80.9 | G16: 83.5 | H16: 75.2 | I16: 82.8 | J16: 65.6 | K16: 42 | L16: 110.6 | M16: 56 | N16: 109.7 | O16: 109.7 | P16: =SUM(D16:O16) -> 972.9
C17: 合計 | D17: =SUM(D15:D16) -> 120.6 | E17: =SUM(E15:E16) -> 99.5 | F17: =SUM(F15:F16) -> 150.9 | G17: =SUM(G15:G16) -> 119.5 | H17: =SUM(H15:H16) -> 128.2 | I17: =SUM(I15:I16) -> 128.8 | J17: =SUM(J15:J16) -> 95 | K17: =SUM(K15:K16) -> 53.8 | ... O17: =SUM(O15:O16) -> 145.6 | P17: =SUM(D17:O17) -> 1406.2
C18: 同期比 | D18: =D17/D9 -> 1.9868204 | E18: =E17/E9 -> 1.7486819 | F18: =F17/F9 -> 1.3780822 | G18: =G17/G9 -> 1.0391304 | H18: =H17/H9 -> 2.1225166 | I18: =I17/I9 -> 1.712766 | J18: =J17/J9 -> 1.1994949 | K18: =K17/K9 -> 1.0890688 | ... P18: =P17/P9 -> 1.555531 | Q18: =SUM(D18:P18) -> 20.870106 | R18: =Q18/12 -> 1.7391755
A19: 2016包材回收 | B19: 重量 | C19: 國內 | D19: 3338 | E19: 3751 | F19: 3605 | G19: 1456 | H19: 2994 | I19: 4268 | J19: 3994 | K19: 3873 | L19: 5975 | M19: 3747 | N19: 5619 | O19: 3012 | P19: =SUM(D19:O19) -> 45632
C20: 國外 | D20: 19493 | E20: 15955 | F20: 25893 | G20: 13272 | H20: 23488 | I20: 20366 | J20: 18294 | K20: 15565 | L20: 17423 | M20: 17599 | N20: 19639 | O20: 22475 | P20: =SUM(D20:O20) -> 229462
C21: 合計 | D21: 22831 | E21: 19706 | F21: 29498 | G21: 14728 | H21: 24648 | I21: 24634 | J21: 22288 | K21: 19438 | L21: 23398 | M21: 21346 | N21: 25258 | O21: =SUM(O19:O20) -> 25487 | P21: =SUM(D21:O21) -> 273260
C22: 同期比 | D22: =D21/D13 -> 0.92399531 | E22: =E21/E13 -> 1.4143401 | F22: =F21/F13 -> 1.2104227 | G22: =G21/G13 -> 0.68429122 | H22: =H21/H13 -> 1.1670455 | I22: =I21/I13 -> 1.142208 | J22: =J21/J13 -> 1.0690201 | K22: =K21/K13 -> 1.6820699 | ... O22: =O21/O13 -> 0.97434819 | P22: =SUM(D22:O22) -> 13.319763
B23: 金額 (萬元) | C23: 國內 | D23: 16.2 | E23: 22.1 | F23: 18.1 | G23: 6.7 | H23: 15.2 | I23: 23.9 | J23: 31.5 | K23: 19 | L23: 26.2 | M23: 29.1 | N23: 35.1 | O23: 32.3 | P23: =SUM(D23:O23) -> 275.4
C24: 國外 | D24: 95.5 | E24: 73.2 | F24: 116.3 | G24: 58.8 | H24: 110.5 | I24: 90.5 | J24: 85.3 | K24: 70.8 | L24: 83 | M24: 90 | N24: 96.1 | O24: 110.1 | P24: =SUM(D24:O24) -> 1080.1
C25: 合計 | D25: 111.7 | E25: 95.3 | F25: 134.4 | G25: 65.5 | H25: 125.7 | I25: 114.4 | J25: 116.8 | K25: 89.8 | L25: 109.2 | M25: 119.1 | N25: 131.2 | O25: =SUM(O23:O24) -> 142.4 | P25: =SUM(D25:O25) -> 1355.5
C26: 同期比 | D26: =D25/D17 -> 0.92620232 | E26: =E25/E17 -> 0.95778894 | F26: =F25/F17 -> 0.89065606 | G26: =G25/G17 -> 0.54811715 | H26: =H25/H17 -> 0.98049922 | I26: =I25/I17 -> 0.88819876 | J26: =J25/J17 -> 1.2294737 | K26: =K25/K17 -> 1.669145 | ... P26: =P25/P17 -> 0.96394538
A27: 2017包材回收 | B27: 重量 | C27: 國內 | D27: 2876 | E27: 2359 | F27: 4705 | G27: 2973 | H27: 3131 | I27: 4878 | J27: 4725 | K27: 3367 | L27: 2448 | M27: 2792 | N27: 6921 | O27: 5847 | P27: =SUM(D27:O27) -> 47022
C28: 國外 | D28: 23333 | E28: 20020 | F28: 23623 | G28: 11484 | H28: 22607 | I28: 22292 | J28: 19945 | K28: 21619 | L28: 19035 | M28: 13170 | N28: 13418 | O28: 12391 | P28: =SUM(D28:O28) -> 222937
C29: 合計 | D29: =SUM(D27:D28) -> 26209 | E29: 22379 | F29: 28328 | G29: 14457 | H29: 25738 | I29: 27170 | J29: 24670 | K29: 24986 | L29: 21483 | M29: 15962 | N29: 20339 | O29: 18238 | P29: =SUM(D29:O29) -> 269959
C30: 同期比 | D30: =D29/D21 -> 1.1479567 | E30: =E29/E21 -> 1.135644 | F30: =F29/F21 -> 0.96033629 | G30: =G29/G21 -> 0.98159967 | H30: =H29/H21 -> 1.0442227 | I30: =I29/I21 -> 1.1029471 | J30: =J29/J21 -> 1.1068737 | K30: =K29/K21 -> 1.2854203 | ... O30: =O29/O21 -> 0.71558049 | P30: =SUM(D30:O30) -> 11.951761
B31: 金額 (萬元) | C31: 國內 | D31: 28.9 | E31: 32.1 | F31: 36.9 | G31: 23.4 | H31: 26.8 | I31: 25.1 | J31: 29.6 | K31: 28.3 | L31: 28.6 | M31: 21.6 | N31: 40.4 | O31: 34.1 | P31: =SUM(D31:O31) -> 355.8
C32: 國外 | D32: 113.3 | E32: 92.9 | F32: 111.3 | G32: 49.4 | H32: 97.6 | I32: 108.2 | J32: 100.7 | K32: 103.3 | L32: 88.3 | M32: 62.8 | N32: 59 | O32: 62 | P32: =SUM(D32:O32) -> 1048.8
C33: 合計 | D33: 142.2 | E33: 125 | F33: 148.2 | G33: 72.8 | H33: 124.4 | I33: 133.3 | J33: 130.3 | K33: 131.6 | L33: 116.9 | M33: 84.4 | N33: 99.4 | O33: 96.1 | P33: =SUM(D33:O33) -> 1404.6
C34: 同期比 | D34: =D33/D25 -> 1.2730528 | E34: =E33/E25 -> 1.3116474 | F34: =F33/F25 -> 1.1026786 | G34: =G33/G25 -> 1.1114504 | H34: =H33/H25 -> 0.98965792 | I34: =I33/I25 -> 1.1652098 | J34: =J33/J25 -> 1.1155822 | K34: =K33/K25 -> 1.4654788 | ... P34: =P33/P25 -> 1.0362228
A35: 2018包材回收 | B35: 重量 | C35: 國內 | D35: 6404 | E35: 5279 | F35: 7157 | G35: 3367 | H35: 9871 | I35: 9953 | J35: 9618 | K35: 9544 | L35: 9712 | M35: 8041 | N35: 3313 | O35: 7407 | P35: =SUM(D35:O35) -> 89666
C36: 國外 | D36: 18721 | E36: 9937 | F36: 21946 | G36: 10583 | H36: 13259 | I36: 11654 | J36: 8581 | K36: 3900 | L36: 8800 | M36: 18008 | N36: 23826 | O36: 16269 | P36: =SUM(D36:O36) -> 165484
C37: 合計 | D37: =SUM(D35:D36) -> 25125 | E37: =SUM(E35:E36) -> 15216 | F37: 29103 | G37: 13950 | H37: 23130 | I37: 21607 | J37: 18199 | K37: 13444 | L37: 18512 | M37: 26049 | N37: 27139 | O37: 23676 | P37: =SUM(D37:O37) -> 255150
C38: 同期比 | D38: =D37/D29 -> 0.95864016 | E38: =E37/E29 -> 0.67992314 | F38: =F37/F29 -> 1.0273581 | G38: =G37/G29 -> 0.96493048 | H38: =H37/H29 -> 0.89867123 | I38: =I37/I29 -> 0.79525212 | J38: =J37/J29 -> 0.73769761 | K38: =K37/K29 -> 0.53806131 | ... O38: =O37/O29 -> 1.2981687 | P38: =SUM(D38:O38) -> 11.726679
B39: 金額 (萬元) | C39: 國內 | D39: 37 | E39: 33 | F39: 40.1 | G39: 21.9 | H39: 56.7 | I39: 56.9 | J39: 56.4 | K39: 55.8 | L39: 56 | M39: 48.8 | N39: 12.3 | O39: 31.9 | P39: =SUM(D39:O39) -> 506.8
C40: 國外 | D40: 89.3 | E40: 46.3 | F40: 96.2 | G40: 53.9 | H40: 69 | I40: 70 | J40: 50 | K40: 22 | L40: 35.4 | M40: 81 | N40: 100 | O40: 98 | P40: =SUM(D40:O40) -> 811.1
C41: 合計 | D41: =SUM(D39:D40) -> 126.3 | E41: =SUM(E39:E40) -> 79.3 | F41: 136.3 | G41: 75.8 | H41: 125.7 | I41: 126.9 | J41: 106.4 | K41: 77.8 | L41: 91.4 | M41: 129.8 | N41: 112.3 | O41: 98.4 | P41: =SUM(D41:O41) -> 1286.4
C42: 同期比 | D42: =D41/D33 -> 0.88818565 | E42: =E41/E33 -> 0.6344 | F42: =F41/F33 -> 0.9197031 | G42: =G41/G33 -> 1.0412088 | H42: =H41/H33 -> 1.0104502 | I42: =I41/I33 -> 0.951988 | J42: =J41/J33 -> 0.81657713 | K42: =K41/K33 -> 0.59118541 | ... P42: =P41/P33 -> 0.91584793
A43: 2019包材回收 | B43: 重量 | C43: 國內 | D43: 4564 | E43: 5089 | F43: 5015 | G43: 3895 | H43: 3866 | I43: 6300 | J43: 4003 | K43: 3024 | L43: 3113 | M43: 3984 | N43: 3524 | O43: 4305 | P43: =SUM(D43:O43) -> 50682
...

Sheet 加班時數
A1: 月份/類別 | B1: 一 | C1: 二 | D1: 三 | E1: 四 | F1: 五 | G1: 六 | H1: 七 | I1: 八 | J1: 九 | K1: 十 | L1: 十一 | M1: 十二
A2: 大物進貨 | B2: 91.8 | C2: 89.7 | D2: 153 | E2: 128.8 | F2: 49 | G2: 109 | H2: 112 | I2: 169 | J2: 141
A3: 中小物進貨 | B3: 122 | C3: 132 | D3: 141 | E3: 275 | F3: 272 | G3: 849 | H3: 711.5 | I3: 922 | J3: 688
A4: 改善支援上架 | B4: 23.5 | C4: 20 | D4: 16.5 | E4: 11 | F4: 6 | G4: 26 | H4: 22
A5: 支援補充上架作業(中小物) | B5: 80 | C5: 32 | H5: 41.7
A6: 中小物進貨空運檢查支援＆加班
A7: 進貨合計 | B7: =SUM(B2:B6) -> 317.3 | C7: =SUM(C2:C6) -> 273.7 | D7: =SUM(D2:D6) -> 310.5 | E7: =SUM(E2:E6) -> 414.8 | F7: =SUM(F2:F6) -> 327 | G7: =SUM(G2:G6) -> 984 | H7: =SUM(H2:H6) -> 887.2 | I7: =SUM(I2:I6) -> 1091 | ... M7: =SUM(M2:M6) -> 0
A9: 大物出貨 | B9: 443.5 | C9: 163 | D9: 391.5 | E9: 380.5 | F9: 340.5 | G9: 284 | H9: 420.5 | I9: 355.5 | J9: 354.5
A10: 中小物出貨 | B10: 876.5 | C10: =52+256 -> 308 | D10: 782 | E10: 969 | F10: 1137.5 | G10: 1151 | H10: 1100 | I10: 999.5 | J10: 958
A11: 月台理貨 | B11: 168.5 | C11: =57+32 -> 89 | D11: 163 | E11: 52 | F11: 177.5 | G11: 168.5 | H11: 167.5 | I11: 148 | J11: 135
A12: 精品出貨 | I12: 97 | J12: 96
A13: AGV理貨段取(支援) | G13: 13
A14: 改善人員/週六出勤封箱補充支援周六出貨(補充) | D14: 64 | E14: 72 | F14: 64 | G14: 50 | H14: 64 | I14: 95 | J14: 99.5
A15: 支援段取到月台 | B15: 20 | C15: 14 | D15: 25 | E15: 153 | F15: 23 | I15: 22.5 | J15: 20.5
A16: 中小物出貨W庫支援&加班 | B16: 84.5 | C16: 34.5 | D16: 83 | E16: 44
A17: 幹線疊貨作業
A18: 出貨合計 | B18: =SUM(B9:B17) -> 1593 | C18: =SUM(C9:C17) -> 608.5 | D18: =SUM(D9:D17) -> 1508.5 | E18: =SUM(E9:E17) -> 1670.5 | F18: =SUM(F9:F17) -> 1742.5 | G18: =SUM(G9:G17) -> 1666.5 | H18: =SUM(H9:H17) -> 1752 | I18: =SUM(I9:I17) -> 1717.5 | ... M18: =SUM(M9:M17) -> 0
A20: 包裝大物進貨
A21: 包裝中小物進貨 | B21: 4 | C21: 16 | D21: 20 | E21: 12 | F21: 32 | G21: 40 | H21: 44 | I21: 16 | J21: 18
A22: 包裝 | B22: 79.5 | C22: 145 | D22: 120 | E22: 178.5 | F22: 241 | G22: 675 | H22: 695.5 | I22: 642.5 | J22: 689
A23: 保桿
A24: 輸出 | B24: 104.5 | C24: 58 | D24: 195.5 | E24: 62.5 | F24: 82 | G24: 25.5 | H24: 190 | I24: 110 | J24: 220
A25: 其他:對應KZ盤點.打切零件.事務.手冊 | B25: 25.3 | C25: 19 | D25: 11.3 | E25: 53.8 | F25: 27 | G25: 50 | H25: 50.2 | I25: 69.3 | J25: 25
A26: 包裝合計 | B26: =SUM(B20:B25) -> 213.3 | C26: =SUM(C20:C25) -> 238 | D26: =SUM(D20:D25) -> 346.8 | E26: =SUM(E20:E25) -> 306.8 | F26: =SUM(F20:F25) -> 382 | G26: =SUM(G20:G25) -> 790.5 | H26: =SUM(H20:H25) -> 979.7 | I26: =SUM(I20:I25) -> 837.8 | ... M26: =SUM(M20:M25) -> 0
A28: 總計 | B28: =B26+B18+B7 -> 2123.6 | C28: =C26+C18+C7 -> 1120.2 | D28: =D26+D18+D7 -> 2165.8 | E28: =E26+E18+E7 -> 2392.1 | F28: =F26+F18+F7 -> 2451.5 | G28: =G26+G18+G7 -> 3441 | H28: =H26+H18+H7 -> 3618.9 | I28: =I26+I18+I7 -> 3646.3 | ... M28: =M26+M18+M7 -> 0

Sheet 優開SQL(中小物)
A1: --優開--
A2: SELECT CAST(CRTDT AS DATE) AS CRTDT,COUNT(*) AS CNT
A3: FROM VPMTSNO
A4: WHERE REJECTCD=' ' AND SNOTYPE='C'
A5: AND CONVERT(VARCHAR,CRTDT,112) BETWEEN '20260701' AND '20260731'
A6: GROUP BY CAST(CRTDT AS DATE)
A7: ORDER BY CAST(CRTDT AS DATE)
